Workbook

Sheet Cover
A1: CreditIQ — Brandywine Realty Trust credit underwriting model
A2: PUBLIC DATA CASE · HYPOTHETICAL INVESTMENT TERMS · $ in millions · as of 2026-06-30
A3: Real estate credit — first-lien secured loan to an office REIT with a 2027–29 maturity wall
A4: Model status | B4: ='Investment Summary'!$D$53 -> ALL CHECKS PASS
A5: Active scenario | B5: =Assumptions!$D$10 -> Downside
A6: Recommendation (rule-based; see Investment Summary) | B6: ='Investment Summary'!$C$4 -> HOLD
A8: Colour conventions
A9: Blue on pale yellow | B9: Hardcoded input: sourced historical data, explicit assumption, scenario / transaction / macro input, covenant threshold, sensitivity axis, structural block parameter.
A10: Black | B10: Formula or calculation. No outputs, subtotals or metrics are hardcoded anywhere in this workbook.
A11: Green | B11: Direct link to a cell on another worksheet.
A12: Grey fill | B12: Labels and headers.
A14: Flow of logic | B14: Assumptions + Historical → Operating Model → Debt Schedule ↔ Cash Flow → Credit Metrics & Covenants → Recovery → Returns → Sensitivities → Investment Summary
A15: Data classes | B15: PUBLIC FILING = reported inputs · ANALYST PROJECTION = scenario drivers · UNDERWRITING ASSUMPTION = hypothetical purchase price / terms · DEMO = fictional
A17: Tabs
A18: Assumptions | B18: All inputs, scenario drivers, covenants, selector
A19: Historical Financials | B19: Sourced statements; derived lines and LTM calculated
A20: Operating Model | B20: Income statement and FCF, history + projection
A21: Debt Schedule | B21: Per-tranche roll-forward, floors, PIK, refinancing test, sweep
A22: Cash Flow | B22: Cash waterfall, funding gap, default test
A23: Credit Metrics | B23: Ratios, covenant compliance, transparent credit score
A24: Scenarios | B24: Base / Downside / Severe side by side + reconciliation
A25: Capital Structure | B25: Tranches, leverage through the stack, maturity wall & refinancing requirement
A26: Recovery | B26: Seniority waterfall with collateral pools and deficiency claims
A27: Returns | B27: Face, price, coupon, yield, recovery; IRR, XIRR, MOIC
A28: Sensitivities | B28: Seven formula-driven tables
A29: Investment Summary | B29: Live outputs, recommendation evidence, integrity checks
... A31: Calc Engine | B31: Supporting: 63 simultaneous model runs
A33: Validation: docs/MODEL_VALIDATION.md · Audit: scripts/audit_model.py · Change-impact harness: scripts/model_harness.py

Sheet Assumptions
A1: Assumptions — Brandywine Realty Trust: all explicit inputs live on this tab
A2: PUBLIC DATA CASE · HYPOTHETICAL INVESTMENT TERMS · Blue on pale yellow = hardcoded input · Black = formula · Green = link to another sheet · $ in millions
A4: 1. General & model settings
A5: Company | C5: Brandywine Realty Trust
A6: Base period label (year in which the base / LTM period ends) | C6: 2026
A7: Fiscal-period end month (12 = calendar FY; 6 = LTM June periods) | C7: 6
A8: As-of / entry date | C8: 46203
A9: Cash tax rate on positive EBT | B9: % of EBT | C9: 0
A10: ACTIVE SCENARIO selector (1=Base, 2=Downside, 3=Severe) | B10: select 1 / 2 / 3 | C10: 2 | D10: =CHOOSE(C10,"Base Case","Downside","Severe Downside") -> Downside
A11: Cash & equivalents at base date (balance sheet) | B11: $M | C11: 37.87
A12: Minimum operating cash | B12: $M | C12: 25
A13: Cash sweep (% of excess cash applied to prepayable debt) | B13: % | C13: 0
A14: Recovery value override (leave blank = model-derived) | B14: $M, optional
A15: Administrative / DIP costs | B15: % of recovery value | C15: 0.04
A16: Accrued unpaid interest included in claims | B16: months | C16: 3
A17: Rank at which secured deficiency claims join general creditors | C17: 99
A18: Maturity alert window | B18: periods from base | C18: 2
A19: Materiality threshold for maturity alert | B19: % of total debt | C19: 0.25
A20: Concentration threshold (single-period maturities) | B20: % of total debt | C20: 0.3
A21: Market-implied EV / EBITDA (analyst assumption) | B21: x | C21: 12.5
A22: Credit score: maturity-risk window | B22: periods | C22: 3
A24: 2. Collateral / asset base (recovery & LTV)
A25: LTM NOI ÷ 7.5% analyst cap rate + construction-in-progress + land held for development + unconsolidated JV book value (6/30/2026). Property values are NOT disclosed in the filings.
A26: Analyst cap rate on LTM NOI | B26: % (assumption) | C26: 0.075
A27: Operating-property value = LTM NOI ÷ cap rate | C27: ='Historical Financials'!G27/Assumptions!$C$26 -> 4020.1467
A28: Construction-in-progress | C28: 85.569 | D28: bdn.cip.2026-06-30
A29: Land held for development | C29: 75.134 | D29: bdn.land.2026-06-30
A30: Investment in unconsolidated real estate ventures (book) | C30: 336.851 | D30: bdn.jv_investment.2026-06-30
A31: Total asset base | C31: =SUM(C27:C30) -> 4517.7007
A33: 3. Transaction / position being underwritten — HYPOTHETICAL INVESTMENT TERMS
A34: Target tranche # (row in the debt table below) | C34: 1
A35: Face value held (legal claim) | B35: $M | C35: 100
A36: Purchase price / OID (UNDERWRITING ASSUMPTION) | B36: % of face | C36: 98
A37: Transaction fees | B37: % of cost | C37: 0.005
A38: Hold period (whole years, 1-5) | B38: periods | C38: 3
A39: Coupon payments per year on target tranche (contractual-timing cross-check only) | B39: per year | C39: 4
A40: Default → recovery cash receipt lag | B40: periods | C40: 1
A41: Required IRR (hurdle) | C41: 0.1
A42: Minimum acceptable downside IRR | C42: 0
A43: Minimum yield to maturity | C43: 0.085
...

Sheet Historical Financials
A1: Historical Financials — Brandywine Realty Trust
A2: PUBLIC FILING data (blue = reported inputs, each traced to a datapoint on the Sources tab). All subtotals, EBITDA, EBIT, net income, FCF and LTM columns are formulas.
A4: US$ millions | B4: FY2023A | C4: FY2024A | D4: FY2025A | E4: H1-25A | F4: H1-26A | G4: LTM Jun-26 | H4: Source datapoint IDs (see Sources tab)
A5: A. Reported inputs
A6: Total revenue | B6: 514.651 | C6: 505.517 | D6: 484.454 | E6: 242.087 | F6: 255.924 | G6: =D6+F6-E6 -> 498.291 | H6: bdn.revenue.* (5 datapoints)
A7: Property operating expenses | B7: 129.885 | C7: 129.89 | D7: 131.347 | E7: 64.891 | F7: 77.094 | G7: =D7+F7-E7 -> 143.55 | H7: bdn.prop_opex.* (5 datapoints)
A8: Real estate taxes | B8: 49.974 | C8: 47.726 | D8: 43.602 | E8: 22.939 | F8: 23.006 | G8: =D8+F8-E8 -> 43.669 | H8: bdn.re_taxes.* (5 datapoints)
A9: Third-party management expenses | B9: 10.088 | C9: 9.714 | D9: 10.245 | E9: 5.117 | F9: 4.433 | G9: =D9+F9-E9 -> 9.561 | H9: bdn.mgmt_exp.* (5 datapoints)
A10: General and administrative expenses | B10: 34.862 | C10: 42.781 | D10: 42.031 | E10: 26.795 | F10: 21.598 | G10: =D10+F10-E10 -> 36.834 | H10: bdn.ga.* (5 datapoints)
A11: Depreciation and amortization | B11: 188.797 | C11: 178.168 | D11: 176.428 | E11: 88.115 | F11: 96.98 | G11: =D11+F11-E11 -> 185.293 | H11: bdn.da.* (5 datapoints)
A12: Interest expense (excl. financing-cost amortization) | B12: 95.456 | C12: 116.306 | D12: 134.955 | E12: 64.19 | F12: 82.82 | G12: =D12+F12-E12 -> 153.585 | H12: bdn.interest_expense.* (5 datapoints)
A13: Income tax provision | B13: 0.072 | C13: 0.014 | D13: 0.112 | E13: 0.085 | F13: 0.024 | G13: =D13+F13-E13 -> 0.051 | H13: bdn.taxes.* (5 datapoints)
A14: Net cash provided by operating activities | B14: 177.273 | C14: 181.125 | D14: 116.701 | E14: 40.704 | F14: 45.821 | G14: =D14+F14-E14 -> 121.818 | H14: bdn.cfo.* (5 datapoints)
A15: Capex: tenant improvements | B15: 48.939 | C15: 72.792 | D15: 74.005 | E15: 39.524 | F15: 33.162 | G15: =D15+F15-E15 -> 67.643 | H15: bdn.capex_ti.* (5 datapoints)
A16: Capex: redevelopments | B16: 59.984 | C16: 18.398 | D16: 6.168 | E16: 4.766 | F16: 1.872 | G16: =D16+F16-E16 -> 3.274 | H16: bdn.capex_redev.* (5 datapoints)
A17: Capex: developments | B17: 47.537 | C17: 38.57 | D17: 33.223 | E17: 17.656 | F17: 26.632 | G17: =D17+F17-E17 -> 42.199 | H17: bdn.capex_dev.* (5 datapoints)
... A22: Share-based compensation add-back (none applied for this company) | B22: 0 | C22: 0 | D22: 0 | E22: 0 | F22: 0 | G22: =D22+F22-E22 -> 0 | H22: none reported
A24: B. Standardized statements (calculated)
A25: Revenue | B25: =B6 -> 514.651 | C25: =C6 -> 505.517 | D25: =D6 -> 484.454 | E25: =E6 -> 242.087 | F25: =F6 -> 255.924 | G25: =G6 -> 498.291
A26: Direct costs / COGS | B26: =B7+B8+B9 -> 189.947 | C26: =C7+C8+C9 -> 187.33 | D26: =D7+D8+D9 -> 185.194 | E26: =E7+E8+E9 -> 92.947 | F26: =F7+F8+F9 -> 104.533 | G26: =G7+G8+G9 -> 196.78
A27: Gross profit (NOI for real estate) | B27: =B25-B26 -> 324.704 | C27: =C25-C26 -> 318.187 | D27: =D25-D26 -> 299.26 | E27: =E25-E26 -> 149.14 | F27: =F25-F26 -> 151.391 | G27: =G25-G26 -> 301.511
A28: Operating expenses, cash & adjusted (excl. D&A and non-cash add-backs) | B28: =B10 -> 34.862 | C28: =C10 -> 42.781 | D28: =D10 -> 42.031 | E28: =E10 -> 26.795 | F28: =F10 -> 21.598 | G28: =G10 -> 36.834
A29: EBITDA (company-adjusted basis) | B29: =B27-B28 -> 289.842 | C29: =C27-C28 -> 275.406 | D29: =D27-D28 -> 257.229 | E29: =E27-E28 -> 122.345 | F29: =F27-F28 -> 129.793 | G29: =G27-G28 -> 264.677
A30: Depreciation & amortization | B30: =B11 -> 188.797 | C30: =C11 -> 178.168 | D30: =D11 -> 176.428 | E30: =E11 -> 88.115 | F30: =F11 -> 96.98 | G30: =G11 -> 185.293
A31: Share-based compensation (non-cash add-back) | B31: =B22 -> 0 | C31: =C22 -> 0 | D31: =D22 -> 0 | E31: =E22 -> 0 | F31: =F22 -> 0 | G31: =G22 -> 0
A32: EBIT (EBITDA − D&A − SBC) | B32: =B29-B30-B31 -> 101.045 | C32: =C29-C30-C31 -> 97.238 | D32: =D29-D30-D31 -> 80.801 | E32: =E29-E30-E31 -> 34.23 | F32: =F29-F30-F31 -> 32.813 | G32: =G29-G30-G31 -> 79.384
A33: Interest expense | B33: =B12 -> 95.456 | C33: =C12 -> 116.306 | D33: =D12 -> 134.955 | E33: =E12 -> 64.19 | F33: =F12 -> 82.82 | G33: =G12 -> 153.585
A34: EBT | B34: =B32-B33 -> 5.589 | C34: =C32-C33 -> -19.068 | D34: =D32-D33 -> -54.154 | E34: =E32-E33 -> -29.96 | F34: =F32-F33 -> -50.007 | G34: =G32-G33 -> -74.201
A35: Income taxes | B35: =B13 -> 0.072 | C35: =C13 -> 0.014 | D35: =D13 -> 0.112 | E35: =E13 -> 0.085 | F35: =F13 -> 0.024 | G35: =G13 -> 0.051
A36: Net income (model basis; excludes impairments and one-offs) | B36: =B34-B35 -> 5.517 | C36: =C34-C35 -> -19.082 | D36: =D34-D35 -> -54.266 | E36: =E34-E35 -> -30.045 | F36: =F34-F35 -> -50.031 | G36: =G34-G35 -> -74.252
A37: Capex (incl. leasing costs where applicable) | B37: =B15+B16+B17+B18 -> 164.339 | C37: =C15+C16+C17+C18 -> 140.317 | D37: =D15+D16+D17+D18 -> 126.145 | E37: =E15+E16+E17+E18 -> 68.672 | F37: =F15+F16+F17+F18 -> 71.552 | G37: =G15+G16+G17+G18 -> 129.025
A38: Net cash provided by operating activities (reported) | B38: =B14 -> 177.273 | C38: =C14 -> 181.125 | D38: =D14 -> 116.701 | E38: =E14 -> 40.704 | F38: =F14 -> 45.821 | G38: =G14 -> 121.818
A39: Free cash flow (CFO − capex) | B39: =B38-B37 -> 12.934 | C39: =C38-C37 -> 40.808 | D39: =D38-D37 -> -9.444 | E39: =E38-E37 -> -27.968 | F39: =F38-F37 -> -25.731 | G39: =G38-G37 -> -7.207
A40: Δ working capital & other (derived plug: NI + D&A + SBC − capex − FCF) | B40: =B36+B30+B31-B37-B39 -> 17.041 | C40: =C36+C30+C31-C37-C39 -> -22.039 | D40: =D36+D30+D31-D37-D39 -> 5.461 | E40: =E36+E30+E31-E37-E39 -> 17.366 | F40: =F36+F30+F31-F37-F39 -> 1.128 | G40: =G36+G30+G31-G37-G39 -> -10.777
A42: C. Ratios & checks (calculated)
A43: Gross margin | B43: =B27/B25 -> 0.63092076 | C43: =C27/C25 -> 0.62942888 | D43: =D27/D25 -> 0.61772635 | E43: =E27/E25 -> 0.61605952 | F43: =F27/F25 -> 0.59154671 | G43: =G27/G25 -> 0.6050902
A44: EBITDA margin | B44: =B29/B25 -> 0.56318165 | C44: =C29/C25 -> 0.54480067 | D44: =D29/D25 -> 0.53096682 | E44: =E29/E25 -> 0.50537617 | F44: =F29/F25 -> 0.50715447 | G44: =G29/G25 -> 0.53116954
A45: Revenue growth (YoY) | C45: =C25/B25-1 -> -0.01774795 | D45: =D25/C25-1 -> -0.041666255 | F45: =F25/E25-1 -> 0.057157138
A46: EBITDA growth (YoY) | C46: =C29/B29-1 -> -0.049806446 | D46: =D29/C29-1 -> -0.066000741 | F46: =F29/E29-1 -> 0.060877028
A47: Check: Calculated NOI (revenue − direct costs) vs company-reported NOI (should be 0.000) | B47: =B27-B21 -> 0 | C47: =C27-C21 -> 0 | D47: =D27-D21 -> 0

Sheet Operating Model
A1: Operating Model — selected scenario (assumptions → statements)
A2: ="Brandywine Realty Trust · PUBLIC DATA CASE · HYPOTHETICAL INVESTMENT TERMS · Active scenario: "&Assumptions!$D$10 -> Brandywine Realty Trust · PUBLIC DATA CASE · HYPOTHETICAL INVESTMENT TERMS · Active scenario: Downside
A4: $M | C4: FY2023A | D4: FY2024A | E4: FY2025A | F4: LTM Jun-26 | G4: LTM Jun-27E | H4: LTM Jun-28E | I4: LTM Jun-29E | J4: LTM Jun-30E | K4: LTM Jun-31E
A6: Operating drivers (selected scenario → Assumptions)
A7: Model period (year in which the period ends) | C7: =D7-1 -> 2023 | D7: =E7-1 -> 2024 | E7: =F7-1 -> 2025 | F7: =Assumptions!$C$6 -> 2026 | G7: =F7+1 -> 2027 | H7: =G7+1 -> 2028 | I7: =H7+1 -> 2029 | J7: =I7+1 -> 2030 | K7: =J7+1 -> 2031
A8: Projection period # | G8: =G7-Assumptions!$C$6 -> 1 | H8: =H7-Assumptions!$C$6 -> 2 | I8: =I7-Assumptions!$C$6 -> 3 | J8: =J7-Assumptions!$C$6 -> 4 | K8: =K7-Assumptions!$C$6 -> 5
A9: Revenue growth | G9: =CHOOSE(Assumptions!$C$10,Assumptions!$G$79,Assumptions!$G$98,Assumptions!$G$117) -> -0.06 | H9: =CHOOSE(Assumptions!$C$10,Assumptions!$H$79,Assumptions!$H$98,Assumptions!$H$117) -> -0.03 | I9: =CHOOSE(Assumptions!$C$10,Assumptions!$I$79,Assumptions!$I$98,Assumptions!$I$117) -> 0 | J9: =CHOOSE(Assumptions!$C$10,Assumptions!$J$79,Assumptions!$J$98,Assumptions!$J$117) -> 0.01 | K9: =CHOOSE(Assumptions!$C$10,Assumptions!$K$79,Assumptions!$K$98,Assumptions!$K$117) -> 0.01
A10: Gross margin | G10: =CHOOSE(Assumptions!$C$10,Assumptions!$G$80,Assumptions!$G$99,Assumptions!$G$118) -> 0.57392066 | H10: =CHOOSE(Assumptions!$C$10,Assumptions!$H$80,Assumptions!$H$99,Assumptions!$H$118) -> 0.55892066 | I10: =CHOOSE(Assumptions!$C$10,Assumptions!$I$80,Assumptions!$I$99,Assumptions!$I$118) -> 0.55892066 | J10: =CHOOSE(Assumptions!$C$10,Assumptions!$J$80,Assumptions!$J$99,Assumptions!$J$118) -> 0.56392066 | K10: =CHOOSE(Assumptions!$C$10,Assumptions!$K$80,Assumptions!$K$99,Assumptions!$K$118) -> 0.56892066
A11: EBITDA margin | G11: =CHOOSE(Assumptions!$C$10,Assumptions!$G$81,Assumptions!$G$100,Assumptions!$G$119) -> 0.5 | H11: =CHOOSE(Assumptions!$C$10,Assumptions!$H$81,Assumptions!$H$100,Assumptions!$H$119) -> 0.485 | I11: =CHOOSE(Assumptions!$C$10,Assumptions!$I$81,Assumptions!$I$100,Assumptions!$I$119) -> 0.485 | J11: =CHOOSE(Assumptions!$C$10,Assumptions!$J$81,Assumptions!$J$100,Assumptions!$J$119) -> 0.49 | K11: =CHOOSE(Assumptions!$C$10,Assumptions!$K$81,Assumptions!$K$100,Assumptions!$K$119) -> 0.495
A12: Income statement ($M)
A13: Revenue | C13: ='Historical Financials'!B25 -> 514.651 | D13: ='Historical Financials'!C25 -> 505.517 | E13: ='Historical Financials'!D25 -> 484.454 | F13: ='Historical Financials'!G25 -> 498.291 | G13: =F13*(1+G9) -> 468.39354 | H13: =G13*(1+H9) -> 454.34173 | I13: =H13*(1+I9) -> 454.34173 | J13: =I13*(1+J9) -> 458.88515 | K13: =J13*(1+K9) -> 463.474
A14: Direct costs / COGS | C14: ='Historical Financials'!B26 -> 189.947 | D14: ='Historical Financials'!C26 -> 187.33 | E14: ='Historical Financials'!D26 -> 185.194 | F14: ='Historical Financials'!G26 -> 196.78 | G14: =G13*(1-G10) -> 199.57281 | H14: =H13*(1-H10) -> 200.40075 | I14: =I13*(1-I10) -> 200.40075 | J14: =J13*(1-J10) -> 200.11033 | K14: =K13*(1-K10) -> 199.79407
A15: Gross profit (NOI for real estate) | C15: =C13-C14 -> 324.704 | D15: =D13-D14 -> 318.187 | E15: =E13-E14 -> 299.26 | F15: =F13-F14 -> 301.511 | G15: =G13-G14 -> 268.82073 | H15: =H13-H14 -> 253.94098 | I15: =I13-I14 -> 253.94098 | J15: =J13-J14 -> 258.77482 | K15: =K13-K14 -> 263.67994
A16: Operating expenses (implied: gross profit − EBITDA) | C16: ='Historical Financials'!B28 -> 34.862 | D16: ='Historical Financials'!C28 -> 42.781 | E16: ='Historical Financials'!D28 -> 42.031 | F16: ='Historical Financials'!G28 -> 36.834 | G16: =G15-G17 -> 34.62396 | H16: =H15-H17 -> 33.585241 | I16: =I15-I17 -> 33.585241 | J16: =J15-J17 -> 33.921094 | K16: =K15-K17 -> 34.260305
A17: EBITDA | C17: =C15-C16 -> 289.842 | D17: =D15-D16 -> 275.406 | E17: =E15-E16 -> 257.229 | F17: =F15-F16 -> 264.677 | G17: =G13*G11 -> 234.19677 | H17: =H13*H11 -> 220.35574 | I17: =I13*I11 -> 220.35574 | J17: =J13*J11 -> 224.85372 | K17: =K13*K11 -> 229.41963
A18: D&A | C18: ='Historical Financials'!B30 -> 188.797 | D18: ='Historical Financials'!C30 -> 178.168 | E18: ='Historical Financials'!D30 -> 176.428 | F18: ='Historical Financials'!G30 -> 185.293 | G18: =G13*'Historical Financials'!G30/'Historical Financials'!G25 -> 174.17542 | H18: =H13*'Historical Financials'!G30/'Historical Financials'!G25 -> 168.95016 | I18: =I13*'Historical Financials'!G30/'Historical Financials'!G25 -> 168.95016 | J18: =J13*'Historical Financials'!G30/'Historical Financials'!G25 -> 170.63966 | K18: =K13*'Historical Financials'!G30/'Historical Financials'!G25 -> 172.34606
A19: Share-based compensation (non-cash) | C19: ='Historical Financials'!B31 -> 0 | D19: ='Historical Financials'!C31 -> 0 | E19: ='Historical Financials'!D31 -> 0 | F19: ='Historical Financials'!G31 -> 0 | G19: =G13*'Historical Financials'!G31/'Historical Financials'!G25 -> 0 | H19: =H13*'Historical Financials'!G31/'Historical Financials'!G25 -> 0 | I19: =I13*'Historical Financials'!G31/'Historical Financials'!G25 -> 0 | J19: =J13*'Historical Financials'!G31/'Historical Financials'!G25 -> 0 | K19: =K13*'Historical Financials'!G31/'Historical Financials'!G25 -> 0
A20: EBIT | C20: =C17-C18-C19 -> 101.045 | D20: =D17-D18-D19 -> 97.238 | E20: =E17-E18-E19 -> 80.801 | F20: =F17-F18-F19 -> 79.384 | G20: =G17-G18-G19 -> 60.02135 | H20: =H17-H18-H19 -> 51.405583 | I20: =I17-I18-I19 -> 51.405583 | J20: =J17-J18-J19 -> 54.214065 | K20: =K17-K18-K19 -> 57.073576
A21: Cash interest expense (Debt Schedule) | G21: ='Debt Schedule'!G21+'Debt Schedule'!G34+'Debt Schedule'!G47+'Debt Schedule'!G60+'Debt Schedule'!G73+'Debt Schedule'!G86+'Debt Schedule'!G99+'Debt Schedule'!G112+'Debt Schedule'!G125+'Debt Schedule'!G138 -> 187.38884 | H21: ='Debt Schedule'!H21+'Debt Schedule'!H34+'Debt Schedule'!H47+'Debt Schedule'!H60+'Debt Schedule'!H73+'Debt Schedule'!H86+'Debt Schedule'!H99+'Debt Schedule'!H112+'Debt Schedule'!H125+'Debt Schedule'!H138 -> 186.25092 | I21: ='Debt Schedule'!I21+'Debt Schedule'!I34+'Debt Schedule'!I47+'Debt Schedule'!I60+'Debt Schedule'!I73+'Debt Schedule'!I86+'Debt Schedule'!I99+'Debt Schedule'!I112+'Debt Schedule'!I125+'Debt Schedule'!I138 -> 182.73653 | J21: ='Debt Schedule'!J21+'Debt Schedule'!J34+'Debt Schedule'!J47+'Debt Schedule'!J60+'Debt Schedule'!J73+'Debt Schedule'!J86+'Debt Schedule'!J99+'Debt Schedule'!J112+'Debt Schedule'!J125+'Debt Schedule'!J138 -> 182.32653 | K21: ='Debt Schedule'!K21+'Debt Schedule'!K34+'Debt Schedule'!K47+'Debt Schedule'!K60+'Debt Schedule'!K73+'Debt Schedule'!K86+'Debt Schedule'!K99+'Debt Schedule'!K112+'Debt Schedule'!K125+'Debt Schedule'!K138 -> 181.91653
A22: PIK interest (non-cash) | G22: ='Debt Schedule'!G22+'Debt Schedule'!G35+'Debt Schedule'!G48+'Debt Schedule'!G61+'Debt Schedule'!G74+'Debt Schedule'!G87+'Debt Schedule'!G100+'Debt Schedule'!G113+'Debt Schedule'!G126+'Debt Schedule'!G139 -> 0 | H22: ='Debt Schedule'!H22+'Debt Schedule'!H35+'Debt Schedule'!H48+'Debt Schedule'!H61+'Debt Schedule'!H74+'Debt Schedule'!H87+'Debt Schedule'!H100+'Debt Schedule'!H113+'Debt Schedule'!H126+'Debt Schedule'!H139 -> 0 | I22: ='Debt Schedule'!I22+'Debt Schedule'!I35+'Debt Schedule'!I48+'Debt Schedule'!I61+'Debt Schedule'!I74+'Debt Schedule'!I87+'Debt Schedule'!I100+'Debt Schedule'!I113+'Debt Schedule'!I126+'Debt Schedule'!I139 -> 0 | J22: ='Debt Schedule'!J22+'Debt Schedule'!J35+'Debt Schedule'!J48+'Debt Schedule'!J61+'Debt Schedule'!J74+'Debt Schedule'!J87+'Debt Schedule'!J100+'Debt Schedule'!J113+'Debt Schedule'!J126+'Debt Schedule'!J139 -> 0 | K22: ='Debt Schedule'!K22+'Debt Schedule'!K35+'Debt Schedule'!K48+'Debt Schedule'!K61+'Debt Schedule'!K74+'Debt Schedule'!K87+'Debt Schedule'!K100+'Debt Schedule'!K113+'Debt Schedule'!K126+'Debt Schedule'!K139 -> 0
A23: Interest expense | C23: ='Historical Financials'!B33 -> 95.456 | D23: ='Historical Financials'!C33 -> 116.306 | E23: ='Historical Financials'!D33 -> 134.955 | F23: ='Historical Financials'!G33 -> 153.585 | G23: =G21+G22 -> 187.38884 | H23: =H21+H22 -> 186.25092 | I23: =I21+I22 -> 182.73653 | J23: =J21+J22 -> 182.32653 | K23: =K21+K22 -> 181.91653
A24: EBT | C24: =C20-C23 -> 5.589 | D24: =D20-D23 -> -19.068 | E24: =E20-E23 -> -54.154 | F24: =F20-F23 -> -74.201 | G24: =G20-G23 -> -127.36749 | H24: =H20-H23 -> -134.84534 | I24: =I20-I23 -> -131.33094 | J24: =J20-J23 -> -128.11246 | K24: =K20-K23 -> -124.84295
A25: Taxes | C25: ='Historical Financials'!B35 -> 0.072 | D25: ='Historical Financials'!C35 -> 0.014 | E25: ='Historical Financials'!D35 -> 0.112 | F25: ='Historical Financials'!G35 -> 0.051 | G25: =MAX(0,G24)*Assumptions!$C$9 -> 0 | H25: =MAX(0,H24)*Assumptions!$C$9 -> 0 | I25: =MAX(0,I24)*Assumptions!$C$9 -> 0 | J25: =MAX(0,J24)*Assumptions!$C$9 -> 0 | K25: =MAX(0,K24)*Assumptions!$C$9 -> 0
A26: Net income (model basis) | C26: =C24-C25 -> 5.517 | D26: =D24-D25 -> -19.082 | E26: =E24-E25 -> -54.266 | F26: =F24-F25 -> -74.252 | G26: =G24-G25 -> -127.36749 | H26: =H24-H25 -> -134.84534 | I26: =I24-I25 -> -131.33094 | J26: =J24-J25 -> -128.11246 | K26: =K24-K25 -> -124.84295
A27: Free cash flow build ($M)
A28: Capex | C28: ='Historical Financials'!B37 -> 164.339 | D28: ='Historical Financials'!C37 -> 140.317 | E28: ='Historical Financials'!D37 -> 126.145 | F28: ='Historical Financials'!G37 -> 129.025 | G28: =G13*CHOOSE(Assumptions!$C$10,Assumptions!$C$83,Assumptions!$C$102,Assumptions!$C$121) -> 84.310837 | H28: =H13*CHOOSE(Assumptions!$C$10,Assumptions!$C$83,Assumptions!$C$102,Assumptions!$C$121) -> 81.781512 | I28: =I13*CHOOSE(Assumptions!$C$10,Assumptions!$C$83,Assumptions!$C$102,Assumptions!$C$121) -> 81.781512 | J28: =J13*CHOOSE(Assumptions!$C$10,Assumptions!$C$83,Assumptions!$C$102,Assumptions!$C$121) -> 82.599327 | K28: =K13*CHOOSE(Assumptions!$C$10,Assumptions!$C$83,Assumptions!$C$102,Assumptions!$C$121) -> 83.42532
A29: Working capital & other cash items (+ = outflow) | C29: ='Historical Financials'!B40 -> 17.041 | D29: ='Historical Financials'!C40 -> -22.039 | E29: ='Historical Financials'!D40 -> 5.461 | F29: ='Historical Financials'!G40 -> -10.777 | G29: =CHOOSE(Assumptions!$C$10,Assumptions!$C$84,Assumptions!$C$103,Assumptions!$C$122)*(G13-F13)+CHOOSE(Assumptions!$C$10,Assumptions!$C$85,Assumptions!$C$104,Assumptions!$C$123)*G13 -> 23.419677 | H29: =CHOOSE(Assumptions!$C$10,Assumptions!$C$84,Assumptions!$C$103,Assumptions!$C$122)*(H13-G13)+CHOOSE(Assumptions!$C$10,Assumptions!$C$85,Assumptions!$C$104,Assumptions!$C$123)*H13 -> 22.717087 | I29: =CHOOSE(Assumptions!$C$10,Assumptions!$C$84,Assumptions!$C$103,Assumptions!$C$122)*(I13-H13)+CHOOSE(Assumptions!$C$10,Assumptions!$C$85,Assumptions!$C$104,Assumptions!$C$123)*I13 -> 22.717087 | J29: =CHOOSE(Assumptions!$C$10,Assumptions!$C$84,Assumptions!$C$103,Assumptions!$C$122)*(J13-I13)+CHOOSE(Assumptions!$C$10,Assumptions!$C$85,Assumptions!$C$104,Assumptions!$C$123)*J13 -> 22.944258 | K29: =CHOOSE(Assumptions!$C$10,Assumptions!$C$84,Assumptions!$C$103,Assumptions!$C$122)*(K13-J13)+CHOOSE(Assumptions!$C$10,Assumptions!$C$85,Assumptions!$C$104,Assumptions!$C$123)*K13 -> 23.1737
A30: Free cash flow (NI + D&A + SBC + PIK − capex − ΔNWC/other) | C30: ='Historical Financials'!B39 -> 12.934 | D30: ='Historical Financials'!C39 -> 40.808 | E30: ='Historical Financials'!D39 -> -9.444 | F30: ='Historical Financials'!G39 -> -7.207 | G30: =G26+G18+G19+G22-G28-G29 -> -60.92258 | H30: =H26+H18+H19+H22-H28-H29 -> -70.393778 | I30: =I26+I18+I19+I22-I28-I29 -> -66.879384 | J30: =J26+J18+J19+J22-J28-J29 -> -63.016387 | K30: =K26+K18+K19+K22-K28-K29 -> -59.095916

Sheet Debt Schedule
A1: Debt Schedule — tranche roll-forward, rates, PIK, refinancing test, cash sweep
A2: ="Brandywine Realty Trust · PUBLIC DATA CASE · HYPOTHETICAL INVESTMENT TERMS · Active scenario: "&Assumptions!$D$10 -> Brandywine Realty Trust · PUBLIC DATA CASE · HYPOTHETICAL INVESTMENT TERMS · Active scenario: Downside
A4: $M | C4: FY2023A | D4: FY2024A | E4: FY2025A | F4: LTM Jun-26 | G4: LTM Jun-27E | H4: LTM Jun-28E | I4: LTM Jun-29E | J4: LTM Jun-30E | K4: LTM Jun-31E
A6: Rates & market-access (refinancing) test
A7: Base rate (SOFR) | G7: =Assumptions!$G$53 -> 0.039 | H7: =Assumptions!$H$53 -> 0.0375 | I7: =Assumptions!$I$53 -> 0.035 | J7: =Assumptions!$J$53 -> 0.035 | K7: =Assumptions!$K$53 -> 0.035
A8: Floating-rate shock (selected scenario) | C8: =CHOOSE(Assumptions!$C$10,Assumptions!$C$86,Assumptions!$C$105,Assumptions!$C$124) -> 0.015
A9: Refinancing rate (selected scenario) | C9: =CHOOSE(Assumptions!$C$10,Assumptions!$C$87,Assumptions!$C$106,Assumptions!$C$125) -> 0.1
A10: Max net leverage to refinance | C10: =CHOOSE(Assumptions!$C$10,Assumptions!$C$88,Assumptions!$C$107,Assumptions!$C$126) -> 9.5
A11: Min pro-forma coverage to refinance | C11: =CHOOSE(Assumptions!$C$10,Assumptions!$C$89,Assumptions!$C$108,Assumptions!$C$127) -> 1.5
A12: Beginning total debt | G12: =G17+G30+G43+G56+G69+G82+G95+G108+G121+G134 -> 2625.934 | H12: =H17+H30+H43+H56+H69+H82+H95+H108+H121+H134 -> 2621.934 | I12: =I17+I30+I43+I56+I69+I82+I95+I108+I121+I134 -> 2569.3804 | J12: =J17+J30+J43+J56+J69+J82+J95+J108+J121+J134 -> 2565.3804 | K12: =K17+K30+K43+K56+K69+K82+K95+K108+K121+K134 -> 2561.3804
A13: Beginning cash | G13: ='Cash Flow'!F19 -> 37.87 | H13: ='Cash Flow'!G19 -> 122.94742 | I13: ='Cash Flow'!H19 -> 0 | J13: ='Cash Flow'!I19 -> -70.879384 | K13: ='Cash Flow'!J19 -> -137.89577
A14: Pro-forma interest for refinancing test | G14: =G17*IF(G18=1,$C$9,IF(Assumptions!$I$57=1,MAX(G7,Assumptions!$G$57)+Assumptions!$F$57+$C$8,Assumptions!$E$57))+G30*IF(G31=1,$C$9,IF(Assumptions!$I$58=1,MAX(G7,Assumptions!$G$58)+Assumptions!$F$58+$C$8,Assumptions!$E$58))+G43*IF(G44=1,$C$9,IF(Assumptions!$I$59=1,MAX(G7,Assumptions!$G$59)+Assumptions!$F$59+$C$8,Assumptions!$E$59))+G56*IF(G57=1,$C$9,IF(Assumptions!$I$60=1,MAX(G7,Assumptions!$G$60)+Assumptions!$F$60+$C$8,Assumptions!$E$60))+G69*IF(G70=1,$C$9,IF(Assumptions!$I$61=1,MAX(G7,Assumptions!$G$61)+Assumptions!$F$61+$C$8,Assumptions!$E$61))+G82*IF(G83=1,$C$9,IF(Assumptions!$I$62=1,MAX(G7,Assumptions!$G$62)+Assumptions!$F$62+$C$8,Assumptions!$E$62))+G95*IF(G96=1,$C$9,IF(Assumptions!$I$63=1,MAX(G7,Assumptions!$G$63)+Assumptions!$F$63+$C$8,Assumptions!$E$63))+G108*IF(G109=1,$C$9,IF(Assumptions!$I$64=1,MAX(G7,Assumptions!$G$64)+Assumptions!$F$64+$C$8,Assumptions!$E$64))+G121*IF(G122=1,$C$9,IF(Assumptions!$I$65=1,MAX(G7,Assumptions!$G$65)+Assumptions!$F$65+$C$8,Assumptions!$E$65))+G134*IF(G135=1,$C$9,IF(Assumptions!$I$66=1,MAX(G7,Assumptions!$G$66)+Assumptions!$F$66+$C$8,Assumptions!$E$66)) -> 187.38884 | H14: =H17*IF(OR(H18=1,Recovery!G63=1),$C$9,IF(Assumptions!$I$57=1,MAX(H7,Assumptions!$G$57)+Assumptions!$F$57+$C$8,Assumptions!$E$57))+H30*IF(OR(H31=1,Recovery!G64=1),$C$9,IF(Assumptions!$I$58=1,MAX(H7,Assumptions!$G$58)+Assumptions!$F$58+$C$8,Assumptions!$E$58))+H43*IF(OR(H44=1,Recovery!G65=1),$C$9,IF(Assumptions!$I$59=1,MAX(H7,Assumptions!$G$59)+Assumptions!$F$59+$C$8,Assumptions!$E$59))+H56*IF(OR(H57=1,Recovery!G66=1),$C$9,IF(Assumptions!$I$60=1,MAX(H7,Assumptions!$G$60)+Assumptions!$F$60+$C$8,Assumptions!$E$60))+H69*IF(OR(H70=1,Recovery!G67=1),$C$9,IF(Assumptions!$I$61=1,MAX(H7,Assumptions!$G$61)+Assumptions!$F$61+$C$8,Assumptions!$E$61))+H82*IF(OR(H83=1,Recovery!G68=1),$C$9,IF(Assumptions!$I$62=1,MAX(H7,Assumptions!$G$62)+Assumptions!$F$62+$C$8,Assumptions!$E$62))+H95*IF(OR(H96=1,Recovery!G69=1),$C$9,IF(Assumptions!$I$63=1,MAX(H7,Assumptions!$G$63)+Assumptions!$F$63+$C$8,Assumptions!$E$63))+H108*IF(OR(H109=1,Recovery!G70=1),$C$9,IF(Assumptions!$I$64=1,MAX(H7,Assumptions!$G$64)+Assumptions!$F$64+$C$8,Assumptions!$E$64))+H121*IF(OR(H122=1,Recovery!G71=1),$C$9,IF(Assumptions!$I$65=1,MAX(H7,Assumptions!$G$65)+Assumptions!$F$65+$C$8,Assumptions!$E$65))+H134*IF(OR(H135=1,Recovery!G72=1),$C$9,IF(Assumptions!$I$66=1,MAX(H7,Assumptions!$G$66)+Assumptions!$F$66+$C$8,Assumptions!$E$66)) -> 219.42592 | I14: =I17*IF(OR(I18=1,Recovery!H63=1),$C$9,IF(Assumptions!$I$57=1,MAX(I7,Assumptions!$G$57)+Assumptions!$F$57+$C$8,Assumptions!$E$57))+I30*IF(OR(I31=1,Recovery!H64=1),$C$9,IF(Assumptions!$I$58=1,MAX(I7,Assumptions!$G$58)+Assumptions!$F$58+$C$8,Assumptions!$E$58))+I43*IF(OR(I44=1,Recovery!H65=1),$C$9,IF(Assumptions!$I$59=1,MAX(I7,Assumptions!$G$59)+Assumptions!$F$59+$C$8,Assumptions!$E$59))+I56*IF(OR(I57=1,Recovery!H66=1),$C$9,IF(Assumptions!$I$60=1,MAX(I7,Assumptions!$G$60)+Assumptions!$F$60+$C$8,Assumptions!$E$60))+I69*IF(OR(I70=1,Recovery!H67=1),$C$9,IF(Assumptions!$I$61=1,MAX(I7,Assumptions!$G$61)+Assumptions!$F$61+$C$8,Assumptions!$E$61))+I82*IF(OR(I83=1,Recovery!H68=1),$C$9,IF(Assumptions!$I$62=1,MAX(I7,Assumptions!$G$62)+Assumptions!$F$62+$C$8,Assumptions!$E$62))+I95*IF(OR(I96=1,Recovery!H69=1),$C$9,IF(Assumptions!$I$63=1,MAX(I7,Assumptions!$G$63)+Assumptions!$F$63+$C$8,Assumptions!$E$63))+I108*IF(OR(I109=1,Recovery!H70=1),$C$9,IF(Assumptions!$I$64=1,MAX(I7,Assumptions!$G$64)+Assumptions!$F$64+$C$8,Assumptions!$E$64))+I121*IF(OR(I122=1,Recovery!H71=1),$C$9,IF(Assumptions!$I$65=1,MAX(I7,Assumptions!$G$65)+Assumptions!$F$65+$C$8,Assumptions!$E$65))+I134*IF(OR(I135=1,Recovery!H72=1),$C$9,IF(Assumptions!$I$66=1,MAX(I7,Assumptions!$G$66)+Assumptions!$F$66+$C$8,Assumptions!$E$66)) -> 188.92403 | J14: =J17*IF(OR(J18=1,Recovery!I63=1),$C$9,IF(Assumptions!$I$57=1,MAX(J7,Assumptions!$G$57)+Assumptions!$F$57+$C$8,Assumptions!$E$57))+J30*IF(OR(J31=1,Recovery!I64=1),$C$9,IF(Assumptions!$I$58=1,MAX(J7,Assumptions!$G$58)+Assumptions!$F$58+$C$8,Assumptions!$E$58))+J43*IF(OR(J44=1,Recovery!I65=1),$C$9,IF(Assumptions!$I$59=1,MAX(J7,Assumptions!$G$59)+Assumptions!$F$59+$C$8,Assumptions!$E$59))+J56*IF(OR(J57=1,Recovery!I66=1),$C$9,IF(Assumptions!$I$60=1,MAX(J7,Assumptions!$G$60)+Assumptions!$F$60+$C$8,Assumptions!$E$60))+J69*IF(OR(J70=1,Recovery!I67=1),$C$9,IF(Assumptions!$I$61=1,MAX(J7,Assumptions!$G$61)+Assumptions!$F$61+$C$8,Assumptions!$E$61))+J82*IF(OR(J83=1,Recovery!I68=1),$C$9,IF(Assumptions!$I$62=1,MAX(J7,Assumptions!$G$62)+Assumptions!$F$62+$C$8,Assumptions!$E$62))+J95*IF(OR(J96=1,Recovery!I69=1),$C$9,IF(Assumptions!$I$63=1,MAX(J7,Assumptions!$G$63)+Assumptions!$F$63+$C$8,Assumptions!$E$63))+J108*IF(OR(J109=1,Recovery!I70=1),$C$9,IF(Assumptions!$I$64=1,MAX(J7,Assumptions!$G$64)+Assumptions!$F$64+$C$8,Assumptions!$E$64))+J121*IF(OR(J122=1,Recovery!I71=1),$C$9,IF(Assumptions!$I$65=1,MAX(J7,Assumptions!$G$65)+Assumptions!$F$65+$C$8,Assumptions!$E$65))+J134*IF(OR(J135=1,Recovery!I72=1),$C$9,IF(Assumptions!$I$66=1,MAX(J7,Assumptions!$G$66)+Assumptions!$F$66+$C$8,Assumptions!$E$66)) -> 201.40153 | K14: =K17*IF(OR(K18=1,Recovery!J63=1),$C$9,IF(Assumptions!$I$57=1,MAX(K7,Assumptions!$G$57)+Assumptions!$F$57+$C$8,Assumptions!$E$57))+K30*IF(OR(K31=1,Recovery!J64=1),$C$9,IF(Assumptions!$I$58=1,MAX(K7,Assumptions!$G$58)+Assumptions!$F$58+$C$8,Assumptions!$E$58))+K43*IF(OR(K44=1,Recovery!J65=1),$C$9,IF(Assumptions!$I$59=1,MAX(K7,Assumptions!$G$59)+Assumptions!$F$59+$C$8,Assumptions!$E$59))+K56*IF(OR(K57=1,Recovery!J66=1),$C$9,IF(Assumptions!$I$60=1,MAX(K7,Assumptions!$G$60)+Assumptions!$F$60+$C$8,Assumptions!$E$60))+K69*IF(OR(K70=1,Recovery!J67=1),$C$9,IF(Assumptions!$I$61=1,MAX(K7,Assumptions!$G$61)+Assumptions!$F$61+$C$8,Assumptions!$E$61))+K82*IF(OR(K83=1,Recovery!J68=1),$C$9,IF(Assumptions!$I$62=1,MAX(K7,Assumptions!$G$62)+Assumptions!$F$62+$C$8,Assumptions!$E$62))+K95*IF(OR(K96=1,Recovery!J69=1),$C$9,IF(Assumptions!$I$63=1,MAX(K7,Assumptions!$G$63)+Assumptions!$F$63+$C$8,Assumptions!$E$63))+K108*IF(OR(K109=1,Recovery!J70=1),$C$9,IF(Assumptions!$I$64=1,MAX(K7,Assumptions!$G$64)+Assumptions!$F$64+$C$8,Assumptions!$E$64))+K121*IF(OR(K122=1,Recovery!J71=1),$C$9,IF(Assumptions!$I$65=1,MAX(K7,Assumptions!$G$65)+Assumptions!$F$65+$C$8,Assumptions!$E$65))+K134*IF(OR(K135=1,Recovery!J72=1),$C$9,IF(Assumptions!$I$66=1,MAX(K7,Assumptions!$G$66)+Assumptions!$F$66+$C$8,Assumptions!$E$66)) -> 192.58153
A15: Market access to refinance? (1 = yes) | G15: =IF('Operating Model'!G17<=0,0,IF(AND((G12-G13)/'Operating Model'!G17<=$C$10,'Operating Model'!G17/G14>=$C$11),1,0)) -> 0 | H15: =IF('Operating Model'!H17<=0,0,IF(AND((H12-H13)/'Operating Model'!H17<=$C$10,'Operating Model'!H17/H14>=$C$11),1,0)) -> 0 | I15: =IF('Operating Model'!I17<=0,0,IF(AND((I12-I13)/'Operating Model'!I17<=$C$10,'Operating Model'!I17/I14>=$C$11),1,0)) -> 0 | J15: =IF('Operating Model'!J17<=0,0,IF(AND((J12-J13)/'Operating Model'!J17<=$C$10,'Operating Model'!J17/J14>=$C$11),1,0)) -> 0 | K15: =IF('Operating Model'!K17<=0,0,IF(AND((K12-K13)/'Operating Model'!K17<=$C$10,'Operating Model'!K17/K14>=$C$11),1,0)) -> 0
A16: Tranche 1: Hypothetical Senior Secured Term Loan (S+525, 1% floor)
A17: Beginning balance | G17: =F28 -> 400 | H17: =G28 -> 396 | I17: =H28 -> 392 | J17: =I28 -> 388 | K17: =J28 -> 384
A18: Maturing this period? (1 = yes) | G18: =IF('Operating Model'!G7=Assumptions!$K$57,1,0) -> 0 | H18: =IF('Operating Model'!H7=Assumptions!$K$57,1,0) -> 0 | I18: =IF('Operating Model'!I7=Assumptions!$K$57,1,0) -> 0 | J18: =IF('Operating Model'!J7=Assumptions!$K$57,1,0) -> 0 | K18: =IF('Operating Model'!K7=Assumptions!$K$57,1,0) -> 1
A20: All-in interest rate applied | G20: =IF(Assumptions!$I$57=1,MAX(G7,Assumptions!$G$57)+Assumptions!$F$57+$C$8,Assumptions!$E$57) -> 0.1065 | H20: =IF(Recovery!G63=1,$C$9,IF(Assumptions!$I$57=1,MAX(H7,Assumptions!$G$57)+Assumptions!$F$57+$C$8,Assumptions!$E$57)) -> 0.105 | I20: =IF(Recovery!H63=1,$C$9,IF(Assumptions!$I$57=1,MAX(I7,Assumptions!$G$57)+Assumptions!$F$57+$C$8,Assumptions!$E$57)) -> 0.1025 | J20: =IF(Recovery!I63=1,$C$9,IF(Assumptions!$I$57=1,MAX(J7,Assumptions!$G$57)+Assumptions!$F$57+$C$8,Assumptions!$E$57)) -> 0.1025 | K20: =IF(Recovery!J63=1,$C$9,IF(Assumptions!$I$57=1,MAX(K7,Assumptions!$G$57)+Assumptions!$F$57+$C$8,Assumptions!$E$57)) -> 0.1025
A21: Cash interest expense | G21: =G17*G20 -> 42.6 | H21: =H17*H20 -> 41.58 | I21: =I17*I20 -> 40.18 | J21: =J17*J20 -> 39.77 | K21: =K17*K20 -> 39.36
A22: PIK interest | G22: =G17*Assumptions!$H$57 -> 0 | H22: =H17*Assumptions!$H$57 -> 0 | I22: =I17*Assumptions!$H$57 -> 0 | J22: =J17*Assumptions!$H$57 -> 0 | K22: =K17*Assumptions!$H$57 -> 0
A23: Mandatory amortization | G23: =MIN(G17,Assumptions!$L$57*Assumptions!$C$57) -> 4 | H23: =MIN(H17,Assumptions!$L$57*Assumptions!$C$57) -> 4 | I23: =MIN(I17,Assumptions!$L$57*Assumptions!$C$57) -> 4 | J23: =MIN(J17,Assumptions!$L$57*Assumptions!$C$57) -> 4 | K23: =MIN(K17,Assumptions!$L$57*Assumptions!$C$57) -> 4
A24: New borrowing (revolver draw) | G24: =IF(AND(Assumptions!$P$57=1,'Operating Model'!G7<Assumptions!$K$57),MIN(MAX(0,-'Cash Flow'!G11),MAX(0,Assumptions!$D$57-G17)),0) -> 0 | H24: =IF(AND(Assumptions!$P$57=1,OR('Operating Model'!H7<Assumptions!$K$57,Recovery!G63=1)),MIN(MAX(0,-'Cash Flow'!H11),MAX(0,Assumptions!$D$57-H17)),0) -> 0 | I24: =IF(AND(Assumptions!$P$57=1,OR('Operating Model'!I7<Assumptions!$K$57,Recovery!H63=1)),MIN(MAX(0,-'Cash Flow'!I11),MAX(0,Assumptions!$D$57-I17)),0) -> 0 | J24: =IF(AND(Assumptions!$P$57=1,OR('Operating Model'!J7<Assumptions!$K$57,Recovery!I63=1)),MIN(MAX(0,-'Cash Flow'!J11),MAX(0,Assumptions!$D$57-J17)),0) -> 0 | K24: =IF(AND(Assumptions!$P$57=1,OR('Operating Model'!K7<Assumptions!$K$57,Recovery!J63=1)),MIN(MAX(0,-'Cash Flow'!K11),MAX(0,Assumptions!$D$57-K17)),0) -> 0
A25: Repayment at maturity (from available cash) | G25: =G18*MIN(G17-G23+G22,MAX(0,'Cash Flow'!G13-Assumptions!$C$12*G15)) -> 0 | H25: =H18*MIN(H17-H23+H22,MAX(0,'Cash Flow'!H13-Assumptions!$C$12*H15)) -> 0 | I25: =I18*MIN(I17-I23+I22,MAX(0,'Cash Flow'!I13-Assumptions!$C$12*I15)) -> 0 | J25: =J18*MIN(J17-J23+J22,MAX(0,'Cash Flow'!J13-Assumptions!$C$12*J15)) -> 0 | K25: =K18*MIN(K17-K23+K22,MAX(0,'Cash Flow'!K13-Assumptions!$C$12*K15)) -> 0
A26: Optional repayment (cash sweep) | G26: =Assumptions!$N$57*MIN(G17+G24+G22-G23-G25,MAX(0,'Cash Flow'!G17)) -> 0 | H26: =Assumptions!$N$57*MIN(H17+H24+H22-H23-H25,MAX(0,'Cash Flow'!H17)) -> 0 | I26: =Assumptions!$N$57*MIN(I17+I24+I22-I23-I25,MAX(0,'Cash Flow'!I17)) -> 0 | J26: =Assumptions!$N$57*MIN(J17+J24+J22-J23-J25,MAX(0,'Cash Flow'!J17)) -> 0 | K26: =Assumptions!$N$57*MIN(K17+K24+K22-K23-K25,MAX(0,'Cash Flow'!K17)) -> 0
A27: Unpaid at maturity (no refinancing, insufficient cash) | G27: =G18*(1-G15)*(G17-G23+G22-G25) -> 0 | H27: =H18*(1-H15)*(H17-H23+H22-H25) -> 0 | I27: =I18*(1-I15)*(I17-I23+I22-I25) -> 0 | J27: =J18*(1-J15)*(J17-J23+J22-J25) -> 0 | K27: =K18*(1-K15)*(K17-K23+K22-K25) -> 380
A28: Ending balance | F28: =Assumptions!$C$57 -> 400 | G28: =G17+G24+G22-G23-G25-G26 -> 396 | H28: =H17+H24+H22-H23-H25-H26 -> 392 | I28: =I17+I24+I22-I23-I25-I26 -> 388 | J28: =J17+J24+J22-J23-J25-J26 -> 384 | K28: =K17+K24+K22-K23-K25-K26 -> 380
A29: Tranche 2: Avira Secured Term Loan (swapped to 5.81%)
A30: Beginning balance | G30: =F41 -> 90 | H30: =G41 -> 90 | I30: =H41 -> 90 | J30: =I41 -> 90 | K30: =J41 -> 90
A31: Maturing this period? (1 = yes) | G31: =IF('Operating Model'!G7=Assumptions!$K$58,1,0) -> 0 | H31: =IF('Operating Model'!H7=Assumptions!$K$58,1,0) -> 0 | I31: =IF('Operating Model'!I7=Assumptions!$K$58,1,0) -> 0 | J31: =IF('Operating Model'!J7=Assumptions!$K$58,1,0) -> 0 | K31: =IF('Operating Model'!K7=Assumptions!$K$58,1,0) -> 0
A33: All-in interest rate applied | G33: =IF(Assumptions!$I$58=1,MAX(G7,Assumptions!$G$58)+Assumptions!$F$58+$C$8,Assumptions!$E$58) -> 0.0581 | H33: =IF(Recovery!G64=1,$C$9,IF(Assumptions!$I$58=1,MAX(H7,Assumptions!$G$58)+Assumptions!$F$58+$C$8,Assumptions!$E$58)) -> 0.0581 | I33: =IF(Recovery!H64=1,$C$9,IF(Assumptions!$I$58=1,MAX(I7,Assumptions!$G$58)+Assumptions!$F$58+$C$8,Assumptions!$E$58)) -> 0.0581 | J33: =IF(Recovery!I64=1,$C$9,IF(Assumptions!$I$58=1,MAX(J7,Assumptions!$G$58)+Assumptions!$F$58+$C$8,Assumptions!$E$58)) -> 0.0581 | K33: =IF(Recovery!J64=1,$C$9,IF(Assumptions!$I$58=1,MAX(K7,Assumptions!$G$58)+Assumptions!$F$58+$C$8,Assumptions!$E$58)) -> 0.0581
A34: Cash interest expense | G34: =G30*G33 -> 5.229 | H34: =H30*H33 -> 5.229 | I34: =I30*I33 -> 5.229 | J34: =J30*J33 -> 5.229 | K34: =K30*K33 -> 5.229
A35: PIK interest | G35: =G30*Assumptions!$H$58 -> 0 | H35: =H30*Assumptions!$H$58 -> 0 | I35: =I30*Assumptions!$H$58 -> 0 | J35: =J30*Assumptions!$H$58 -> 0 | K35: =K30*Assumptions!$H$58 -> 0
A36: Mandatory amortization | G36: =MIN(G30,Assumptions!$L$58*Assumptions!$C$58) -> 0 | H36: =MIN(H30,Assumptions!$L$58*Assumptions!$C$58) -> 0 | I36: =MIN(I30,Assumptions!$L$58*Assumptions!$C$58) -> 0 | J36: =MIN(J30,Assumptions!$L$58*Assumptions!$C$58) -> 0 | K36: =MIN(K30,Assumptions!$L$58*Assumptions!$C$58) -> 0
A37: New borrowing (revolver draw) | G37: =IF(AND(Assumptions!$P$58=1,'Operating Model'!G7<Assumptions!$K$58),MIN(MAX(0,-'Cash Flow'!G11),MAX(0,Assumptions!$D$58-G30)),0) -> 0 | H37: =IF(AND(Assumptions!$P$58=1,OR('Operating Model'!H7<Assumptions!$K$58,Recovery!G64=1)),MIN(MAX(0,-'Cash Flow'!H11),MAX(0,Assumptions!$D$58-H30)),0) -> 0 | I37: =IF(AND(Assumptions!$P$58=1,OR('Operating Model'!I7<Assumptions!$K$58,Recovery!H64=1)),MIN(MAX(0,-'Cash Flow'!I11),MAX(0,Assumptions!$D$58-I30)),0) -> 0 | J37: =IF(AND(Assumptions!$P$58=1,OR('Operating Model'!J7<Assumptions!$K$58,Recovery!I64=1)),MIN(MAX(0,-'Cash Flow'!J11),MAX(0,Assumptions!$D$58-J30)),0) -> 0 | K37: =IF(AND(Assumptions!$P$58=1,OR('Operating Model'!K7<Assumptions!$K$58,Recovery!J64=1)),MIN(MAX(0,-'Cash Flow'!K11),MAX(0,Assumptions!$D$58-K30)),0) -> 0
A38: Repayment at maturity (from available cash) | G38: =G31*MIN(G30-G36+G35,MAX(0,'Cash Flow'!G13-Assumptions!$C$12*G15-G25)) -> 0 | H38: =H31*MIN(H30-H36+H35,MAX(0,'Cash Flow'!H13-Assumptions!$C$12*H15-H25)) -> 0 | I38: =I31*MIN(I30-I36+I35,MAX(0,'Cash Flow'!I13-Assumptions!$C$12*I15-I25)) -> 0 | J38: =J31*MIN(J30-J36+J35,MAX(0,'Cash Flow'!J13-Assumptions!$C$12*J15-J25)) -> 0 | K38: =K31*MIN(K30-K36+K35,MAX(0,'Cash Flow'!K13-Assumptions!$C$12*K15-K25)) -> 0
A39: Optional repayment (cash sweep) | G39: =Assumptions!$N$58*MIN(G30+G37+G35-G36-G38,MAX(0,'Cash Flow'!G17-G26)) -> 0 | H39: =Assumptions!$N$58*MIN(H30+H37+H35-H36-H38,MAX(0,'Cash Flow'!H17-H26)) -> 0 | I39: =Assumptions!$N$58*MIN(I30+I37+I35-I36-I38,MAX(0,'Cash Flow'!I17-I26)) -> 0 | J39: =Assumptions!$N$58*MIN(J30+J37+J35-J36-J38,MAX(0,'Cash Flow'!J17-J26)) -> 0 | K39: =Assumptions!$N$58*MIN(K30+K37+K35-K36-K38,MAX(0,'Cash Flow'!K17-K26)) -> 0
A40: Unpaid at maturity (no refinancing, insufficient cash) | G40: =G31*(1-G15)*(G30-G36+G35-G38) -> 0 | H40: =H31*(1-H15)*(H30-H36+H35-H38) -> 0 | I40: =I31*(1-I15)*(I30-I36+I35-I38) -> 0 | J40: =J31*(1-J15)*(J30-J36+J35-J38) -> 0 | K40: =K31*(1-K15)*(K30-K36+K35-K38) -> 0
A41: Ending balance | F41: =Assumptions!$C$58 -> 90 | G41: =G30+G37+G35-G36-G38-G39 -> 90 | H41: =H30+H37+H35-H36-H38-H39 -> 90 | I41: =I30+I37+I35-I36-I38-I39 -> 90 | J41: =J30+J37+J35-J36-J38-J39 -> 90 | K41: =K30+K37+K35-K36-K38-K39 -> 90
A42: Tranche 3: 3151 Market C-PACE Loan
A43: Beginning balance | G43: =F54 -> 57.324 | H43: =G54 -> 57.324 | I43: =H54 -> 57.324 | J43: =I54 -> 57.324 | K43: =J54 -> 57.324
A44: Maturing this period? (1 = yes) | G44: =IF('Operating Model'!G7=Assumptions!$K$59,1,0) -> 0 | H44: =IF('Operating Model'!H7=Assumptions!$K$59,1,0) -> 0 | I44: =IF('Operating Model'!I7=Assumptions!$K$59,1,0) -> 0 | J44: =IF('Operating Model'!J7=Assumptions!$K$59,1,0) -> 0 | K44: =IF('Operating Model'!K7=Assumptions!$K$59,1,0) -> 0
...

Sheet Cash Flow
A1: Cash Flow & Liquidity — cash waterfall and default test
A2: ="Brandywine Realty Trust · PUBLIC DATA CASE · HYPOTHETICAL INVESTMENT TERMS · Active scenario: "&Assumptions!$D$10 -> Brandywine Realty Trust · PUBLIC DATA CASE · HYPOTHETICAL INVESTMENT TERMS · Active scenario: Downside
A4: $M | C4: FY2023A | D4: FY2024A | E4: FY2025A | F4: LTM Jun-26 | G4: LTM Jun-27E | H4: LTM Jun-28E | I4: LTM Jun-29E | J4: LTM Jun-30E | K4: LTM Jun-31E
A6: Cash flow & liquidity waterfall ($M)
A7: Beginning cash | G7: =F19 -> 37.87 | H7: =G19 -> 122.94742 | I7: =H19 -> 0 | J7: =I19 -> -70.879384 | K7: =J19 -> -137.89577
A8: Free cash flow (from Operating Model) | G8: ='Operating Model'!G30 -> -60.92258 | H8: ='Operating Model'!H30 -> -70.393778 | I8: ='Operating Model'!I30 -> -66.879384 | J8: ='Operating Model'!J30 -> -63.016387 | K8: ='Operating Model'!K30 -> -59.095916
A9: Plus: net asset-sale proceeds | G9: =CHOOSE(Assumptions!$C$10,Assumptions!$G$82,Assumptions!$G$101,Assumptions!$G$120) -> 150 | H9: =CHOOSE(Assumptions!$C$10,Assumptions!$H$82,Assumptions!$H$101,Assumptions!$H$120) -> 0 | I9: =CHOOSE(Assumptions!$C$10,Assumptions!$I$82,Assumptions!$I$101,Assumptions!$I$120) -> 0 | J9: =CHOOSE(Assumptions!$C$10,Assumptions!$J$82,Assumptions!$J$101,Assumptions!$J$120) -> 0 | K9: =CHOOSE(Assumptions!$C$10,Assumptions!$K$82,Assumptions!$K$101,Assumptions!$K$120) -> 0
A10: Less: mandatory amortization | G10: ='Debt Schedule'!G23+'Debt Schedule'!G36+'Debt Schedule'!G49+'Debt Schedule'!G62+'Debt Schedule'!G75+'Debt Schedule'!G88+'Debt Schedule'!G101+'Debt Schedule'!G114+'Debt Schedule'!G127+'Debt Schedule'!G140 -> 4 | H10: ='Debt Schedule'!H23+'Debt Schedule'!H36+'Debt Schedule'!H49+'Debt Schedule'!H62+'Debt Schedule'!H75+'Debt Schedule'!H88+'Debt Schedule'!H101+'Debt Schedule'!H114+'Debt Schedule'!H127+'Debt Schedule'!H140 -> 4 | I10: ='Debt Schedule'!I23+'Debt Schedule'!I36+'Debt Schedule'!I49+'Debt Schedule'!I62+'Debt Schedule'!I75+'Debt Schedule'!I88+'Debt Schedule'!I101+'Debt Schedule'!I114+'Debt Schedule'!I127+'Debt Schedule'!I140 -> 4 | J10: ='Debt Schedule'!J23+'Debt Schedule'!J36+'Debt Schedule'!J49+'Debt Schedule'!J62+'Debt Schedule'!J75+'Debt Schedule'!J88+'Debt Schedule'!J101+'Debt Schedule'!J114+'Debt Schedule'!J127+'Debt Schedule'!J140 -> 4 | K10: ='Debt Schedule'!K23+'Debt Schedule'!K36+'Debt Schedule'!K49+'Debt Schedule'!K62+'Debt Schedule'!K75+'Debt Schedule'!K88+'Debt Schedule'!K101+'Debt Schedule'!K114+'Debt Schedule'!K127+'Debt Schedule'!K140 -> 4
A11: Cash after mandatory debt service | G11: =G7+G8+G9-G10 -> 122.94742 | H11: =H7+H8+H9-H10 -> 48.553642 | I11: =I7+I8+I9-I10 -> -70.879384 | J11: =J7+J8+J9-J10 -> -137.89577 | K11: =K7+K8+K9-K10 -> -200.99169
A12: Plus: revolver draw | G12: ='Debt Schedule'!G24+'Debt Schedule'!G37+'Debt Schedule'!G50+'Debt Schedule'!G63+'Debt Schedule'!G76+'Debt Schedule'!G89+'Debt Schedule'!G102+'Debt Schedule'!G115+'Debt Schedule'!G128+'Debt Schedule'!G141 -> 0 | H12: ='Debt Schedule'!H24+'Debt Schedule'!H37+'Debt Schedule'!H50+'Debt Schedule'!H63+'Debt Schedule'!H76+'Debt Schedule'!H89+'Debt Schedule'!H102+'Debt Schedule'!H115+'Debt Schedule'!H128+'Debt Schedule'!H141 -> 0 | I12: ='Debt Schedule'!I24+'Debt Schedule'!I37+'Debt Schedule'!I50+'Debt Schedule'!I63+'Debt Schedule'!I76+'Debt Schedule'!I89+'Debt Schedule'!I102+'Debt Schedule'!I115+'Debt Schedule'!I128+'Debt Schedule'!I141 -> 0 | J12: ='Debt Schedule'!J24+'Debt Schedule'!J37+'Debt Schedule'!J50+'Debt Schedule'!J63+'Debt Schedule'!J76+'Debt Schedule'!J89+'Debt Schedule'!J102+'Debt Schedule'!J115+'Debt Schedule'!J128+'Debt Schedule'!J141 -> 0 | K12: ='Debt Schedule'!K24+'Debt Schedule'!K37+'Debt Schedule'!K50+'Debt Schedule'!K63+'Debt Schedule'!K76+'Debt Schedule'!K89+'Debt Schedule'!K102+'Debt Schedule'!K115+'Debt Schedule'!K128+'Debt Schedule'!K141 -> 0
A13: Cash available for maturities | G13: =G11+G12 -> 122.94742 | H13: =H11+H12 -> 48.553642 | I13: =I11+I12 -> -70.879384 | J13: =J11+J12 -> -137.89577 | K13: =K11+K12 -> -200.99169
A14: Less: repayment of maturing debt | G14: ='Debt Schedule'!G25+'Debt Schedule'!G38+'Debt Schedule'!G51+'Debt Schedule'!G64+'Debt Schedule'!G77+'Debt Schedule'!G90+'Debt Schedule'!G103+'Debt Schedule'!G116+'Debt Schedule'!G129+'Debt Schedule'!G142 -> 0 | H14: ='Debt Schedule'!H25+'Debt Schedule'!H38+'Debt Schedule'!H51+'Debt Schedule'!H64+'Debt Schedule'!H77+'Debt Schedule'!H90+'Debt Schedule'!H103+'Debt Schedule'!H116+'Debt Schedule'!H129+'Debt Schedule'!H142 -> 48.553642 | I14: ='Debt Schedule'!I25+'Debt Schedule'!I38+'Debt Schedule'!I51+'Debt Schedule'!I64+'Debt Schedule'!I77+'Debt Schedule'!I90+'Debt Schedule'!I103+'Debt Schedule'!I116+'Debt Schedule'!I129+'Debt Schedule'!I142 -> 0 | J14: ='Debt Schedule'!J25+'Debt Schedule'!J38+'Debt Schedule'!J51+'Debt Schedule'!J64+'Debt Schedule'!J77+'Debt Schedule'!J90+'Debt Schedule'!J103+'Debt Schedule'!J116+'Debt Schedule'!J129+'Debt Schedule'!J142 -> 0 | K14: ='Debt Schedule'!K25+'Debt Schedule'!K38+'Debt Schedule'!K51+'Debt Schedule'!K64+'Debt Schedule'!K77+'Debt Schedule'!K90+'Debt Schedule'!K103+'Debt Schedule'!K116+'Debt Schedule'!K129+'Debt Schedule'!K142 -> 0
A15: Cash before sweep | G15: =G13-G14 -> 122.94742 | H15: =H13-H14 -> 0 | I15: =I13-I14 -> -70.879384 | J15: =J13-J14 -> -137.89577 | K15: =K13-K14 -> -200.99169
A16: Funding gap (shortfall after cash & revolver) | G16: =MAX(0,-G15) -> 0 | H16: =MAX(0,-H15) -> 0 | I16: =MAX(0,-I15) -> 70.879384 | J16: =MAX(0,-J15) -> 137.89577 | K16: =MAX(0,-K15) -> 200.99169
A17: Excess cash available for sweep | G17: =MAX(0,G15-Assumptions!$C$12)*Assumptions!$C$13 -> 0 | H17: =MAX(0,H15-Assumptions!$C$12)*Assumptions!$C$13 -> 0 | I17: =MAX(0,I15-Assumptions!$C$12)*Assumptions!$C$13 -> 0 | J17: =MAX(0,J15-Assumptions!$C$12)*Assumptions!$C$13 -> 0 | K17: =MAX(0,K15-Assumptions!$C$12)*Assumptions!$C$13 -> 0
A18: Less: optional repayment (cash sweep) | G18: ='Debt Schedule'!G26+'Debt Schedule'!G39+'Debt Schedule'!G52+'Debt Schedule'!G65+'Debt Schedule'!G78+'Debt Schedule'!G91+'Debt Schedule'!G104+'Debt Schedule'!G117+'Debt Schedule'!G130+'Debt Schedule'!G143 -> 0 | H18: ='Debt Schedule'!H26+'Debt Schedule'!H39+'Debt Schedule'!H52+'Debt Schedule'!H65+'Debt Schedule'!H78+'Debt Schedule'!H91+'Debt Schedule'!H104+'Debt Schedule'!H117+'Debt Schedule'!H130+'Debt Schedule'!H143 -> 0 | I18: ='Debt Schedule'!I26+'Debt Schedule'!I39+'Debt Schedule'!I52+'Debt Schedule'!I65+'Debt Schedule'!I78+'Debt Schedule'!I91+'Debt Schedule'!I104+'Debt Schedule'!I117+'Debt Schedule'!I130+'Debt Schedule'!I143 -> 0 | J18: ='Debt Schedule'!J26+'Debt Schedule'!J39+'Debt Schedule'!J52+'Debt Schedule'!J65+'Debt Schedule'!J78+'Debt Schedule'!J91+'Debt Schedule'!J104+'Debt Schedule'!J117+'Debt Schedule'!J130+'Debt Schedule'!J143 -> 0 | K18: ='Debt Schedule'!K26+'Debt Schedule'!K39+'Debt Schedule'!K52+'Debt Schedule'!K65+'Debt Schedule'!K78+'Debt Schedule'!K91+'Debt Schedule'!K104+'Debt Schedule'!K117+'Debt Schedule'!K130+'Debt Schedule'!K143 -> 0
A19: Ending cash | F19: =Assumptions!$C$11 -> 37.87 | G19: =G15-G18 -> 122.94742 | H19: =H15-H18 -> 0 | I19: =I15-I18 -> -70.879384 | J19: =J15-J18 -> -137.89577 | K19: =K15-K18 -> -200.99169
A20: Unpaid maturities (balance left outstanding) | G20: ='Debt Schedule'!G27+'Debt Schedule'!G40+'Debt Schedule'!G53+'Debt Schedule'!G66+'Debt Schedule'!G79+'Debt Schedule'!G92+'Debt Schedule'!G105+'Debt Schedule'!G118+'Debt Schedule'!G131+'Debt Schedule'!G144 -> 0 | H20: ='Debt Schedule'!H27+'Debt Schedule'!H40+'Debt Schedule'!H53+'Debt Schedule'!H66+'Debt Schedule'!H79+'Debt Schedule'!H92+'Debt Schedule'!H105+'Debt Schedule'!H118+'Debt Schedule'!H131+'Debt Schedule'!H144 -> 751.44636 | I20: ='Debt Schedule'!I27+'Debt Schedule'!I40+'Debt Schedule'!I53+'Debt Schedule'!I66+'Debt Schedule'!I79+'Debt Schedule'!I92+'Debt Schedule'!I105+'Debt Schedule'!I118+'Debt Schedule'!I131+'Debt Schedule'!I144 -> 550 | J20: ='Debt Schedule'!J27+'Debt Schedule'!J40+'Debt Schedule'!J53+'Debt Schedule'!J66+'Debt Schedule'!J79+'Debt Schedule'!J92+'Debt Schedule'!J105+'Debt Schedule'!J118+'Debt Schedule'!J131+'Debt Schedule'!J144 -> 350 | K20: ='Debt Schedule'!K27+'Debt Schedule'!K40+'Debt Schedule'!K53+'Debt Schedule'!K66+'Debt Schedule'!K79+'Debt Schedule'!K92+'Debt Schedule'!K105+'Debt Schedule'!K118+'Debt Schedule'!K131+'Debt Schedule'!K144 -> 680
A21: Payment default? (1 = yes) | G21: =IF(OR(G16>0.001,G20>0.001),1,0) -> 0 | H21: =IF(OR(H16>0.001,H20>0.001),1,0) -> 1 | I21: =IF(OR(I16>0.001,I20>0.001),1,0) -> 1 | J21: =IF(OR(J16>0.001,J20>0.001),1,0) -> 1 | K21: =IF(OR(K16>0.001,K20>0.001),1,0) -> 1
A22: First default period flag | G22: =IF(G21=1,1,0) -> 0 | H22: =IF(AND(H21=1,SUM($G$21:G21)=0),1,0) -> 1 | I22: =IF(AND(I21=1,SUM($G$21:H21)=0),1,0) -> 0 | J22: =IF(AND(J21=1,SUM($G$21:I21)=0),1,0) -> 0 | K22: =IF(AND(K21=1,SUM($G$21:J21)=0),1,0) -> 0
A23: Check: Δ debt = draws + PIK − repayments | G23: =('Debt Schedule'!G147-'Debt Schedule'!F147)-(G12+'Operating Model'!G22-G10-G14-G18) -> 0 | H23: =('Debt Schedule'!H147-'Debt Schedule'!G147)-(H12+'Operating Model'!H22-H10-H14-H18) -> -3.8369308e-13 | I23: =('Debt Schedule'!I147-'Debt Schedule'!H147)-(I12+'Operating Model'!I22-I10-I14-I18) -> 0 | J23: =('Debt Schedule'!J147-'Debt Schedule'!I147)-(J12+'Operating Model'!J22-J10-J14-J18) -> 0 | K23: =('Debt Schedule'!K147-'Debt Schedule'!J147)-(K12+'Operating Model'!K22-K10-K14-K18) -> 0

Sheet Credit Metrics
A1: Credit Metrics, Covenants & Credit Score
A2: ="Brandywine Realty Trust · PUBLIC DATA CASE · HYPOTHETICAL INVESTMENT TERMS · Active scenario: "&Assumptions!$D$10 -> Brandywine Realty Trust · PUBLIC DATA CASE · HYPOTHETICAL INVESTMENT TERMS · Active scenario: Downside
A4: $M | C4: FY2023A | D4: FY2024A | E4: FY2025A | F4: LTM Jun-26 | G4: LTM Jun-27E | H4: LTM Jun-28E | I4: LTM Jun-29E | J4: LTM Jun-30E | K4: LTM Jun-31E
A6: Credit metrics (selected scenario)
A7: Total debt (face value) | F7: ='Debt Schedule'!F147 -> 2625.934 | G7: ='Debt Schedule'!G147 -> 2621.934 | H7: ='Debt Schedule'!H147 -> 2569.3804 | I7: ='Debt Schedule'!I147 -> 2565.3804 | J7: ='Debt Schedule'!J147 -> 2561.3804 | K7: ='Debt Schedule'!K147 -> 2557.3804
A8: Secured debt | F8: =Assumptions!$O$57*'Debt Schedule'!F28+Assumptions!$O$58*'Debt Schedule'!F41+Assumptions!$O$59*'Debt Schedule'!F54+Assumptions!$O$60*'Debt Schedule'!F67+Assumptions!$O$61*'Debt Schedule'!F80+Assumptions!$O$62*'Debt Schedule'!F93+Assumptions!$O$63*'Debt Schedule'!F106+Assumptions!$O$64*'Debt Schedule'!F119+Assumptions!$O$65*'Debt Schedule'!F132+Assumptions!$O$66*'Debt Schedule'!F145 -> 547.324 | G8: =Assumptions!$O$57*'Debt Schedule'!G28+Assumptions!$O$58*'Debt Schedule'!G41+Assumptions!$O$59*'Debt Schedule'!G54+Assumptions!$O$60*'Debt Schedule'!G67+Assumptions!$O$61*'Debt Schedule'!G80+Assumptions!$O$62*'Debt Schedule'!G93+Assumptions!$O$63*'Debt Schedule'!G106+Assumptions!$O$64*'Debt Schedule'!G119+Assumptions!$O$65*'Debt Schedule'!G132+Assumptions!$O$66*'Debt Schedule'!G145 -> 543.324 | H8: =Assumptions!$O$57*'Debt Schedule'!H28+Assumptions!$O$58*'Debt Schedule'!H41+Assumptions!$O$59*'Debt Schedule'!H54+Assumptions!$O$60*'Debt Schedule'!H67+Assumptions!$O$61*'Debt Schedule'!H80+Assumptions!$O$62*'Debt Schedule'!H93+Assumptions!$O$63*'Debt Schedule'!H106+Assumptions!$O$64*'Debt Schedule'!H119+Assumptions!$O$65*'Debt Schedule'!H132+Assumptions!$O$66*'Debt Schedule'!H145 -> 539.324 | I8: =Assumptions!$O$57*'Debt Schedule'!I28+Assumptions!$O$58*'Debt Schedule'!I41+Assumptions!$O$59*'Debt Schedule'!I54+Assumptions!$O$60*'Debt Schedule'!I67+Assumptions!$O$61*'Debt Schedule'!I80+Assumptions!$O$62*'Debt Schedule'!I93+Assumptions!$O$63*'Debt Schedule'!I106+Assumptions!$O$64*'Debt Schedule'!I119+Assumptions!$O$65*'Debt Schedule'!I132+Assumptions!$O$66*'Debt Schedule'!I145 -> 535.324 | J8: =Assumptions!$O$57*'Debt Schedule'!J28+Assumptions!$O$58*'Debt Schedule'!J41+Assumptions!$O$59*'Debt Schedule'!J54+Assumptions!$O$60*'Debt Schedule'!J67+Assumptions!$O$61*'Debt Schedule'!J80+Assumptions!$O$62*'Debt Schedule'!J93+Assumptions!$O$63*'Debt Schedule'!J106+Assumptions!$O$64*'Debt Schedule'!J119+Assumptions!$O$65*'Debt Schedule'!J132+Assumptions!$O$66*'Debt Schedule'!J145 -> 531.324 | K8: =Assumptions!$O$57*'Debt Schedule'!K28+Assumptions!$O$58*'Debt Schedule'!K41+Assumptions!$O$59*'Debt Schedule'!K54+Assumptions!$O$60*'Debt Schedule'!K67+Assumptions!$O$61*'Debt Schedule'!K80+Assumptions!$O$62*'Debt Schedule'!K93+Assumptions!$O$63*'Debt Schedule'!K106+Assumptions!$O$64*'Debt Schedule'!K119+Assumptions!$O$65*'Debt Schedule'!K132+Assumptions!$O$66*'Debt Schedule'!K145 -> 527.324
A9: Net debt | F9: =F7-'Cash Flow'!F19 -> 2588.064 | G9: =G7-'Cash Flow'!G19 -> 2498.9866 | H9: =H7-'Cash Flow'!H19 -> 2569.3804 | I9: =I7-'Cash Flow'!I19 -> 2636.2597 | J9: =J7-'Cash Flow'!J19 -> 2699.2761 | K9: =K7-'Cash Flow'!K19 -> 2758.372
A10: Gross debt / EBITDA | F10: =IF('Operating Model'!F17>0,F7/'Operating Model'!F17,0) -> 9.9212776 | G10: =IF('Operating Model'!G17>0,G7/'Operating Model'!G17,0) -> 11.195432 | H10: =IF('Operating Model'!H17>0,H7/'Operating Model'!H17,0) -> 11.660147 | I10: =IF('Operating Model'!I17>0,I7/'Operating Model'!I17,0) -> 11.641995 | J10: =IF('Operating Model'!J17>0,J7/'Operating Model'!J17,0) -> 11.391318 | K10: =IF('Operating Model'!K17>0,K7/'Operating Model'!K17,0) -> 11.147173
A11: Net debt / EBITDA | F11: =IF('Operating Model'!F17>0,F9/'Operating Model'!F17,0) -> 9.7781976 | G11: =IF('Operating Model'!G17>0,G9/'Operating Model'!G17,0) -> 10.670457 | H11: =IF('Operating Model'!H17>0,H9/'Operating Model'!H17,0) -> 11.660147 | I11: =IF('Operating Model'!I17>0,I9/'Operating Model'!I17,0) -> 11.963654 | J11: =IF('Operating Model'!J17>0,J9/'Operating Model'!J17,0) -> 12.004587 | K11: =IF('Operating Model'!K17>0,K9/'Operating Model'!K17,0) -> 12.023261
A12: Interest coverage (EBITDA / cash interest) | F12: =IF('Operating Model'!F23>0,'Operating Model'!F17/'Operating Model'!F23,0) -> 1.7233258 | G12: =IF('Operating Model'!G21>0,'Operating Model'!G17/'Operating Model'!G21,0) -> 1.2497904 | H12: =IF('Operating Model'!H21>0,'Operating Model'!H17/'Operating Model'!H21,0) -> 1.1831122 | I12: =IF('Operating Model'!I21>0,'Operating Model'!I17/'Operating Model'!I21,0) -> 1.2058659 | J12: =IF('Operating Model'!J21>0,'Operating Model'!J17/'Operating Model'!J21,0) -> 1.2332475 | K12: =IF('Operating Model'!K21>0,'Operating Model'!K17/'Operating Model'!K21,0) -> 1.2611258
A13: EBIT / interest | F13: =IF('Operating Model'!F23>0,'Operating Model'!F20/'Operating Model'!F23,0) -> 0.51687339 | G13: =IF('Operating Model'!G21>0,'Operating Model'!G20/'Operating Model'!G21,0) -> 0.32030377 | H13: =IF('Operating Model'!H21>0,'Operating Model'!H20/'Operating Model'!H21,0) -> 0.27600177 | I13: =IF('Operating Model'!I21>0,'Operating Model'!I20/'Operating Model'!I21,0) -> 0.28130984 | J13: =IF('Operating Model'!J21>0,'Operating Model'!J20/'Operating Model'!J21,0) -> 0.29734601 | K13: =IF('Operating Model'!K21>0,'Operating Model'!K20/'Operating Model'!K21,0) -> 0.31373497
A14: FCF / debt | F14: =IF(F7>0,'Operating Model'!F30/F7,0) -> -0.0027445473 | G14: =IF(G7>0,'Operating Model'!G30/G7,0) -> -0.023235741 | H14: =IF(H7>0,'Operating Model'!H30/H7,0) -> -0.027397181 | I14: =IF(I7>0,'Operating Model'!I30/I7,0) -> -0.026069968 | J14: =IF(J7>0,'Operating Model'!J30/J7,0) -> -0.024602511 | K14: =IF(K7>0,'Operating Model'!K30/K7,0) -> -0.023107988
A15: Debt service coverage ((EBITDA − capex − tax) / (cash interest + amortization)) | G15: =IF('Operating Model'!G21+'Cash Flow'!G10>0,('Operating Model'!G17-'Operating Model'!G28-'Operating Model'!G25)/('Operating Model'!G21+'Cash Flow'!G10),0) -> 0.78314878 | H15: =IF('Operating Model'!H21+'Cash Flow'!H10>0,('Operating Model'!H17-'Operating Model'!H28-'Operating Model'!H25)/('Operating Model'!H21+'Cash Flow'!H10),0) -> 0.72837613 | I15: =IF('Operating Model'!I21+'Cash Flow'!I10>0,('Operating Model'!I17-'Operating Model'!I28-'Operating Model'!I25)/('Operating Model'!I21+'Cash Flow'!I10),0) -> 0.74208422 | J15: =IF('Operating Model'!J21+'Cash Flow'!J10>0,('Operating Model'!J17-'Operating Model'!J28-'Operating Model'!J25)/('Operating Model'!J21+'Cash Flow'!J10),0) -> 0.7634683 | K15: =IF('Operating Model'!K21+'Cash Flow'!K10>0,('Operating Model'!K17-'Operating Model'!K28-'Operating Model'!K25)/('Operating Model'!K21+'Cash Flow'!K10),0) -> 0.78526806
