Workbook

Sheet Cover
A1: CreditIQ — AMC Networks (AMC Global Media) credit underwriting model
A2: PUBLIC DATA CASE · HYPOTHETICAL INVESTMENT TERMS · $ in millions · as of 2026-06-30
A3: Corporate credit — senior secured notes of a levered, declining linear-TV network
A4: Model status | B4: ='Investment Summary'!$D$53 -> ALL CHECKS PASS
A5: Active scenario | B5: =Assumptions!$D$10 -> Downside
A6: Recommendation (rule-based; see Investment Summary) | B6: ='Investment Summary'!$C$4 -> HOLD
A8: Colour conventions
A9: Blue on pale yellow | B9: Hardcoded input: sourced historical data, explicit assumption, scenario / transaction / macro input, covenant threshold, sensitivity axis, structural block parameter.
A10: Black | B10: Formula or calculation. No outputs, subtotals or metrics are hardcoded anywhere in this workbook.
A11: Green | B11: Direct link to a cell on another worksheet.
A12: Grey fill | B12: Labels and headers.
A14: Flow of logic | B14: Assumptions + Historical → Operating Model → Debt Schedule ↔ Cash Flow → Credit Metrics & Covenants → Recovery → Returns → Sensitivities → Investment Summary
A15: Data classes | B15: PUBLIC FILING = reported inputs · ANALYST PROJECTION = scenario drivers · UNDERWRITING ASSUMPTION = hypothetical purchase price / terms · DEMO = fictional
A17: Tabs
A18: Assumptions | B18: All inputs, scenario drivers, covenants, selector
A19: Historical Financials | B19: Sourced statements; derived lines and LTM calculated
A20: Operating Model | B20: Income statement and FCF, history + projection
A21: Debt Schedule | B21: Per-tranche roll-forward, floors, PIK, refinancing test, sweep
A22: Cash Flow | B22: Cash waterfall, funding gap, default test
A23: Credit Metrics | B23: Ratios, covenant compliance, transparent credit score
A24: Scenarios | B24: Base / Downside / Severe side by side + reconciliation
A25: Capital Structure | B25: Tranches, leverage through the stack, maturity wall & refinancing requirement
A26: Recovery | B26: Seniority waterfall with collateral pools and deficiency claims
A27: Returns | B27: Face, price, coupon, yield, recovery; IRR, XIRR, MOIC
A28: Sensitivities | B28: Seven formula-driven tables
A29: Investment Summary | B29: Live outputs, recommendation evidence, integrity checks
... A31: Calc Engine | B31: Supporting: 63 simultaneous model runs
A33: Validation: docs/MODEL_VALIDATION.md · Audit: scripts/audit_model.py · Change-impact harness: scripts/model_harness.py

Sheet Assumptions
A1: Assumptions — AMC Networks (AMC Global Media): all explicit inputs live on this tab
A2: PUBLIC DATA CASE · HYPOTHETICAL INVESTMENT TERMS · Blue on pale yellow = hardcoded input · Black = formula · Green = link to another sheet · $ in millions
A4: 1. General & model settings
A5: Company | C5: AMC Networks (AMC Global Media)
A6: Base period label (year in which the base / LTM period ends) | C6: 2026
A7: Fiscal-period end month (12 = calendar FY; 6 = LTM June periods) | C7: 6
A8: As-of / entry date | C8: 46203
A9: Cash tax rate on positive EBT | B9: % of EBT | C9: 0.25
A10: ACTIVE SCENARIO selector (1=Base, 2=Downside, 3=Severe) | B10: select 1 / 2 / 3 | C10: 2 | D10: =CHOOSE(C10,"Base Case","Downside","Severe Downside") -> Downside
A11: Cash & equivalents at base date (balance sheet) | B11: $M | C11: 463.996
A12: Minimum operating cash | B12: $M | C12: 150
A13: Cash sweep (% of excess cash applied to prepayable debt) | B13: % | C13: 0
A14: Recovery value override (leave blank = model-derived) | B14: $M, optional
A15: Administrative / DIP costs | B15: % of recovery value | C15: 0.04
A16: Accrued unpaid interest included in claims | B16: months | C16: 3
A17: Rank at which secured deficiency claims join general creditors | C17: 99
A18: Maturity alert window | B18: periods from base | C18: 2
A19: Materiality threshold for maturity alert | B19: % of total debt | C19: 0.25
A20: Concentration threshold (single-period maturities) | B20: % of total debt | C20: 0.3
A21: Market-implied EV / EBITDA (analyst assumption) | B21: x | C21: 5.5
A22: Credit score: maturity-risk window | B22: periods | C22: 3
A24: 2. Collateral / asset base (recovery & LTV)
A25: Book value of program rights, receivables, PP&E and intangibles at 2026-06-30 (derived from the 10-Q balance sheet); liquidation recovery on that base is an analyst assumption (30%).
A26: Program rights, net | C26: 1627.782 | D26: amcx.program_rights.2026-06-30
A27: Accounts receivable, trade | C27: 547.187 | D27: amcx.ar.2026-06-30
A28: Property and equipment, net | C28: 110.555 | D28: amcx.ppe.2026-06-30
A29: Intangible assets, net | C29: 169.447 | D29: amcx.intangibles.2026-06-30
A30: Total asset base | C30: =SUM(C26:C29) -> 2454.971
A32: 3. Transaction / position being underwritten — HYPOTHETICAL INVESTMENT TERMS
A33: Target tranche # (row in the debt table below) | C33: 1
A34: Face value held (legal claim) | B34: $M | C34: 100
A35: Purchase price / OID (UNDERWRITING ASSUMPTION) | B35: % of face | C35: 95
A36: Transaction fees | B36: % of cost | C36: 0
A37: Hold period (whole years, 1-5) | B37: periods | C37: 3
A38: Coupon payments per year on target tranche (contractual-timing cross-check only) | B38: per year | C38: 2
A39: Default → recovery cash receipt lag | B39: periods | C39: 1
A40: Required IRR (hurdle) | C40: 0.12
A41: Minimum acceptable downside IRR | C41: 0
A42: Minimum yield to maturity | C42: 0.1
A43: Maximum net leverage (net debt / EBITDA) | C43: 6
...

Sheet Historical Financials
A1: Historical Financials — AMC Networks (AMC Global Media)
A2: PUBLIC FILING data (blue = reported inputs, each traced to a datapoint on the Sources tab). All subtotals, EBITDA, EBIT, net income, FCF and LTM columns are formulas.
A4: US$ millions | B4: FY2023A | C4: FY2024A | D4: FY2025A | E4: H1-25A | F4: H1-26A | G4: LTM Jun-26 | H4: Source datapoint IDs (see Sources tab)
A5: A. Reported inputs
A6: Revenues, net | B6: 2711.877 | C6: 2421.314 | D6: 2311.801 | E6: 1155.257 | F6: 1089.622 | G6: =D6+F6-E6 -> 2246.166 | H6: amcx.revenue.* (5 datapoints)
A7: Technical and operating (excl. D&A) | B7: 1327.5 | C7: 1132.593 | D7: 1141.393 | E7: 551.222 | F7: 571.961 | G7: =D7+F7-E7 -> 1162.132 | H7: amcx.direct_costs.* (5 datapoints)
A8: Selling, general and administrative | B8: 764.087 | C8: 781.329 | D8: 818.341 | E8: 419.679 | F8: 426.623 | G8: =D8+F8-E8 -> 825.285 | H8: amcx.sga.* (5 datapoints)
A9: Share-based compensation (AOI add-back) | B9: 25.665 | C9: 26.051 | D9: 25.33 | E9: 13.8 | F9: 12.826 | G9: =D9+F9-E9 -> 24.356 | H9: amcx.sbc.* (5 datapoints)
A10: Cloud computing amortization (AOI add-back) | B10: 10.543 | C10: 13.452 | D10: 10.733 | E10: 5.938 | F10: 4.416 | G10: =D10+F10-E10 -> 9.211 | H10: amcx.cloud_amort.* (5 datapoints)
A11: Majority-owned equity-investee AOI (AOI add-back) | B11: 13.606 | C11: 15.678 | D11: 23.744 | E11: 9.777 | F11: 6.762 | G11: =D11+F11-E11 -> 20.729 | H11: amcx.jv_aoi.* (5 datapoints)
A12: Depreciation and amortization | B12: 107.402 | C12: 98.015 | D12: 94.425 | E12: 47.372 | F12: 38.243 | G12: =D12+F12-E12 -> 85.296 | H12: amcx.da.* (5 datapoints)
A13: Interest expense | B13: 152.703 | C13: 166.186 | D13: 172.353 | E13: 85.852 | F13: 84.012 | G13: =D13+F13-E13 -> 170.513 | H13: amcx.interest_expense.* (5 datapoints)
A14: Income tax expense (benefit) | B14: 94.606 | C14: 43.49 | D14: 46.226 | E14: 31.027 | F14: -11.413 | G14: =D14+F14-E14 -> 3.786 | H14: amcx.taxes.* (5 datapoints)
A15: Net cash provided by operating activities | B15: 203.919 | C15: 375.615 | D15: 305.67 | E15: 211.596 | F15: 124.659 | G15: =D15+F15-E15 -> 218.733 | H15: amcx.cfo.* (5 datapoints)
A16: Capital expenditures | B16: 35.207 | C16: 44.775 | D16: 33.303 | E16: 21.67 | F16: 16.577 | G16: =D16+F16-E16 -> 28.21 | H16: amcx.capex.* (5 datapoints)
A17: Impairment and other charges (memo, excluded from EBITDA) | B17: 96.689 | C17: 399.513 | D17: 97.784 | E17: 0 | F17: 0 | G17: =D17+F17-E17 -> 97.784 | H17: amcx.impairment.* (3 datapoints)
... A20: Adjusted operating income — company reported (check) | B20: 670.104 | C20: 562.573 | D20: 411.874 | E20: 213.871 | F20: 115.042 | G20: =D20+F20-E20 -> 313.045 | H20: amcx.aoi_reported.* (5 datapoints)
A22: B. Standardized statements (calculated)
A23: Revenue | B23: =B6 -> 2711.877 | C23: =C6 -> 2421.314 | D23: =D6 -> 2311.801 | E23: =E6 -> 1155.257 | F23: =F6 -> 1089.622 | G23: =G6 -> 2246.166
A24: Direct costs / COGS | B24: =B7 -> 1327.5 | C24: =C7 -> 1132.593 | D24: =D7 -> 1141.393 | E24: =E7 -> 551.222 | F24: =F7 -> 571.961 | G24: =G7 -> 1162.132
A25: Gross profit (NOI for real estate) | B25: =B23-B24 -> 1384.377 | C25: =C23-C24 -> 1288.721 | D25: =D23-D24 -> 1170.408 | E25: =E23-E24 -> 604.035 | F25: =F23-F24 -> 517.661 | G25: =G23-G24 -> 1084.034
A26: Operating expenses, cash & adjusted (excl. D&A and non-cash add-backs) | B26: =B8-B9-B10-B11 -> 714.273 | C26: =C8-C9-C10-C11 -> 726.148 | D26: =D8-D9-D10-D11 -> 758.534 | E26: =E8-E9-E10-E11 -> 390.164 | F26: =F8-F9-F10-F11 -> 402.619 | G26: =G8-G9-G10-G11 -> 770.989
A27: EBITDA (company-adjusted basis) | B27: =B25-B26 -> 670.104 | C27: =C25-C26 -> 562.573 | D27: =D25-D26 -> 411.874 | E27: =E25-E26 -> 213.871 | F27: =F25-F26 -> 115.042 | G27: =G25-G26 -> 313.045
A28: Depreciation & amortization | B28: =B12 -> 107.402 | C28: =C12 -> 98.015 | D28: =D12 -> 94.425 | E28: =E12 -> 47.372 | F28: =F12 -> 38.243 | G28: =G12 -> 85.296
A29: Share-based compensation (non-cash add-back) | B29: =B9 -> 25.665 | C29: =C9 -> 26.051 | D29: =D9 -> 25.33 | E29: =E9 -> 13.8 | F29: =F9 -> 12.826 | G29: =G9 -> 24.356
A30: EBIT (EBITDA − D&A − SBC) | B30: =B27-B28-B29 -> 537.037 | C30: =C27-C28-C29 -> 438.507 | D30: =D27-D28-D29 -> 292.119 | E30: =E27-E28-E29 -> 152.699 | F30: =F27-F28-F29 -> 63.973 | G30: =G27-G28-G29 -> 203.393
A31: Interest expense | B31: =B13 -> 152.703 | C31: =C13 -> 166.186 | D31: =D13 -> 172.353 | E31: =E13 -> 85.852 | F31: =F13 -> 84.012 | G31: =G13 -> 170.513
A32: EBT | B32: =B30-B31 -> 384.334 | C32: =C30-C31 -> 272.321 | D32: =D30-D31 -> 119.766 | E32: =E30-E31 -> 66.847 | F32: =F30-F31 -> -20.039 | G32: =G30-G31 -> 32.88
A33: Income taxes | B33: =B14 -> 94.606 | C33: =C14 -> 43.49 | D33: =D14 -> 46.226 | E33: =E14 -> 31.027 | F33: =F14 -> -11.413 | G33: =G14 -> 3.786
A34: Net income (model basis; excludes impairments and one-offs) | B34: =B32-B33 -> 289.728 | C34: =C32-C33 -> 228.831 | D34: =D32-D33 -> 73.54 | E34: =E32-E33 -> 35.82 | F34: =F32-F33 -> -8.626 | G34: =G32-G33 -> 29.094
A35: Capex (incl. leasing costs where applicable) | B35: =B16 -> 35.207 | C35: =C16 -> 44.775 | D35: =D16 -> 33.303 | E35: =E16 -> 21.67 | F35: =F16 -> 16.577 | G35: =G16 -> 28.21
A36: Net cash provided by operating activities (reported) | B36: =B15 -> 203.919 | C36: =C15 -> 375.615 | D36: =D15 -> 305.67 | E36: =E15 -> 211.596 | F36: =F15 -> 124.659 | G36: =G15 -> 218.733
A37: Free cash flow (CFO − capex) | B37: =B36-B35 -> 168.712 | C37: =C36-C35 -> 330.84 | D37: =D36-D35 -> 272.367 | E37: =E36-E35 -> 189.926 | F37: =F36-F35 -> 108.082 | G37: =G36-G35 -> 190.523
A38: Δ working capital & other (derived plug: NI + D&A + SBC − capex − FCF) | B38: =B34+B28+B29-B35-B37 -> 218.876 | C38: =C34+C28+C29-C35-C37 -> -22.718 | D38: =D34+D28+D29-D35-D37 -> -112.375 | E38: =E34+E28+E29-E35-E37 -> -114.604 | F38: =F34+F28+F29-F35-F37 -> -82.216 | G38: =G34+G28+G29-G35-G37 -> -79.987
A40: C. Ratios & checks (calculated)
A41: Gross margin | B41: =B25/B23 -> 0.51048665 | C41: =C25/C23 -> 0.53224035 | D41: =D25/D23 -> 0.50627541 | E41: =E25/E23 -> 0.52285768 | F41: =F25/F23 -> 0.4750831 | G41: =G25/G23 -> 0.48261527
A42: EBITDA margin | B42: =B27/B23 -> 0.2470997 | C42: =C27/C23 -> 0.23234203 | D42: =D27/D23 -> 0.17816153 | E42: =E27/E23 -> 0.1851285 | F42: =F27/F23 -> 0.10557973 | G42: =G27/G23 -> 0.1393686
A43: Revenue growth (YoY) | C43: =C23/B23-1 -> -0.10714461 | D43: =D23/C23-1 -> -0.045228748 | F43: =F23/E23-1 -> -0.056814198
A44: EBITDA growth (YoY) | C44: =C27/B27-1 -> -0.16046912 | D44: =D27/C27-1 -> -0.26787457 | F44: =F27/E27-1 -> -0.46209631
A45: Check: Calculated AOI vs company-reported AOI (should be 0.000) | B45: =B27-B20 -> 0 | C45: =C27-C20 -> 0 | D45: =D27-D20 -> 0 | E45: =E27-E20 -> 0 | F45: =F27-F20 -> 0 | G45: =G27-G20 -> 0

Sheet Operating Model
A1: Operating Model — selected scenario (assumptions → statements)
A2: ="AMC Networks (AMC Global Media) · PUBLIC DATA CASE · HYPOTHETICAL INVESTMENT TERMS · Active scenario: "&Assumptions!$D$10 -> AMC Networks (AMC Global Media) · PUBLIC DATA CASE · HYPOTHETICAL INVESTMENT TERMS · Active scenario: Downside
A4: $M | C4: FY2023A | D4: FY2024A | E4: FY2025A | F4: LTM Jun-26 | G4: LTM Jun-27E | H4: LTM Jun-28E | I4: LTM Jun-29E | J4: LTM Jun-30E | K4: LTM Jun-31E
A6: Operating drivers (selected scenario → Assumptions)
A7: Model period (year in which the period ends) | C7: =D7-1 -> 2023 | D7: =E7-1 -> 2024 | E7: =F7-1 -> 2025 | F7: =Assumptions!$C$6 -> 2026 | G7: =F7+1 -> 2027 | H7: =G7+1 -> 2028 | I7: =H7+1 -> 2029 | J7: =I7+1 -> 2030 | K7: =J7+1 -> 2031
A8: Projection period # | G8: =G7-Assumptions!$C$6 -> 1 | H8: =H7-Assumptions!$C$6 -> 2 | I8: =I7-Assumptions!$C$6 -> 3 | J8: =J7-Assumptions!$C$6 -> 4 | K8: =K7-Assumptions!$C$6 -> 5
A9: Revenue growth | G9: =CHOOSE(Assumptions!$C$10,Assumptions!$G$71,Assumptions!$G$90,Assumptions!$G$109) -> -0.08 | H9: =CHOOSE(Assumptions!$C$10,Assumptions!$H$71,Assumptions!$H$90,Assumptions!$H$109) -> -0.07 | I9: =CHOOSE(Assumptions!$C$10,Assumptions!$I$71,Assumptions!$I$90,Assumptions!$I$109) -> -0.06 | J9: =CHOOSE(Assumptions!$C$10,Assumptions!$J$71,Assumptions!$J$90,Assumptions!$J$109) -> -0.05 | K9: =CHOOSE(Assumptions!$C$10,Assumptions!$K$71,Assumptions!$K$90,Assumptions!$K$109) -> -0.05
A10: Gross margin | G10: =CHOOSE(Assumptions!$C$10,Assumptions!$G$72,Assumptions!$G$91,Assumptions!$G$110) -> 0.46324667 | H10: =CHOOSE(Assumptions!$C$10,Assumptions!$H$72,Assumptions!$H$91,Assumptions!$H$110) -> 0.45324667 | I10: =CHOOSE(Assumptions!$C$10,Assumptions!$I$72,Assumptions!$I$91,Assumptions!$I$110) -> 0.44824667 | J10: =CHOOSE(Assumptions!$C$10,Assumptions!$J$72,Assumptions!$J$91,Assumptions!$J$110) -> 0.44324667 | K10: =CHOOSE(Assumptions!$C$10,Assumptions!$K$72,Assumptions!$K$91,Assumptions!$K$110) -> 0.44324667
A11: EBITDA margin | G11: =CHOOSE(Assumptions!$C$10,Assumptions!$G$73,Assumptions!$G$92,Assumptions!$G$111) -> 0.12 | H11: =CHOOSE(Assumptions!$C$10,Assumptions!$H$73,Assumptions!$H$92,Assumptions!$H$111) -> 0.11 | I11: =CHOOSE(Assumptions!$C$10,Assumptions!$I$73,Assumptions!$I$92,Assumptions!$I$111) -> 0.105 | J11: =CHOOSE(Assumptions!$C$10,Assumptions!$J$73,Assumptions!$J$92,Assumptions!$J$111) -> 0.1 | K11: =CHOOSE(Assumptions!$C$10,Assumptions!$K$73,Assumptions!$K$92,Assumptions!$K$111) -> 0.1
A12: Income statement ($M)
A13: Revenue | C13: ='Historical Financials'!B23 -> 2711.877 | D13: ='Historical Financials'!C23 -> 2421.314 | E13: ='Historical Financials'!D23 -> 2311.801 | F13: ='Historical Financials'!G23 -> 2246.166 | G13: =F13*(1+G9) -> 2066.4727 | H13: =G13*(1+H9) -> 1921.8196 | I13: =H13*(1+I9) -> 1806.5105 | J13: =I13*(1+J9) -> 1716.1849 | K13: =J13*(1+K9) -> 1630.3757
A14: Direct costs / COGS | C14: ='Historical Financials'!B24 -> 1327.5 | D14: ='Historical Financials'!C24 -> 1132.593 | E14: ='Historical Financials'!D24 -> 1141.393 | F14: ='Historical Financials'!G24 -> 1162.132 | G14: =G13*(1-G10) -> 1109.1861 | H14: =H13*(1-H10) -> 1050.7613 | I14: =I13*(1-I10) -> 996.74816 | J14: =J13*(1-J10) -> 955.49167 | K14: =K13*(1-K10) -> 907.71709
A15: Gross profit (NOI for real estate) | C15: =C13-C14 -> 1384.377 | D15: =D13-D14 -> 1288.721 | E15: =E13-E14 -> 1170.408 | F15: =F13-F14 -> 1084.034 | G15: =G13-G14 -> 957.28661 | H15: =H13-H14 -> 871.05835 | I15: =I13-I14 -> 809.76229 | J15: =J13-J14 -> 760.69326 | K15: =K13-K14 -> 722.65859
A16: Operating expenses (implied: gross profit − EBITDA) | C16: ='Historical Financials'!B26 -> 714.273 | D16: ='Historical Financials'!C26 -> 726.148 | E16: ='Historical Financials'!D26 -> 758.534 | F16: ='Historical Financials'!G26 -> 770.989 | G16: =G15-G17 -> 709.30988 | H16: =H15-H17 -> 659.65819 | I16: =I15-I17 -> 620.0787 | J16: =J15-J17 -> 589.07476 | K16: =K15-K17 -> 559.62102
A17: EBITDA | C17: =C15-C16 -> 670.104 | D17: =D15-D16 -> 562.573 | E17: =E15-E16 -> 411.874 | F17: =F15-F16 -> 313.045 | G17: =G13*G11 -> 247.97673 | H17: =H13*H11 -> 211.40016 | I17: =I13*I11 -> 189.6836 | J17: =J13*J11 -> 171.61849 | K17: =K13*K11 -> 163.03757
A18: D&A | C18: ='Historical Financials'!B28 -> 107.402 | D18: ='Historical Financials'!C28 -> 98.015 | E18: ='Historical Financials'!D28 -> 94.425 | F18: ='Historical Financials'!G28 -> 85.296 | G18: =G13*'Historical Financials'!G28/'Historical Financials'!G23 -> 78.47232 | H18: =H13*'Historical Financials'!G28/'Historical Financials'!G23 -> 72.979258 | I18: =I13*'Historical Financials'!G28/'Historical Financials'!G23 -> 68.600502 | J18: =J13*'Historical Financials'!G28/'Historical Financials'!G23 -> 65.170477 | K18: =K13*'Historical Financials'!G28/'Historical Financials'!G23 -> 61.911953
A19: Share-based compensation (non-cash) | C19: ='Historical Financials'!B29 -> 25.665 | D19: ='Historical Financials'!C29 -> 26.051 | E19: ='Historical Financials'!D29 -> 25.33 | F19: ='Historical Financials'!G29 -> 24.356 | G19: =G13*'Historical Financials'!G29/'Historical Financials'!G23 -> 22.40752 | H19: =H13*'Historical Financials'!G29/'Historical Financials'!G23 -> 20.838994 | I19: =I13*'Historical Financials'!G29/'Historical Financials'!G23 -> 19.588654 | J19: =J13*'Historical Financials'!G29/'Historical Financials'!G23 -> 18.609221 | K19: =K13*'Historical Financials'!G29/'Historical Financials'!G23 -> 17.67876
A20: EBIT | C20: =C17-C18-C19 -> 537.037 | D20: =D17-D18-D19 -> 438.507 | E20: =E17-E18-E19 -> 292.119 | F20: =F17-F18-F19 -> 203.393 | G20: =G17-G18-G19 -> 147.09689 | H20: =H17-H18-H19 -> 117.58191 | I20: =I17-I18-I19 -> 101.49444 | J20: =J17-J18-J19 -> 87.838795 | K20: =K17-K18-K19 -> 83.446855
A21: Cash interest expense (Debt Schedule) | G21: ='Debt Schedule'!G21+'Debt Schedule'!G34+'Debt Schedule'!G47 -> 155.95467 | H21: ='Debt Schedule'!H21+'Debt Schedule'!H34+'Debt Schedule'!H47 -> 155.95467 | I21: ='Debt Schedule'!I21+'Debt Schedule'!I34+'Debt Schedule'!I47 -> 155.95467 | J21: ='Debt Schedule'!J21+'Debt Schedule'!J34+'Debt Schedule'!J47 -> 138.08529 | K21: ='Debt Schedule'!K21+'Debt Schedule'!K34+'Debt Schedule'!K47 -> 138.08529
A22: PIK interest (non-cash) | G22: ='Debt Schedule'!G22+'Debt Schedule'!G35+'Debt Schedule'!G48 -> 0 | H22: ='Debt Schedule'!H22+'Debt Schedule'!H35+'Debt Schedule'!H48 -> 0 | I22: ='Debt Schedule'!I22+'Debt Schedule'!I35+'Debt Schedule'!I48 -> 0 | J22: ='Debt Schedule'!J22+'Debt Schedule'!J35+'Debt Schedule'!J48 -> 0 | K22: ='Debt Schedule'!K22+'Debt Schedule'!K35+'Debt Schedule'!K48 -> 0
A23: Interest expense | C23: ='Historical Financials'!B31 -> 152.703 | D23: ='Historical Financials'!C31 -> 166.186 | E23: ='Historical Financials'!D31 -> 172.353 | F23: ='Historical Financials'!G31 -> 170.513 | G23: =G21+G22 -> 155.95467 | H23: =H21+H22 -> 155.95467 | I23: =I21+I22 -> 155.95467 | J23: =J21+J22 -> 138.08529 | K23: =K21+K22 -> 138.08529
A24: EBT | C24: =C20-C23 -> 384.334 | D24: =D20-D23 -> 272.321 | E24: =E20-E23 -> 119.766 | F24: =F20-F23 -> 32.88 | G24: =G20-G23 -> -8.8577836 | H24: =H20-H23 -> -38.372762 | I24: =I20-I23 -> -54.460229 | J24: =J20-J23 -> -50.246495 | K24: =K20-K23 -> -54.638435
A25: Taxes | C25: ='Historical Financials'!B33 -> 94.606 | D25: ='Historical Financials'!C33 -> 43.49 | E25: ='Historical Financials'!D33 -> 46.226 | F25: ='Historical Financials'!G33 -> 3.786 | G25: =MAX(0,G24)*Assumptions!$C$9 -> 0 | H25: =MAX(0,H24)*Assumptions!$C$9 -> 0 | I25: =MAX(0,I24)*Assumptions!$C$9 -> 0 | J25: =MAX(0,J24)*Assumptions!$C$9 -> 0 | K25: =MAX(0,K24)*Assumptions!$C$9 -> 0
A26: Net income (model basis) | C26: =C24-C25 -> 289.728 | D26: =D24-D25 -> 228.831 | E26: =E24-E25 -> 73.54 | F26: =F24-F25 -> 29.094 | G26: =G24-G25 -> -8.8577836 | H26: =H24-H25 -> -38.372762 | I26: =I24-I25 -> -54.460229 | J26: =J24-J25 -> -50.246495 | K26: =K24-K25 -> -54.638435
A27: Free cash flow build ($M)
A28: Capex | C28: ='Historical Financials'!B35 -> 35.207 | D28: ='Historical Financials'!C35 -> 44.775 | E28: ='Historical Financials'!D35 -> 33.303 | F28: ='Historical Financials'!G35 -> 28.21 | G28: =G13*CHOOSE(Assumptions!$C$10,Assumptions!$C$75,Assumptions!$C$94,Assumptions!$C$113) -> 26.864145 | H28: =H13*CHOOSE(Assumptions!$C$10,Assumptions!$C$75,Assumptions!$C$94,Assumptions!$C$113) -> 24.983655 | I28: =I13*CHOOSE(Assumptions!$C$10,Assumptions!$C$75,Assumptions!$C$94,Assumptions!$C$113) -> 23.484636 | J28: =J13*CHOOSE(Assumptions!$C$10,Assumptions!$C$75,Assumptions!$C$94,Assumptions!$C$113) -> 22.310404 | K28: =K13*CHOOSE(Assumptions!$C$10,Assumptions!$C$75,Assumptions!$C$94,Assumptions!$C$113) -> 21.194884
A29: Working capital & other cash items (+ = outflow) | C29: ='Historical Financials'!B38 -> 218.876 | D29: ='Historical Financials'!C38 -> -22.718 | E29: ='Historical Financials'!D38 -> -112.375 | F29: ='Historical Financials'!G38 -> -79.987 | G29: =CHOOSE(Assumptions!$C$10,Assumptions!$C$76,Assumptions!$C$95,Assumptions!$C$114)*(G13-F13)+CHOOSE(Assumptions!$C$10,Assumptions!$C$77,Assumptions!$C$96,Assumptions!$C$115)*G13 -> 10.332364 | H29: =CHOOSE(Assumptions!$C$10,Assumptions!$C$76,Assumptions!$C$95,Assumptions!$C$114)*(H13-G13)+CHOOSE(Assumptions!$C$10,Assumptions!$C$77,Assumptions!$C$96,Assumptions!$C$115)*H13 -> 9.6090981 | I29: =CHOOSE(Assumptions!$C$10,Assumptions!$C$76,Assumptions!$C$95,Assumptions!$C$114)*(I13-H13)+CHOOSE(Assumptions!$C$10,Assumptions!$C$77,Assumptions!$C$96,Assumptions!$C$115)*I13 -> 9.0325523 | J29: =CHOOSE(Assumptions!$C$10,Assumptions!$C$76,Assumptions!$C$95,Assumptions!$C$114)*(J13-I13)+CHOOSE(Assumptions!$C$10,Assumptions!$C$77,Assumptions!$C$96,Assumptions!$C$115)*J13 -> 8.5809246 | K29: =CHOOSE(Assumptions!$C$10,Assumptions!$C$76,Assumptions!$C$95,Assumptions!$C$114)*(K13-J13)+CHOOSE(Assumptions!$C$10,Assumptions!$C$77,Assumptions!$C$96,Assumptions!$C$115)*K13 -> 8.1518784
A30: Free cash flow (NI + D&A + SBC + PIK − capex − ΔNWC/other) | C30: ='Historical Financials'!B37 -> 168.712 | D30: ='Historical Financials'!C37 -> 330.84 | E30: ='Historical Financials'!D37 -> 272.367 | F30: ='Historical Financials'!G37 -> 190.523 | G30: =G26+G18+G19+G22-G28-G29 -> 54.825547 | H30: =H26+H18+H19+H22-H28-H29 -> 20.852736 | I30: =I26+I18+I19+I22-I28-I29 -> 1.2117393 | J30: =J26+J18+J19+J22-J28-J29 -> 2.6418742 | K30: =K26+K18+K19+K22-K28-K29 -> -4.394484

Sheet Debt Schedule
A1: Debt Schedule — tranche roll-forward, rates, PIK, refinancing test, cash sweep
A2: ="AMC Networks (AMC Global Media) · PUBLIC DATA CASE · HYPOTHETICAL INVESTMENT TERMS · Active scenario: "&Assumptions!$D$10 -> AMC Networks (AMC Global Media) · PUBLIC DATA CASE · HYPOTHETICAL INVESTMENT TERMS · Active scenario: Downside
A4: $M | C4: FY2023A | D4: FY2024A | E4: FY2025A | F4: LTM Jun-26 | G4: LTM Jun-27E | H4: LTM Jun-28E | I4: LTM Jun-29E | J4: LTM Jun-30E | K4: LTM Jun-31E
A6: Rates & market-access (refinancing) test
A7: Base rate (SOFR) | G7: =Assumptions!$G$52 -> 0.039 | H7: =Assumptions!$H$52 -> 0.0375 | I7: =Assumptions!$I$52 -> 0.035 | J7: =Assumptions!$J$52 -> 0.035 | K7: =Assumptions!$K$52 -> 0.035
A8: Floating-rate shock (selected scenario) | C8: =CHOOSE(Assumptions!$C$10,Assumptions!$C$78,Assumptions!$C$97,Assumptions!$C$116) -> 0.015
A9: Refinancing rate (selected scenario) | C9: =CHOOSE(Assumptions!$C$10,Assumptions!$C$79,Assumptions!$C$98,Assumptions!$C$117) -> 0.13
A10: Max net leverage to refinance | C10: =CHOOSE(Assumptions!$C$10,Assumptions!$C$80,Assumptions!$C$99,Assumptions!$C$118) -> 5.5
A11: Min pro-forma coverage to refinance | C11: =CHOOSE(Assumptions!$C$10,Assumptions!$C$81,Assumptions!$C$100,Assumptions!$C$119) -> 1.5
A12: Beginning total debt | G12: =G17+G30+G43 -> 1735.554 | H12: =H17+H30+H43 -> 1735.554 | I12: =I17+I30+I43 -> 1735.554 | J12: =J17+J30+J43 -> 1315.098 | K12: =K17+K30+K43 -> 1315.098
A13: Beginning cash | G13: ='Cash Flow'!F19 -> 463.996 | H13: ='Cash Flow'!G19 -> 518.82155 | I13: ='Cash Flow'!H19 -> 539.67428 | J13: ='Cash Flow'!I19 -> 120.43002 | K13: ='Cash Flow'!J19 -> 123.0719
A14: Pro-forma interest for refinancing test | G14: =G17*IF(G18=1,$C$9,IF(Assumptions!$I$56=1,MAX(G7,Assumptions!$G$56)+Assumptions!$F$56+$C$8,Assumptions!$E$56))+G30*IF(G31=1,$C$9,IF(Assumptions!$I$57=1,MAX(G7,Assumptions!$G$57)+Assumptions!$F$57+$C$8,Assumptions!$E$57))+G43*IF(G44=1,$C$9,IF(Assumptions!$I$58=1,MAX(G7,Assumptions!$G$58)+Assumptions!$F$58+$C$8,Assumptions!$E$58)) -> 155.95467 | H14: =H17*IF(OR(H18=1,Recovery!G35=1),$C$9,IF(Assumptions!$I$56=1,MAX(H7,Assumptions!$G$56)+Assumptions!$F$56+$C$8,Assumptions!$E$56))+H30*IF(OR(H31=1,Recovery!G36=1),$C$9,IF(Assumptions!$I$57=1,MAX(H7,Assumptions!$G$57)+Assumptions!$F$57+$C$8,Assumptions!$E$57))+H43*IF(OR(H44=1,Recovery!G37=1),$C$9,IF(Assumptions!$I$58=1,MAX(H7,Assumptions!$G$58)+Assumptions!$F$58+$C$8,Assumptions!$E$58)) -> 155.95467 | I14: =I17*IF(OR(I18=1,Recovery!H35=1),$C$9,IF(Assumptions!$I$56=1,MAX(I7,Assumptions!$G$56)+Assumptions!$F$56+$C$8,Assumptions!$E$56))+I30*IF(OR(I31=1,Recovery!H36=1),$C$9,IF(Assumptions!$I$57=1,MAX(I7,Assumptions!$G$57)+Assumptions!$F$57+$C$8,Assumptions!$E$57))+I43*IF(OR(I44=1,Recovery!H37=1),$C$9,IF(Assumptions!$I$58=1,MAX(I7,Assumptions!$G$58)+Assumptions!$F$58+$C$8,Assumptions!$E$58)) -> 192.74457 | J14: =J17*IF(OR(J18=1,Recovery!I35=1),$C$9,IF(Assumptions!$I$56=1,MAX(J7,Assumptions!$G$56)+Assumptions!$F$56+$C$8,Assumptions!$E$56))+J30*IF(OR(J31=1,Recovery!I36=1),$C$9,IF(Assumptions!$I$57=1,MAX(J7,Assumptions!$G$57)+Assumptions!$F$57+$C$8,Assumptions!$E$57))+J43*IF(OR(J44=1,Recovery!I37=1),$C$9,IF(Assumptions!$I$58=1,MAX(J7,Assumptions!$G$58)+Assumptions!$F$58+$C$8,Assumptions!$E$58)) -> 138.08529 | K14: =K17*IF(OR(K18=1,Recovery!J35=1),$C$9,IF(Assumptions!$I$56=1,MAX(K7,Assumptions!$G$56)+Assumptions!$F$56+$C$8,Assumptions!$E$56))+K30*IF(OR(K31=1,Recovery!J36=1),$C$9,IF(Assumptions!$I$57=1,MAX(K7,Assumptions!$G$57)+Assumptions!$F$57+$C$8,Assumptions!$E$57))+K43*IF(OR(K44=1,Recovery!J37=1),$C$9,IF(Assumptions!$I$58=1,MAX(K7,Assumptions!$G$58)+Assumptions!$F$58+$C$8,Assumptions!$E$58)) -> 138.08529
A15: Market access to refinance? (1 = yes) | G15: =IF('Operating Model'!G17<=0,0,IF(AND((G12-G13)/'Operating Model'!G17<=$C$10,'Operating Model'!G17/G14>=$C$11),1,0)) -> 1 | H15: =IF('Operating Model'!H17<=0,0,IF(AND((H12-H13)/'Operating Model'!H17<=$C$10,'Operating Model'!H17/H14>=$C$11),1,0)) -> 0 | I15: =IF('Operating Model'!I17<=0,0,IF(AND((I12-I13)/'Operating Model'!I17<=$C$10,'Operating Model'!I17/I14>=$C$11),1,0)) -> 0 | J15: =IF('Operating Model'!J17<=0,0,IF(AND((J12-J13)/'Operating Model'!J17<=$C$10,'Operating Model'!J17/J14>=$C$11),1,0)) -> 0 | K15: =IF('Operating Model'!K17<=0,0,IF(AND((K12-K13)/'Operating Model'!K17<=$C$10,'Operating Model'!K17/K14>=$C$11),1,0)) -> 0
A16: Tranche 1: 10.50% Senior Secured Notes due 2032
A17: Beginning balance | G17: =F28 -> 1315.098 | H17: =G28 -> 1315.098 | I17: =H28 -> 1315.098 | J17: =I28 -> 1315.098 | K17: =J28 -> 1315.098
A18: Maturing this period? (1 = yes) | G18: =IF('Operating Model'!G7=Assumptions!$K$56,1,0) -> 0 | H18: =IF('Operating Model'!H7=Assumptions!$K$56,1,0) -> 0 | I18: =IF('Operating Model'!I7=Assumptions!$K$56,1,0) -> 0 | J18: =IF('Operating Model'!J7=Assumptions!$K$56,1,0) -> 0 | K18: =IF('Operating Model'!K7=Assumptions!$K$56,1,0) -> 0
A20: All-in interest rate applied | G20: =IF(Assumptions!$I$56=1,MAX(G7,Assumptions!$G$56)+Assumptions!$F$56+$C$8,Assumptions!$E$56) -> 0.105 | H20: =IF(Recovery!G35=1,$C$9,IF(Assumptions!$I$56=1,MAX(H7,Assumptions!$G$56)+Assumptions!$F$56+$C$8,Assumptions!$E$56)) -> 0.105 | I20: =IF(Recovery!H35=1,$C$9,IF(Assumptions!$I$56=1,MAX(I7,Assumptions!$G$56)+Assumptions!$F$56+$C$8,Assumptions!$E$56)) -> 0.105 | J20: =IF(Recovery!I35=1,$C$9,IF(Assumptions!$I$56=1,MAX(J7,Assumptions!$G$56)+Assumptions!$F$56+$C$8,Assumptions!$E$56)) -> 0.105 | K20: =IF(Recovery!J35=1,$C$9,IF(Assumptions!$I$56=1,MAX(K7,Assumptions!$G$56)+Assumptions!$F$56+$C$8,Assumptions!$E$56)) -> 0.105
A21: Cash interest expense | G21: =G17*G20 -> 138.08529 | H21: =H17*H20 -> 138.08529 | I21: =I17*I20 -> 138.08529 | J21: =J17*J20 -> 138.08529 | K21: =K17*K20 -> 138.08529
A22: PIK interest | G22: =G17*Assumptions!$H$56 -> 0 | H22: =H17*Assumptions!$H$56 -> 0 | I22: =I17*Assumptions!$H$56 -> 0 | J22: =J17*Assumptions!$H$56 -> 0 | K22: =K17*Assumptions!$H$56 -> 0
A23: Mandatory amortization | G23: =MIN(G17,Assumptions!$L$56*Assumptions!$C$56) -> 0 | H23: =MIN(H17,Assumptions!$L$56*Assumptions!$C$56) -> 0 | I23: =MIN(I17,Assumptions!$L$56*Assumptions!$C$56) -> 0 | J23: =MIN(J17,Assumptions!$L$56*Assumptions!$C$56) -> 0 | K23: =MIN(K17,Assumptions!$L$56*Assumptions!$C$56) -> 0
A24: New borrowing (revolver draw) | G24: =IF(AND(Assumptions!$P$56=1,'Operating Model'!G7<Assumptions!$K$56),MIN(MAX(0,-'Cash Flow'!G11),MAX(0,Assumptions!$D$56-G17)),0) -> 0 | H24: =IF(AND(Assumptions!$P$56=1,OR('Operating Model'!H7<Assumptions!$K$56,Recovery!G35=1)),MIN(MAX(0,-'Cash Flow'!H11),MAX(0,Assumptions!$D$56-H17)),0) -> 0 | I24: =IF(AND(Assumptions!$P$56=1,OR('Operating Model'!I7<Assumptions!$K$56,Recovery!H35=1)),MIN(MAX(0,-'Cash Flow'!I11),MAX(0,Assumptions!$D$56-I17)),0) -> 0 | J24: =IF(AND(Assumptions!$P$56=1,OR('Operating Model'!J7<Assumptions!$K$56,Recovery!I35=1)),MIN(MAX(0,-'Cash Flow'!J11),MAX(0,Assumptions!$D$56-J17)),0) -> 0 | K24: =IF(AND(Assumptions!$P$56=1,OR('Operating Model'!K7<Assumptions!$K$56,Recovery!J35=1)),MIN(MAX(0,-'Cash Flow'!K11),MAX(0,Assumptions!$D$56-K17)),0) -> 0
A25: Repayment at maturity (from available cash) | G25: =G18*MIN(G17-G23+G22,MAX(0,'Cash Flow'!G13-Assumptions!$C$12*G15)) -> 0 | H25: =H18*MIN(H17-H23+H22,MAX(0,'Cash Flow'!H13-Assumptions!$C$12*H15)) -> 0 | I25: =I18*MIN(I17-I23+I22,MAX(0,'Cash Flow'!I13-Assumptions!$C$12*I15)) -> 0 | J25: =J18*MIN(J17-J23+J22,MAX(0,'Cash Flow'!J13-Assumptions!$C$12*J15)) -> 0 | K25: =K18*MIN(K17-K23+K22,MAX(0,'Cash Flow'!K13-Assumptions!$C$12*K15)) -> 0
A26: Optional repayment (cash sweep) | G26: =Assumptions!$N$56*MIN(G17+G24+G22-G23-G25,MAX(0,'Cash Flow'!G17)) -> 0 | H26: =Assumptions!$N$56*MIN(H17+H24+H22-H23-H25,MAX(0,'Cash Flow'!H17)) -> 0 | I26: =Assumptions!$N$56*MIN(I17+I24+I22-I23-I25,MAX(0,'Cash Flow'!I17)) -> 0 | J26: =Assumptions!$N$56*MIN(J17+J24+J22-J23-J25,MAX(0,'Cash Flow'!J17)) -> 0 | K26: =Assumptions!$N$56*MIN(K17+K24+K22-K23-K25,MAX(0,'Cash Flow'!K17)) -> 0
A27: Unpaid at maturity (no refinancing, insufficient cash) | G27: =G18*(1-G15)*(G17-G23+G22-G25) -> 0 | H27: =H18*(1-H15)*(H17-H23+H22-H25) -> 0 | I27: =I18*(1-I15)*(I17-I23+I22-I25) -> 0 | J27: =J18*(1-J15)*(J17-J23+J22-J25) -> 0 | K27: =K18*(1-K15)*(K17-K23+K22-K25) -> 0
A28: Ending balance | F28: =Assumptions!$C$56 -> 1315.098 | G28: =G17+G24+G22-G23-G25-G26 -> 1315.098 | H28: =H17+H24+H22-H23-H25-H26 -> 1315.098 | I28: =I17+I24+I22-I23-I25-I26 -> 1315.098 | J28: =J17+J24+J22-J23-J25-J26 -> 1315.098 | K28: =K17+K24+K22-K23-K25-K26 -> 1315.098
A29: Tranche 2: 4.25% Senior Notes due 2029
A30: Beginning balance | G30: =F41 -> 276.706 | H30: =G41 -> 276.706 | I30: =H41 -> 276.706 | J30: =I41 -> 0 | K30: =J41 -> 0
A31: Maturing this period? (1 = yes) | G31: =IF('Operating Model'!G7=Assumptions!$K$57,1,0) -> 0 | H31: =IF('Operating Model'!H7=Assumptions!$K$57,1,0) -> 0 | I31: =IF('Operating Model'!I7=Assumptions!$K$57,1,0) -> 1 | J31: =IF('Operating Model'!J7=Assumptions!$K$57,1,0) -> 0 | K31: =IF('Operating Model'!K7=Assumptions!$K$57,1,0) -> 0
A33: All-in interest rate applied | G33: =IF(Assumptions!$I$57=1,MAX(G7,Assumptions!$G$57)+Assumptions!$F$57+$C$8,Assumptions!$E$57) -> 0.0425 | H33: =IF(Recovery!G36=1,$C$9,IF(Assumptions!$I$57=1,MAX(H7,Assumptions!$G$57)+Assumptions!$F$57+$C$8,Assumptions!$E$57)) -> 0.0425 | I33: =IF(Recovery!H36=1,$C$9,IF(Assumptions!$I$57=1,MAX(I7,Assumptions!$G$57)+Assumptions!$F$57+$C$8,Assumptions!$E$57)) -> 0.0425 | J33: =IF(Recovery!I36=1,$C$9,IF(Assumptions!$I$57=1,MAX(J7,Assumptions!$G$57)+Assumptions!$F$57+$C$8,Assumptions!$E$57)) -> 0.0425 | K33: =IF(Recovery!J36=1,$C$9,IF(Assumptions!$I$57=1,MAX(K7,Assumptions!$G$57)+Assumptions!$F$57+$C$8,Assumptions!$E$57)) -> 0.0425
A34: Cash interest expense | G34: =G30*G33 -> 11.760005 | H34: =H30*H33 -> 11.760005 | I34: =I30*I33 -> 11.760005 | J34: =J30*J33 -> 0 | K34: =K30*K33 -> 0
A35: PIK interest | G35: =G30*Assumptions!$H$57 -> 0 | H35: =H30*Assumptions!$H$57 -> 0 | I35: =I30*Assumptions!$H$57 -> 0 | J35: =J30*Assumptions!$H$57 -> 0 | K35: =K30*Assumptions!$H$57 -> 0
A36: Mandatory amortization | G36: =MIN(G30,Assumptions!$L$57*Assumptions!$C$57) -> 0 | H36: =MIN(H30,Assumptions!$L$57*Assumptions!$C$57) -> 0 | I36: =MIN(I30,Assumptions!$L$57*Assumptions!$C$57) -> 0 | J36: =MIN(J30,Assumptions!$L$57*Assumptions!$C$57) -> 0 | K36: =MIN(K30,Assumptions!$L$57*Assumptions!$C$57) -> 0
A37: New borrowing (revolver draw) | G37: =IF(AND(Assumptions!$P$57=1,'Operating Model'!G7<Assumptions!$K$57),MIN(MAX(0,-'Cash Flow'!G11),MAX(0,Assumptions!$D$57-G30)),0) -> 0 | H37: =IF(AND(Assumptions!$P$57=1,OR('Operating Model'!H7<Assumptions!$K$57,Recovery!G36=1)),MIN(MAX(0,-'Cash Flow'!H11),MAX(0,Assumptions!$D$57-H30)),0) -> 0 | I37: =IF(AND(Assumptions!$P$57=1,OR('Operating Model'!I7<Assumptions!$K$57,Recovery!H36=1)),MIN(MAX(0,-'Cash Flow'!I11),MAX(0,Assumptions!$D$57-I30)),0) -> 0 | J37: =IF(AND(Assumptions!$P$57=1,OR('Operating Model'!J7<Assumptions!$K$57,Recovery!I36=1)),MIN(MAX(0,-'Cash Flow'!J11),MAX(0,Assumptions!$D$57-J30)),0) -> 0 | K37: =IF(AND(Assumptions!$P$57=1,OR('Operating Model'!K7<Assumptions!$K$57,Recovery!J36=1)),MIN(MAX(0,-'Cash Flow'!K11),MAX(0,Assumptions!$D$57-K30)),0) -> 0
A38: Repayment at maturity (from available cash) | G38: =G31*MIN(G30-G36+G35,MAX(0,'Cash Flow'!G13-Assumptions!$C$12*G15-G25)) -> 0 | H38: =H31*MIN(H30-H36+H35,MAX(0,'Cash Flow'!H13-Assumptions!$C$12*H15-H25)) -> 0 | I38: =I31*MIN(I30-I36+I35,MAX(0,'Cash Flow'!I13-Assumptions!$C$12*I15-I25)) -> 276.706 | J38: =J31*MIN(J30-J36+J35,MAX(0,'Cash Flow'!J13-Assumptions!$C$12*J15-J25)) -> 0 | K38: =K31*MIN(K30-K36+K35,MAX(0,'Cash Flow'!K13-Assumptions!$C$12*K15-K25)) -> 0
A39: Optional repayment (cash sweep) | G39: =Assumptions!$N$57*MIN(G30+G37+G35-G36-G38,MAX(0,'Cash Flow'!G17-G26)) -> 0 | H39: =Assumptions!$N$57*MIN(H30+H37+H35-H36-H38,MAX(0,'Cash Flow'!H17-H26)) -> 0 | I39: =Assumptions!$N$57*MIN(I30+I37+I35-I36-I38,MAX(0,'Cash Flow'!I17-I26)) -> 0 | J39: =Assumptions!$N$57*MIN(J30+J37+J35-J36-J38,MAX(0,'Cash Flow'!J17-J26)) -> 0 | K39: =Assumptions!$N$57*MIN(K30+K37+K35-K36-K38,MAX(0,'Cash Flow'!K17-K26)) -> 0
A40: Unpaid at maturity (no refinancing, insufficient cash) | G40: =G31*(1-G15)*(G30-G36+G35-G38) -> 0 | H40: =H31*(1-H15)*(H30-H36+H35-H38) -> 0 | I40: =I31*(1-I15)*(I30-I36+I35-I38) -> 0 | J40: =J31*(1-J15)*(J30-J36+J35-J38) -> 0 | K40: =K31*(1-K15)*(K30-K36+K35-K38) -> 0
A41: Ending balance | F41: =Assumptions!$C$57 -> 276.706 | G41: =G30+G37+G35-G36-G38-G39 -> 276.706 | H41: =H30+H37+H35-H36-H38-H39 -> 276.706 | I41: =I30+I37+I35-I36-I38-I39 -> 0 | J41: =J30+J37+J35-J36-J38-J39 -> 0 | K41: =K30+K37+K35-K36-K38-K39 -> 0
A42: Tranche 3: 4.25% Convertible Senior Notes due 2029
A43: Beginning balance | G43: =F54 -> 143.75 | H43: =G54 -> 143.75 | I43: =H54 -> 143.75 | J43: =I54 -> 0 | K43: =J54 -> 0
A44: Maturing this period? (1 = yes) | G44: =IF('Operating Model'!G7=Assumptions!$K$58,1,0) -> 0 | H44: =IF('Operating Model'!H7=Assumptions!$K$58,1,0) -> 0 | I44: =IF('Operating Model'!I7=Assumptions!$K$58,1,0) -> 1 | J44: =IF('Operating Model'!J7=Assumptions!$K$58,1,0) -> 0 | K44: =IF('Operating Model'!K7=Assumptions!$K$58,1,0) -> 0
...

Sheet Cash Flow
A1: Cash Flow & Liquidity — cash waterfall and default test
A2: ="AMC Networks (AMC Global Media) · PUBLIC DATA CASE · HYPOTHETICAL INVESTMENT TERMS · Active scenario: "&Assumptions!$D$10 -> AMC Networks (AMC Global Media) · PUBLIC DATA CASE · HYPOTHETICAL INVESTMENT TERMS · Active scenario: Downside
A4: $M | C4: FY2023A | D4: FY2024A | E4: FY2025A | F4: LTM Jun-26 | G4: LTM Jun-27E | H4: LTM Jun-28E | I4: LTM Jun-29E | J4: LTM Jun-30E | K4: LTM Jun-31E
A6: Cash flow & liquidity waterfall ($M)
A7: Beginning cash | G7: =F19 -> 463.996 | H7: =G19 -> 518.82155 | I7: =H19 -> 539.67428 | J7: =I19 -> 120.43002 | K7: =J19 -> 123.0719
A8: Free cash flow (from Operating Model) | G8: ='Operating Model'!G30 -> 54.825547 | H8: ='Operating Model'!H30 -> 20.852736 | I8: ='Operating Model'!I30 -> 1.2117393 | J8: ='Operating Model'!J30 -> 2.6418742 | K8: ='Operating Model'!K30 -> -4.394484
A9: Plus: net asset-sale proceeds | G9: =CHOOSE(Assumptions!$C$10,Assumptions!$G$74,Assumptions!$G$93,Assumptions!$G$112) -> 0 | H9: =CHOOSE(Assumptions!$C$10,Assumptions!$H$74,Assumptions!$H$93,Assumptions!$H$112) -> 0 | I9: =CHOOSE(Assumptions!$C$10,Assumptions!$I$74,Assumptions!$I$93,Assumptions!$I$112) -> 0 | J9: =CHOOSE(Assumptions!$C$10,Assumptions!$J$74,Assumptions!$J$93,Assumptions!$J$112) -> 0 | K9: =CHOOSE(Assumptions!$C$10,Assumptions!$K$74,Assumptions!$K$93,Assumptions!$K$112) -> 0
A10: Less: mandatory amortization | G10: ='Debt Schedule'!G23+'Debt Schedule'!G36+'Debt Schedule'!G49 -> 0 | H10: ='Debt Schedule'!H23+'Debt Schedule'!H36+'Debt Schedule'!H49 -> 0 | I10: ='Debt Schedule'!I23+'Debt Schedule'!I36+'Debt Schedule'!I49 -> 0 | J10: ='Debt Schedule'!J23+'Debt Schedule'!J36+'Debt Schedule'!J49 -> 0 | K10: ='Debt Schedule'!K23+'Debt Schedule'!K36+'Debt Schedule'!K49 -> 0
A11: Cash after mandatory debt service | G11: =G7+G8+G9-G10 -> 518.82155 | H11: =H7+H8+H9-H10 -> 539.67428 | I11: =I7+I8+I9-I10 -> 540.88602 | J11: =J7+J8+J9-J10 -> 123.0719 | K11: =K7+K8+K9-K10 -> 118.67741
A12: Plus: revolver draw | G12: ='Debt Schedule'!G24+'Debt Schedule'!G37+'Debt Schedule'!G50 -> 0 | H12: ='Debt Schedule'!H24+'Debt Schedule'!H37+'Debt Schedule'!H50 -> 0 | I12: ='Debt Schedule'!I24+'Debt Schedule'!I37+'Debt Schedule'!I50 -> 0 | J12: ='Debt Schedule'!J24+'Debt Schedule'!J37+'Debt Schedule'!J50 -> 0 | K12: ='Debt Schedule'!K24+'Debt Schedule'!K37+'Debt Schedule'!K50 -> 0
A13: Cash available for maturities | G13: =G11+G12 -> 518.82155 | H13: =H11+H12 -> 539.67428 | I13: =I11+I12 -> 540.88602 | J13: =J11+J12 -> 123.0719 | K13: =K11+K12 -> 118.67741
A14: Less: repayment of maturing debt | G14: ='Debt Schedule'!G25+'Debt Schedule'!G38+'Debt Schedule'!G51 -> 0 | H14: ='Debt Schedule'!H25+'Debt Schedule'!H38+'Debt Schedule'!H51 -> 0 | I14: ='Debt Schedule'!I25+'Debt Schedule'!I38+'Debt Schedule'!I51 -> 420.456 | J14: ='Debt Schedule'!J25+'Debt Schedule'!J38+'Debt Schedule'!J51 -> 0 | K14: ='Debt Schedule'!K25+'Debt Schedule'!K38+'Debt Schedule'!K51 -> 0
A15: Cash before sweep | G15: =G13-G14 -> 518.82155 | H15: =H13-H14 -> 539.67428 | I15: =I13-I14 -> 120.43002 | J15: =J13-J14 -> 123.0719 | K15: =K13-K14 -> 118.67741
A16: Funding gap (shortfall after cash & revolver) | G16: =MAX(0,-G15) -> 0 | H16: =MAX(0,-H15) -> 0 | I16: =MAX(0,-I15) -> 0 | J16: =MAX(0,-J15) -> 0 | K16: =MAX(0,-K15) -> 0
A17: Excess cash available for sweep | G17: =MAX(0,G15-Assumptions!$C$12)*Assumptions!$C$13 -> 0 | H17: =MAX(0,H15-Assumptions!$C$12)*Assumptions!$C$13 -> 0 | I17: =MAX(0,I15-Assumptions!$C$12)*Assumptions!$C$13 -> 0 | J17: =MAX(0,J15-Assumptions!$C$12)*Assumptions!$C$13 -> 0 | K17: =MAX(0,K15-Assumptions!$C$12)*Assumptions!$C$13 -> 0
A18: Less: optional repayment (cash sweep) | G18: ='Debt Schedule'!G26+'Debt Schedule'!G39+'Debt Schedule'!G52 -> 0 | H18: ='Debt Schedule'!H26+'Debt Schedule'!H39+'Debt Schedule'!H52 -> 0 | I18: ='Debt Schedule'!I26+'Debt Schedule'!I39+'Debt Schedule'!I52 -> 0 | J18: ='Debt Schedule'!J26+'Debt Schedule'!J39+'Debt Schedule'!J52 -> 0 | K18: ='Debt Schedule'!K26+'Debt Schedule'!K39+'Debt Schedule'!K52 -> 0
A19: Ending cash | F19: =Assumptions!$C$11 -> 463.996 | G19: =G15-G18 -> 518.82155 | H19: =H15-H18 -> 539.67428 | I19: =I15-I18 -> 120.43002 | J19: =J15-J18 -> 123.0719 | K19: =K15-K18 -> 118.67741
A20: Unpaid maturities (balance left outstanding) | G20: ='Debt Schedule'!G27+'Debt Schedule'!G40+'Debt Schedule'!G53 -> 0 | H20: ='Debt Schedule'!H27+'Debt Schedule'!H40+'Debt Schedule'!H53 -> 0 | I20: ='Debt Schedule'!I27+'Debt Schedule'!I40+'Debt Schedule'!I53 -> 0 | J20: ='Debt Schedule'!J27+'Debt Schedule'!J40+'Debt Schedule'!J53 -> 0 | K20: ='Debt Schedule'!K27+'Debt Schedule'!K40+'Debt Schedule'!K53 -> 0
A21: Payment default? (1 = yes) | G21: =IF(OR(G16>0.001,G20>0.001),1,0) -> 0 | H21: =IF(OR(H16>0.001,H20>0.001),1,0) -> 0 | I21: =IF(OR(I16>0.001,I20>0.001),1,0) -> 0 | J21: =IF(OR(J16>0.001,J20>0.001),1,0) -> 0 | K21: =IF(OR(K16>0.001,K20>0.001),1,0) -> 0
A22: First default period flag | G22: =IF(G21=1,1,0) -> 0 | H22: =IF(AND(H21=1,SUM($G$21:G21)=0),1,0) -> 0 | I22: =IF(AND(I21=1,SUM($G$21:H21)=0),1,0) -> 0 | J22: =IF(AND(J21=1,SUM($G$21:I21)=0),1,0) -> 0 | K22: =IF(AND(K21=1,SUM($G$21:J21)=0),1,0) -> 0
A23: Check: Δ debt = draws + PIK − repayments | G23: =('Debt Schedule'!G56-'Debt Schedule'!F56)-(G12+'Operating Model'!G22-G10-G14-G18) -> 0 | H23: =('Debt Schedule'!H56-'Debt Schedule'!G56)-(H12+'Operating Model'!H22-H10-H14-H18) -> 0 | I23: =('Debt Schedule'!I56-'Debt Schedule'!H56)-(I12+'Operating Model'!I22-I10-I14-I18) -> 0 | J23: =('Debt Schedule'!J56-'Debt Schedule'!I56)-(J12+'Operating Model'!J22-J10-J14-J18) -> 0 | K23: =('Debt Schedule'!K56-'Debt Schedule'!J56)-(K12+'Operating Model'!K22-K10-K14-K18) -> 0

Sheet Credit Metrics
A1: Credit Metrics, Covenants & Credit Score
A2: ="AMC Networks (AMC Global Media) · PUBLIC DATA CASE · HYPOTHETICAL INVESTMENT TERMS · Active scenario: "&Assumptions!$D$10 -> AMC Networks (AMC Global Media) · PUBLIC DATA CASE · HYPOTHETICAL INVESTMENT TERMS · Active scenario: Downside
A4: $M | C4: FY2023A | D4: FY2024A | E4: FY2025A | F4: LTM Jun-26 | G4: LTM Jun-27E | H4: LTM Jun-28E | I4: LTM Jun-29E | J4: LTM Jun-30E | K4: LTM Jun-31E
A6: Credit metrics (selected scenario)
A7: Total debt (face value) | F7: ='Debt Schedule'!F56 -> 1735.554 | G7: ='Debt Schedule'!G56 -> 1735.554 | H7: ='Debt Schedule'!H56 -> 1735.554 | I7: ='Debt Schedule'!I56 -> 1315.098 | J7: ='Debt Schedule'!J56 -> 1315.098 | K7: ='Debt Schedule'!K56 -> 1315.098
A8: Secured debt | F8: =Assumptions!$O$56*'Debt Schedule'!F28+Assumptions!$O$57*'Debt Schedule'!F41+Assumptions!$O$58*'Debt Schedule'!F54 -> 1315.098 | G8: =Assumptions!$O$56*'Debt Schedule'!G28+Assumptions!$O$57*'Debt Schedule'!G41+Assumptions!$O$58*'Debt Schedule'!G54 -> 1315.098 | H8: =Assumptions!$O$56*'Debt Schedule'!H28+Assumptions!$O$57*'Debt Schedule'!H41+Assumptions!$O$58*'Debt Schedule'!H54 -> 1315.098 | I8: =Assumptions!$O$56*'Debt Schedule'!I28+Assumptions!$O$57*'Debt Schedule'!I41+Assumptions!$O$58*'Debt Schedule'!I54 -> 1315.098 | J8: =Assumptions!$O$56*'Debt Schedule'!J28+Assumptions!$O$57*'Debt Schedule'!J41+Assumptions!$O$58*'Debt Schedule'!J54 -> 1315.098 | K8: =Assumptions!$O$56*'Debt Schedule'!K28+Assumptions!$O$57*'Debt Schedule'!K41+Assumptions!$O$58*'Debt Schedule'!K54 -> 1315.098
A9: Net debt | F9: =F7-'Cash Flow'!F19 -> 1271.558 | G9: =G7-'Cash Flow'!G19 -> 1216.7325 | H9: =H7-'Cash Flow'!H19 -> 1195.8797 | I9: =I7-'Cash Flow'!I19 -> 1194.668 | J9: =J7-'Cash Flow'!J19 -> 1192.0261 | K9: =K7-'Cash Flow'!K19 -> 1196.4206
A10: Gross debt / EBITDA | F10: =IF('Operating Model'!F17>0,F7/'Operating Model'!F17,0) -> 5.5441039 | G10: =IF('Operating Model'!G17>0,G7/'Operating Model'!G17,0) -> 6.9988584 | H10: =IF('Operating Model'!H17>0,H7/'Operating Model'!H17,0) -> 8.2098046 | I10: =IF('Operating Model'!I17>0,I7/'Operating Model'!I17,0) -> 6.933114 | J10: =IF('Operating Model'!J17>0,J7/'Operating Model'!J17,0) -> 7.6629154 | K10: =IF('Operating Model'!K17>0,K7/'Operating Model'!K17,0) -> 8.0662268
A11: Net debt / EBITDA | F11: =IF('Operating Model'!F17>0,F9/'Operating Model'!F17,0) -> 4.0619016 | G11: =IF('Operating Model'!G17>0,G9/'Operating Model'!G17,0) -> 4.9066397 | H11: =IF('Operating Model'!H17>0,H9/'Operating Model'!H17,0) -> 5.656948 | I11: =IF('Operating Model'!I17>0,I9/'Operating Model'!I17,0) -> 6.2982145 | J11: =IF('Operating Model'!J17>0,J9/'Operating Model'!J17,0) -> 6.9457905 | K11: =IF('Operating Model'!K17>0,K9/'Operating Model'!K17,0) -> 7.3383123
A12: Interest coverage (EBITDA / cash interest) | F12: =IF('Operating Model'!F23>0,'Operating Model'!F17/'Operating Model'!F23,0) -> 1.8359011 | G12: =IF('Operating Model'!G21>0,'Operating Model'!G17/'Operating Model'!G21,0) -> 1.5900564 | H12: =IF('Operating Model'!H21>0,'Operating Model'!H17/'Operating Model'!H21,0) -> 1.3555231 | I12: =IF('Operating Model'!I21>0,'Operating Model'!I17/'Operating Model'!I21,0) -> 1.2162739 | J12: =IF('Operating Model'!J21>0,'Operating Model'!J17/'Operating Model'!J21,0) -> 1.2428441 | K12: =IF('Operating Model'!K21>0,'Operating Model'!K17/'Operating Model'!K21,0) -> 1.1807019
A13: EBIT / interest | F13: =IF('Operating Model'!F23>0,'Operating Model'!F20/'Operating Model'!F23,0) -> 1.1928299 | G13: =IF('Operating Model'!G21>0,'Operating Model'!G20/'Operating Model'!G21,0) -> 0.94320283 | H13: =IF('Operating Model'!H21>0,'Operating Model'!H20/'Operating Model'!H21,0) -> 0.75394926 | I13: =IF('Operating Model'!I21>0,'Operating Model'!I20/'Operating Model'!I21,0) -> 0.6507945 | J13: =IF('Operating Model'!J21>0,'Operating Model'!J20/'Operating Model'!J21,0) -> 0.63611985 | K13: =IF('Operating Model'!K21>0,'Operating Model'!K20/'Operating Model'!K21,0) -> 0.60431386
A14: FCF / debt | F14: =IF(F7>0,'Operating Model'!F30/F7,0) -> 0.10977647 | G14: =IF(G7>0,'Operating Model'!G30/G7,0) -> 0.031589652 | H14: =IF(H7>0,'Operating Model'!H30/H7,0) -> 0.012015031 | I14: =IF(I7>0,'Operating Model'!I30/I7,0) -> 0.00092140609 | J14: =IF(J7>0,'Operating Model'!J30/J7,0) -> 0.0020088801 | K14: =IF(K7>0,'Operating Model'!K30/K7,0) -> -0.0033415639
A15: Debt service coverage ((EBITDA − capex − tax) / (cash interest + amortization)) | G15: =IF('Operating Model'!G21+'Cash Flow'!G10>0,('Operating Model'!G17-'Operating Model'!G28-'Operating Model'!G25)/('Operating Model'!G21+'Cash Flow'!G10),0) -> 1.4178003 | H15: =IF('Operating Model'!H21+'Cash Flow'!H10>0,('Operating Model'!H17-'Operating Model'!H28-'Operating Model'!H25)/('Operating Model'!H21+'Cash Flow'!H10),0) -> 1.1953249 | I15: =IF('Operating Model'!I21+'Cash Flow'!I10>0,('Operating Model'!I17-'Operating Model'!I28-'Operating Model'!I25)/('Operating Model'!I21+'Cash Flow'!I10),0) -> 1.0656876 | J15: =IF('Operating Model'!J21+'Cash Flow'!J10>0,('Operating Model'!J17-'Operating Model'!J28-'Operating Model'!J25)/('Operating Model'!J21+'Cash Flow'!J10),0) -> 1.0812744 | K15: =IF('Operating Model'!K21+'Cash Flow'!K10>0,('Operating Model'!K17-'Operating Model'!K28-'Operating Model'!K25)/('Operating Model'!K21+'Cash Flow'!K10),0) -> 1.0272107
A16: Liquidity (cash + undrawn revolver) | F16: =MAX(0,'Cash Flow'!F19)+Assumptions!$P$56*MAX(0,Assumptions!$D$56-'Debt Schedule'!F28)+Assumptions!$P$57*MAX(0,Assumptions!$D$57-'Debt Schedule'!F41)+Assumptions!$P$58*MAX(0,Assumptions!$D$58-'Debt Schedule'!F54) -> 463.996 | G16: =MAX(0,'Cash Flow'!G19)+Assumptions!$P$56*MAX(0,Assumptions!$D$56-'Debt Schedule'!G28)+Assumptions!$P$57*MAX(0,Assumptions!$D$57-'Debt Schedule'!G41)+Assumptions!$P$58*MAX(0,Assumptions!$D$58-'Debt Schedule'!G54) -> 518.82155 | H16: =MAX(0,'Cash Flow'!H19)+Assumptions!$P$56*MAX(0,Assumptions!$D$56-'Debt Schedule'!H28)+Assumptions!$P$57*MAX(0,Assumptions!$D$57-'Debt Schedule'!H41)+Assumptions!$P$58*MAX(0,Assumptions!$D$58-'Debt Schedule'!H54) -> 539.67428 | I16: =MAX(0,'Cash Flow'!I19)+Assumptions!$P$56*MAX(0,Assumptions!$D$56-'Debt Schedule'!I28)+Assumptions!$P$57*MAX(0,Assumptions!$D$57-'Debt Schedule'!I41)+Assumptions!$P$58*MAX(0,Assumptions!$D$58-'Debt Schedule'!I54) -> 120.43002 | J16: =MAX(0,'Cash Flow'!J19)+Assumptions!$P$56*MAX(0,Assumptions!$D$56-'Debt Schedule'!J28)+Assumptions!$P$57*MAX(0,Assumptions!$D$57-'Debt Schedule'!J41)+Assumptions!$P$58*MAX(0,Assumptions!$D$58-'Debt Schedule'!J54) -> 123.0719 | K16: =MAX(0,'Cash Flow'!K19)+Assumptions!$P$56*MAX(0,Assumptions!$D$56-'Debt Schedule'!K28)+Assumptions!$P$57*MAX(0,Assumptions!$D$57-'Debt Schedule'!K41)+Assumptions!$P$58*MAX(0,Assumptions!$D$58-'Debt Schedule'!K54) -> 118.67741
A17: Debt / capital (debt + implied equity) | G17: =IF(G7>0,G7/(G7+MAX(0,'Operating Model'!G17*CHOOSE(Assumptions!$C$10,Assumptions!$C$82,Assumptions!$C$101,Assumptions!$C$120)-G9)),0) -> 0.98683624 | H17: =IF(H7>0,H7/(H7+MAX(0,'Operating Model'!H17*CHOOSE(Assumptions!$C$10,Assumptions!$C$82,Assumptions!$C$101,Assumptions!$C$120)-H9)),0) -> 1 | I17: =IF(I7>0,I7/(I7+MAX(0,'Operating Model'!I17*CHOOSE(Assumptions!$C$10,Assumptions!$C$82,Assumptions!$C$101,Assumptions!$C$120)-I9)),0) -> 1 | J17: =IF(J7>0,J7/(J7+MAX(0,'Operating Model'!J17*CHOOSE(Assumptions!$C$10,Assumptions!$C$82,Assumptions!$C$101,Assumptions!$C$120)-J9)),0) -> 1 | K17: =IF(K7>0,K7/(K7+MAX(0,'Operating Model'!K17*CHOOSE(Assumptions!$C$10,Assumptions!$C$82,Assumptions!$C$101,Assumptions!$C$120)-K9)),0) -> 1
A18: Cash / debt | F18: =IF(F7>0,MAX(0,'Cash Flow'!F19)/F7,0) -> 0.26734749 | G18: =IF(G7>0,MAX(0,'Cash Flow'!G19)/G7,0) -> 0.29893714 | H18: =IF(H7>0,MAX(0,'Cash Flow'!H19)/H7,0) -> 0.31095217 | I18: =IF(I7>0,MAX(0,'Cash Flow'!I19)/I7,0) -> 0.091574942 | J18: =IF(J7>0,MAX(0,'Cash Flow'!J19)/J7,0) -> 0.093583822 | K18: =IF(K7>0,MAX(0,'Cash Flow'!K19)/K7,0) -> 0.090242258
A19: Asset value after scenario decline | G19: =Assumptions!$C$30*(1-CHOOSE(Assumptions!$C$10,Assumptions!$C$85,Assumptions!$C$104,Assumptions!$C$123)) -> 2086.7254 | H19: =Assumptions!$C$30*(1-CHOOSE(Assumptions!$C$10,Assumptions!$C$85,Assumptions!$C$104,Assumptions!$C$123)) -> 2086.7254 | I19: =Assumptions!$C$30*(1-CHOOSE(Assumptions!$C$10,Assumptions!$C$85,Assumptions!$C$104,Assumptions!$C$123)) -> 2086.7254 | J19: =Assumptions!$C$30*(1-CHOOSE(Assumptions!$C$10,Assumptions!$C$85,Assumptions!$C$104,Assumptions!$C$123)) -> 2086.7254 | K19: =Assumptions!$C$30*(1-CHOOSE(Assumptions!$C$10,Assumptions!$C$85,Assumptions!$C$104,Assumptions!$C$123)) -> 2086.7254
A20: Covenant compliance (active covenants; tests use model-basis metrics)
A21: Hypothetical maintenance covenant: max net leverage (AOI basis) [HYPOTHETICAL]
A22: Metric | G22: =IF('Operating Model'!G17>0,G9/'Operating Model'!G17,99) -> 4.9066397 | H22: =IF('Operating Model'!H17>0,H9/'Operating Model'!H17,99) -> 5.656948 | I22: =IF('Operating Model'!I17>0,I9/'Operating Model'!I17,99) -> 6.2982145 | J22: =IF('Operating Model'!J17>0,J9/'Operating Model'!J17,99) -> 6.9457905 | K22: =IF('Operating Model'!K17>0,K9/'Operating Model'!K17,99) -> 7.3383123
A23: Covenant threshold | G23: =Assumptions!$G$65 -> 5.25 | H23: =Assumptions!$H$65 -> 5.25 | I23: =Assumptions!$I$65 -> 5 | J23: =Assumptions!$J$65 -> 5 | K23: =Assumptions!$K$65 -> 5
A24: Headroom | G24: =G23-G22 -> 0.34336029 | H24: =H23-H22 -> -0.40694804 | I24: =I23-I22 -> -1.2982145 | J24: =J23-J22 -> -1.9457905 | K24: =K23-K22 -> -2.3383123
A25: Headroom % of threshold | G25: =IF(G23=0,0,G24/ABS(G23)) -> 0.06540196 | H25: =IF(H23=0,0,H24/ABS(H23)) -> -0.077513912 | I25: =IF(I23=0,0,I24/ABS(I23)) -> -0.25964289 | J25: =IF(J23=0,0,J24/ABS(J23)) -> -0.38915811 | K25: =IF(K23=0,0,K24/ABS(K23)) -> -0.46766245
A26: BREACH? (1 = yes) | G26: =IF(G24<0,1,0) -> 0 | H26: =IF(H24<0,1,0) -> 1 | I26: =IF(I24<0,1,0) -> 1 | J26: =IF(J24<0,1,0) -> 1 | K26: =IF(K24<0,1,0) -> 1
A27: First breach period (0 = none) | C27: =IFERROR(INDEX('Operating Model'!$G$7:$K$7,MATCH(1,$G$26:$K$26,0)),0) -> 2028
A28: Minimum headroom % | C28: =MIN($G$25:$K$25) -> -0.46766245
A29: Hypothetical maintenance covenant: min interest coverage (AOI / interest) [HYPOTHETICAL]
A30: Metric | G30: =IF('Operating Model'!G21>0,'Operating Model'!G17/'Operating Model'!G21,99) -> 1.5900564 | H30: =IF('Operating Model'!H21>0,'Operating Model'!H17/'Operating Model'!H21,99) -> 1.3555231 | I30: =IF('Operating Model'!I21>0,'Operating Model'!I17/'Operating Model'!I21,99) -> 1.2162739 | J30: =IF('Operating Model'!J21>0,'Operating Model'!J17/'Operating Model'!J21,99) -> 1.2428441 | K30: =IF('Operating Model'!K21>0,'Operating Model'!K17/'Operating Model'!K21,99) -> 1.1807019
A31: Covenant threshold | G31: =Assumptions!$G$66 -> 1.4 | H31: =Assumptions!$H$66 -> 1.4 | I31: =Assumptions!$I$66 -> 1.4 | J31: =Assumptions!$J$66 -> 1.5 | K31: =Assumptions!$K$66 -> 1.5
A32: Headroom | G32: =G30-G31 -> 0.19005643 | H32: =H30-H31 -> -0.04447689 | I32: =I30-I31 -> -0.18372608 | J32: =J30-J31 -> -0.25715586 | K32: =K30-K31 -> -0.31929807
A33: Headroom % of threshold | G33: =IF(G31=0,0,G32/ABS(G31)) -> 0.1357546 | H33: =IF(H31=0,0,H32/ABS(H31)) -> -0.031769207 | I33: =IF(I31=0,0,I32/ABS(I31)) -> -0.13123292 | J33: =IF(J31=0,0,J32/ABS(J31)) -> -0.17143724 | K33: =IF(K31=0,0,K32/ABS(K31)) -> -0.21286538
A34: BREACH? (1 = yes) | G34: =IF(G32<0,1,0) -> 0 | H34: =IF(H32<0,1,0) -> 1 | I34: =IF(I32<0,1,0) -> 1 | J34: =IF(J32<0,1,0) -> 1 | K34: =IF(K32<0,1,0) -> 1
A35: First breach period (0 = none) | C35: =IFERROR(INDEX('Operating Model'!$G$7:$K$7,MATCH(1,$G$34:$K$34,0)),0) -> 2028
A36: Minimum headroom % | C36: =MIN($G$33:$K$33) -> -0.21286538
A37: Hypothetical maintenance covenant: min liquidity ($M) [HYPOTHETICAL]
A38: Metric | G38: =G16 -> 518.82155 | H38: =H16 -> 539.67428 | I38: =I16 -> 120.43002 | J38: =J16 -> 123.0719 | K38: =K16 -> 118.67741
A39: Covenant threshold | G39: =Assumptions!$G$67 -> 200 | H39: =Assumptions!$H$67 -> 200 | I39: =Assumptions!$I$67 -> 200 | J39: =Assumptions!$J$67 -> 200 | K39: =Assumptions!$K$67 -> 200
A40: Headroom | G40: =G38-G39 -> 318.82155 | H40: =H38-H39 -> 339.67428 | I40: =I38-I39 -> -79.569977 | J40: =J38-J39 -> -76.928103 | K40: =K38-K39 -> -81.322587
A41: Headroom % of threshold | G41: =IF(G39=0,0,G40/ABS(G39)) -> 1.5941077 | H41: =IF(H39=0,0,H40/ABS(H39)) -> 1.6983714 | I41: =IF(I39=0,0,I40/ABS(I39)) -> -0.39784989 | J41: =IF(J39=0,0,J40/ABS(J39)) -> -0.38464052 | K41: =IF(K39=0,0,K40/ABS(K39)) -> -0.40661294
A42: BREACH? (1 = yes) | G42: =IF(G40<0,1,0) -> 0 | H42: =IF(H40<0,1,0) -> 0 | I42: =IF(I40<0,1,0) -> 1 | J42: =IF(J40<0,1,0) -> 1 | K42: =IF(K40<0,1,0) -> 1
...

Sheet Scenarios
A1: Scenarios — side-by-side (all three run simultaneously on Calc Engine)
A2: ="Active scenario for the detailed tabs: "&Assumptions!$D$10 -> Active scenario for the detailed tabs: Downside
A4: Assumptions (links to Assumptions tab) | C4: Base Case | D4: Downside | E4: Severe Downside | F4: Selected
A5: Average revenue growth (5 periods) | C5: =AVERAGE(Assumptions!$G$71:$K$71) -> -0.036 | D5: =AVERAGE(Assumptions!$G$90:$K$90) -> -0.062 | E5: =AVERAGE(Assumptions!$G$109:$K$109) -> -0.1 | F5: =CHOOSE(Assumptions!$C$10,C5,D5,E5) -> -0.062
A6: Average EBITDA margin (5 periods) | C6: =AVERAGE(Assumptions!$G$73:$K$73) -> 0.1376 | D6: =AVERAGE(Assumptions!$G$92:$K$92) -> 0.107 | E6: =AVERAGE(Assumptions!$G$111:$K$111) -> 0.075 | F6: =CHOOSE(Assumptions!$C$10,C6,D6,E6) -> 0.107
A7: Floating-rate shock | C7: =Assumptions!$C$78 -> 0 | D7: =Assumptions!$C$97 -> 0.015 | E7: =Assumptions!$C$116 -> 0.03 | F7: =CHOOSE(Assumptions!$C$10,C7,D7,E7) -> 0.015
A8: Refinancing rate | C8: =Assumptions!$C$79 -> 0.11 | D8: =Assumptions!$C$98 -> 0.13 | E8: =Assumptions!$C$117 -> 0.15 | F8: =CHOOSE(Assumptions!$C$10,C8,D8,E8) -> 0.13
A9: Market access: max net leverage / min coverage | C9: =TEXT(Assumptions!$C$80,"0.0")&"x / "&TEXT(Assumptions!$C$81,"0.00")&"x" -> 6.0x / 1.25x | D9: =TEXT(Assumptions!$C$99,"0.0")&"x / "&TEXT(Assumptions!$C$100,"0.00")&"x" -> 5.5x / 1.50x | E9: =TEXT(Assumptions!$C$118,"0.0")&"x / "&TEXT(Assumptions!$C$119,"0.00")&"x" -> 5.0x / 1.75x | F9: =CHOOSE(Assumptions!$C$10,C9,D9,E9) -> 5.5x / 1.50x
A10: Exit multiple / distressed multiple | C10: =TEXT(Assumptions!$C$82,"0.0")&"x / "&TEXT(Assumptions!$C$84,"0.0")&"x" -> 5.5x / 5.0x | D10: =TEXT(Assumptions!$C$101,"0.0")&"x / "&TEXT(Assumptions!$C$103,"0.0")&"x" -> 5.0x / 4.5x | E10: =TEXT(Assumptions!$C$120,"0.0")&"x / "&TEXT(Assumptions!$C$122,"0.0")&"x" -> 4.0x / 4.0x | F10: =CHOOSE(Assumptions!$C$10,C10,D10,E10) -> 5.0x / 4.5x
A11: Asset value decline | C11: =Assumptions!$C$85 -> 0 | D11: =Assumptions!$C$104 -> 0.15 | E11: =Assumptions!$C$123 -> 0.35 | F11: =CHOOSE(Assumptions!$C$10,C11,D11,E11) -> 0.15
A12: Scenario probability | C12: =Assumptions!$C$87 -> 0.45 | D12: =Assumptions!$C$106 -> 0.35 | E12: =Assumptions!$C$125 -> 0.2 | F12: =CHOOSE(Assumptions!$C$10,C12,D12,E12) -> 0.35
A14: Outputs (from Calc Engine) | C14: Base Case | D14: Downside | E14: Severe Downside | F14: Selected
A15: LTM Jun-31E revenue ($M) | C15: ='Calc Engine'!K19 -> 1869.7659 | D15: ='Calc Engine'!K343 -> 1630.3757 | E15: ='Calc Engine'!K667 -> 1323.0649 | F15: =CHOOSE(Assumptions!$C$10,C15,D15,E15) -> 1630.3757
A16: Trough EBITDA ($M) | C16: =MIN('Calc Engine'!$G$23:$K$23) -> 250.54863 | D16: =MIN('Calc Engine'!$G$347:$K$347) -> 163.03757 | E16: =MIN('Calc Engine'!$G$671:$K$671) -> 92.614546 | F16: =CHOOSE(Assumptions!$C$10,C16,D16,E16) -> 163.03757
A17: Cumulative FCF, 5 periods ($M) | C17: ='Calc Engine'!C325 -> 555.58835 | D17: ='Calc Engine'!C649 -> 75.137413 | E17: ='Calc Engine'!C973 -> -362.4062 | F17: =CHOOSE(Assumptions!$C$10,C17,D17,E17) -> 75.137413
A18: Peak net debt / EBITDA | C18: ='Calc Engine'!C323 -> 3.8149962 | D18: ='Calc Engine'!C647 -> 7.3383123 | E18: ='Calc Engine'!C971 -> 17.64263 | F18: =CHOOSE(Assumptions!$C$10,C18,D18,E18) -> 7.3383123
A19: Minimum EBITDA / cash interest | C19: ='Calc Engine'!C324 -> 1.7584275 | D19: ='Calc Engine'!C648 -> 1.1807019 | E19: ='Calc Engine'!C972 -> 0.64109145 | F19: =CHOOSE(Assumptions!$C$10,C19,D19,E19) -> 1.1807019
A20: Covenant breaches (count of tests failed) | C20: ='Calc Engine'!C164 -> 0 | D20: ='Calc Engine'!C488 -> 11 | E20: ='Calc Engine'!C812 -> 13 | F20: =CHOOSE(Assumptions!$C$10,C20,D20,E20) -> 11
A21: Refinancing failures (maturing tranches) | C21: ='Calc Engine'!C103 -> 0 | D21: ='Calc Engine'!C427 -> 2 | E21: ='Calc Engine'!C751 -> 2 | F21: =CHOOSE(Assumptions!$C$10,C21,D21,E21) -> 2
A22: Payment default modelled? (1 = yes) | C22: ='Calc Engine'!C169 -> 0 | D22: ='Calc Engine'!C493 -> 0 | E22: ='Calc Engine'!C817 -> 1 | F22: =CHOOSE(Assumptions!$C$10,C22,D22,E22) -> 0
A23: Valuation period (default or trough) | C23: ='Calc Engine'!C170 -> 2031 | D23: ='Calc Engine'!C494 -> 2031 | E23: ='Calc Engine'!C818 -> 2029 | F23: =CHOOSE(Assumptions!$C$10,C23,D23,E23) -> 2031
A24: Recovery value used ($M) | C24: ='Calc Engine'!C176 -> 1851.8715 | D24: ='Calc Engine'!C500 -> 852.34647 | E24: ='Calc Engine'!C824 -> 478.71934 | F24: =CHOOSE(Assumptions!$C$10,C24,D24,E24) -> 852.34647
A25: Target-tranche recovery % (valuation waterfall) | C25: ='Calc Engine'!C247 -> 1 | D25: ='Calc Engine'!C571 -> 0.60628401 | E25: ='Calc Engine'!C895 -> 0.34051867 | F25: =CHOOSE(Assumptions!$C$10,C25,D25,E25) -> 0.60628401
A26: Exit price used (% of face) | C26: ='Calc Engine'!C308 -> 100 | D26: ='Calc Engine'!C632 -> 81.27516 | E26: ='Calc Engine'!C956 -> 32.573573 | F26: =CHOOSE(Assumptions!$C$10,C26,D26,E26) -> 81.27516
A27: IRR | C27: ='Calc Engine'!C322 -> 0.12603362 | D27: ='Calc Engine'!C646 -> 0.065384881 | E27: ='Calc Engine'!C970 -> -0.10811295 | F27: =CHOOSE(Assumptions!$C$10,C27,D27,E27) -> 0.065384881
A28: MOIC | C28: ='Calc Engine'!C321 -> 1.3842105 | D28: ='Calc Engine'!C645 -> 1.187107 | E28: ='Calc Engine'!C969 -> 0.69942872 | F28: =CHOOSE(Assumptions!$C$10,C28,D28,E28) -> 1.187107
A29: Absolute profit ($M) | C29: ='Calc Engine'!C320 -> 36.5 | D29: ='Calc Engine'!C644 -> 17.77516 | E29: ='Calc Engine'!C968 -> -28.554272 | F29: =CHOOSE(Assumptions!$C$10,C29,D29,E29) -> 17.77516
A31: Probability-weighted IRR (IRR of expected cash flows) | C31: =IF(SUM(D38:I38)<=0,-1,IFERROR(IRR(C38:I38,MAX(-0.9,(SUM(D38:I38)/-C38)^(1/(COLUMNS(C38:I38)-1))-1)),IRR(C38:I38,0.1))) -> 0.06109225
A32: Memo: probability-weighted AVERAGE of scenario IRRs (IRR is non-linear, so this is not an IRR) | C32: =SUMPRODUCT(C12:E12,C27:E27) -> 0.057977249
