Workbook

Sheet Cover
A1: CreditIQ — Brightwater Retail Holdings credit underwriting model
A2: DEMO DATA · DEMO INVESTMENT TERMS · $ in millions · as of 2026-03-31
A4: Model status | B4: ='Investment Summary'!$D$52 -> ALL CHECKS PASS
A5: Active scenario | B5: =Assumptions!$D$10 -> Downside
A6: Recommendation (rule-based; see Investment Summary) | B6: ='Investment Summary'!$C$4 -> HOLD
A8: Colour conventions
A9: Blue on pale yellow | B9: Hardcoded input: sourced historical data, explicit assumption, scenario / transaction / macro input, covenant threshold, sensitivity axis, structural block parameter.
A10: Black | B10: Formula or calculation. No outputs, subtotals or metrics are hardcoded anywhere in this workbook.
A11: Green | B11: Direct link to a cell on another worksheet.
A12: Grey fill | B12: Labels and headers.
A14: Flow of logic | B14: Assumptions + Historical → Operating Model → Debt Schedule ↔ Cash Flow → Credit Metrics & Covenants → Recovery → Returns → Sensitivities → Investment Summary
A15: Data classes | B15: PUBLIC FILING = reported inputs · ANALYST PROJECTION = scenario drivers · UNDERWRITING ASSUMPTION = hypothetical purchase price / terms · DEMO = fictional
A17: Tabs
A18: Assumptions | B18: All inputs, scenario drivers, covenants, selector
A19: Historical Financials | B19: Sourced statements; derived lines and LTM calculated
A20: Operating Model | B20: Income statement and FCF, history + projection
A21: Debt Schedule | B21: Per-tranche roll-forward, floors, PIK, refinancing test, sweep
A22: Cash Flow | B22: Cash waterfall, funding gap, default test
A23: Credit Metrics | B23: Ratios, covenant compliance, transparent credit score
A24: Scenarios | B24: Base / Downside / Severe side by side + reconciliation
A25: Capital Structure | B25: Tranches, leverage through the stack, maturity wall & refinancing requirement
A26: Recovery | B26: Seniority waterfall with collateral pools and deficiency claims
A27: Returns | B27: Face, price, coupon, yield, recovery; IRR, XIRR, MOIC
A28: Sensitivities | B28: Seven formula-driven tables
A29: Investment Summary | B29: Live outputs, recommendation evidence, integrity checks
... A31: Calc Engine | B31: Supporting: 63 simultaneous model runs
A33: Validation: docs/MODEL_VALIDATION.md · Audit: scripts/audit_model.py · Change-impact harness: scripts/model_harness.py

Sheet Assumptions
A1: Assumptions — Brightwater Retail Holdings: all explicit inputs live on this tab
A2: DEMO DATA · DEMO INVESTMENT TERMS · Blue on pale yellow = hardcoded input · Black = formula · Green = link to another sheet · $ in millions
A4: 1. General & model settings
A5: Company | C5: Brightwater Retail Holdings
A6: Base period label (year in which the base / LTM period ends) | C6: 2025
A7: Fiscal-period end month (12 = calendar FY; 6 = LTM June periods) | C7: 12
A8: As-of / entry date | C8: 46112
A9: Cash tax rate on positive EBT | B9: % of EBT | C9: 0.25
A10: ACTIVE SCENARIO selector (1=Base, 2=Downside, 3=Severe) | B10: select 1 / 2 / 3 | C10: 2 | D10: =CHOOSE(C10,"Base Case","Downside","Severe Downside") -> Downside
A11: Cash & equivalents at base date (balance sheet) | B11: $M | C11: 45
A12: Minimum operating cash | B12: $M | C12: 0
A13: Cash sweep (% of excess cash applied to prepayable debt) | B13: % | C13: 1
A14: Recovery value override (leave blank = model-derived) | B14: $M, optional
A15: Administrative / DIP costs | B15: % of recovery value | C15: 0.04
A16: Accrued unpaid interest included in claims | B16: months | C16: 3
A17: Rank at which secured deficiency claims join general creditors | C17: 99
A18: Maturity alert window | B18: periods from base | C18: 2
A19: Materiality threshold for maturity alert | B19: % of total debt | C19: 0.25
A20: Concentration threshold (single-period maturities) | B20: % of total debt | C20: 0.3
A21: Market-implied EV / EBITDA (analyst assumption) | B21: x | C21: 6.5
A22: Credit score: maturity-risk window | B22: periods | C22: 3
A24: 2. Collateral / asset base (recovery & LTV)
A25: Illustrative appraised / collateral value (DEMO)
A26: Appraised / collateral asset base | C26: 1040
A27: Total asset base | C27: =SUM(C26) -> 1040
A29: 3. Transaction / position being underwritten — DEMO INVESTMENT TERMS
A30: Target tranche # (row in the debt table below) | C30: 2
A31: Face value held (legal claim) | B31: $M | C31: 100
A32: Purchase price / OID (UNDERWRITING ASSUMPTION) | B32: % of face | C32: 78
A33: Transaction fees | B33: % of cost | C33: 0.005
A34: Hold period (whole years, 1-5) | B34: periods | C34: 2
A35: Coupon payments per year on target tranche (contractual-timing cross-check only) | B35: per year | C35: 1
A36: Default → recovery cash receipt lag | B36: periods | C36: 1
A37: Required IRR (hurdle) | C37: 0.12
A38: Minimum acceptable downside IRR | C38: 0
A39: Minimum yield to maturity | C39: 0.09
A40: Maximum net leverage (net debt / EBITDA) | C40: 6
A41: Minimum downside recovery | C41: 0.6
A42: Minimum covenant headroom (base case) | C42: 0.15
A43: Decision rule: secondary test failures tolerated for PROCEED | B43: count | C43: 2
...

Sheet Historical Financials
A1: Historical Financials — Brightwater Retail Holdings
A2: DEMO data (fictional, illustrative). All subtotals, EBITDA, EBIT, net income, FCF and LTM columns are formulas.
A4: US$ millions | B4: FY2022A | C4: FY2023A | D4: FY2024A | E4: FY2025A | F4: Source datapoint IDs (see Sources tab)
A5: A. Reported inputs
A6: Revenue | B6: 2650 | C6: 2560 | D6: 2470 | E6: 2400 | F6: DEMO input
A7: COGS | B7: 1643 | C7: 1605.12 | D7: 1568.45 | E7: 1536 | F7: DEMO input
A8: Operating expenses (cash, ex-D&A) | B8: 781.75 | C8: 755.2 | D8: 728.65 | E8: 708 | F8: DEMO input
A9: Depreciation & amortization | B9: 58.3 | C9: 56.32 | D9: 54.34 | E9: 52.8 | F9: DEMO input
A10: Interest expense | B10: 101.184 | C10: 107.136 | D10: 113.088 | E10: 119.04 | F10: DEMO input
A11: Taxes | B11: 16.4415 | C11: 9.056 | D11: 1.368 | E11: 0 | F11: DEMO input
A12: Capex | B12: 53 | C12: 51.2 | D12: 49.4 | E12: 48 | F12: DEMO input
A13: Increase in working capital | B13: -3.2121212 | C13: -10.8 | D13: -10.8 | E13: -8.4 | F13: DEMO input
A14: Share-based compensation add-back (none applied for this company) | B14: 0 | C14: 0 | D14: 0 | E14: 0 | F14: DEMO input
A16: B. Standardized statements (calculated)
A17: Revenue | B17: =B6 -> 2650 | C17: =C6 -> 2560 | D17: =D6 -> 2470 | E17: =E6 -> 2400
A18: Direct costs / COGS | B18: =B7 -> 1643 | C18: =C7 -> 1605.12 | D18: =D7 -> 1568.45 | E18: =E7 -> 1536
A19: Gross profit (NOI for real estate) | B19: =B17-B18 -> 1007 | C19: =C17-C18 -> 954.88 | D19: =D17-D18 -> 901.55 | E19: =E17-E18 -> 864
A20: Operating expenses, cash & adjusted (excl. D&A and non-cash add-backs) | B20: =B8 -> 781.75 | C20: =C8 -> 755.2 | D20: =D8 -> 728.65 | E20: =E8 -> 708
A21: EBITDA (company-adjusted basis) | B21: =B19-B20 -> 225.25 | C21: =C19-C20 -> 199.68 | D21: =D19-D20 -> 172.9 | E21: =E19-E20 -> 156
A22: Depreciation & amortization | B22: =B9 -> 58.3 | C22: =C9 -> 56.32 | D22: =D9 -> 54.34 | E22: =E9 -> 52.8
A23: Share-based compensation (non-cash add-back) | B23: =B14 -> 0 | C23: =C14 -> 0 | D23: =D14 -> 0 | E23: =E14 -> 0
A24: EBIT (EBITDA − D&A − SBC) | B24: =B21-B22-B23 -> 166.95 | C24: =C21-C22-C23 -> 143.36 | D24: =D21-D22-D23 -> 118.56 | E24: =E21-E22-E23 -> 103.2
A25: Interest expense | B25: =B10 -> 101.184 | C25: =C10 -> 107.136 | D25: =D10 -> 113.088 | E25: =E10 -> 119.04
A26: EBT | B26: =B24-B25 -> 65.766 | C26: =C24-C25 -> 36.224 | D26: =D24-D25 -> 5.472 | E26: =E24-E25 -> -15.84
A27: Income taxes | B27: =B11 -> 16.4415 | C27: =C11 -> 9.056 | D27: =D11 -> 1.368 | E27: =E11 -> 0
A28: Net income (model basis; excludes impairments and one-offs) | B28: =B26-B27 -> 49.3245 | C28: =C26-C27 -> 27.168 | D28: =D26-D27 -> 4.104 | E28: =E26-E27 -> -15.84
A29: Capex (incl. leasing costs where applicable) | B29: =B12 -> 53 | C29: =C12 -> 51.2 | D29: =D12 -> 49.4 | E29: =E12 -> 48
A30: Increase in working capital | B30: =B13 -> -3.2121212 | C30: =C13 -> -10.8 | D30: =D13 -> -10.8 | E30: =E13 -> -8.4
A31: Free cash flow (NI + D&A + SBC − capex − ΔNWC) | B31: =B28+B22+B23-B29-B30 -> 57.836621 | C31: =C28+C22+C23-C29-C30 -> 43.088 | D31: =D28+D22+D23-D29-D30 -> 19.844 | E31: =E28+E22+E23-E29-E30 -> -2.64
A33: C. Ratios & checks (calculated)
A34: Gross margin | B34: =B19/B17 -> 0.38 | C34: =C19/C17 -> 0.373 | D34: =D19/D17 -> 0.365 | E34: =E19/E17 -> 0.36
A35: EBITDA margin | B35: =B21/B17 -> 0.085 | C35: =C21/C17 -> 0.078 | D35: =D21/D17 -> 0.07 | E35: =E21/E17 -> 0.065
A36: Revenue growth (YoY) | C36: =C17/B17-1 -> -0.033962264 | D36: =D17/C17-1 -> -0.03515625 | E36: =E17/D17-1 -> -0.028340081
A37: EBITDA growth (YoY) | C37: =C21/B21-1 -> -0.11351831 | D37: =D21/C21-1 -> -0.13411458 | E37: =E21/D21-1 -> -0.097744361

Sheet Operating Model
A1: Operating Model — selected scenario (assumptions → statements)
A2: ="Brightwater Retail Holdings · DEMO DATA · DEMO INVESTMENT TERMS · Active scenario: "&Assumptions!$D$10 -> Brightwater Retail Holdings · DEMO DATA · DEMO INVESTMENT TERMS · Active scenario: Downside
A4: $M | C4: FY2022A | D4: FY2023A | E4: FY2024A | F4: FY2025A | G4: FY2026E | H4: FY2027E | I4: FY2028E | J4: FY2029E | K4: FY2030E
A6: Operating drivers (selected scenario → Assumptions)
A7: Model period (year in which the period ends) | C7: =D7-1 -> 2022 | D7: =E7-1 -> 2023 | E7: =F7-1 -> 2024 | F7: =Assumptions!$C$6 -> 2025 | G7: =F7+1 -> 2026 | H7: =G7+1 -> 2027 | I7: =H7+1 -> 2028 | J7: =I7+1 -> 2029 | K7: =J7+1 -> 2030
A8: Projection period # | G8: =G7-Assumptions!$C$6 -> 1 | H8: =H7-Assumptions!$C$6 -> 2 | I8: =I7-Assumptions!$C$6 -> 3 | J8: =J7-Assumptions!$C$6 -> 4 | K8: =K7-Assumptions!$C$6 -> 5
A9: Revenue growth | G9: =CHOOSE(Assumptions!$C$10,Assumptions!$G$65,Assumptions!$G$84,Assumptions!$G$103) -> -0.078 | H9: =CHOOSE(Assumptions!$C$10,Assumptions!$H$65,Assumptions!$H$84,Assumptions!$H$103) -> -0.039 | I9: =CHOOSE(Assumptions!$C$10,Assumptions!$I$65,Assumptions!$I$84,Assumptions!$I$103) -> -0.005 | J9: =CHOOSE(Assumptions!$C$10,Assumptions!$J$65,Assumptions!$J$84,Assumptions!$J$103) -> -0.01 | K9: =CHOOSE(Assumptions!$C$10,Assumptions!$K$65,Assumptions!$K$84,Assumptions!$K$103) -> -0.01
A10: Gross margin | G10: =CHOOSE(Assumptions!$C$10,Assumptions!$G$66,Assumptions!$G$85,Assumptions!$G$104) -> 0.33 | H10: =CHOOSE(Assumptions!$C$10,Assumptions!$H$66,Assumptions!$H$85,Assumptions!$H$104) -> 0.318 | I10: =CHOOSE(Assumptions!$C$10,Assumptions!$I$66,Assumptions!$I$85,Assumptions!$I$104) -> 0.324 | J10: =CHOOSE(Assumptions!$C$10,Assumptions!$J$66,Assumptions!$J$85,Assumptions!$J$104) -> 0.33 | K10: =CHOOSE(Assumptions!$C$10,Assumptions!$K$66,Assumptions!$K$85,Assumptions!$K$104) -> 0.336
A11: EBITDA margin | G11: =CHOOSE(Assumptions!$C$10,Assumptions!$G$67,Assumptions!$G$86,Assumptions!$G$105) -> 0.035 | H11: =CHOOSE(Assumptions!$C$10,Assumptions!$H$67,Assumptions!$H$86,Assumptions!$H$105) -> 0.023 | I11: =CHOOSE(Assumptions!$C$10,Assumptions!$I$67,Assumptions!$I$86,Assumptions!$I$105) -> 0.029 | J11: =CHOOSE(Assumptions!$C$10,Assumptions!$J$67,Assumptions!$J$86,Assumptions!$J$105) -> 0.035 | K11: =CHOOSE(Assumptions!$C$10,Assumptions!$K$67,Assumptions!$K$86,Assumptions!$K$105) -> 0.041
A12: Income statement ($M)
A13: Revenue | C13: ='Historical Financials'!B17 -> 2650 | D13: ='Historical Financials'!C17 -> 2560 | E13: ='Historical Financials'!D17 -> 2470 | F13: ='Historical Financials'!E17 -> 2400 | G13: =F13*(1+G9) -> 2212.8 | H13: =G13*(1+H9) -> 2126.5008 | I13: =H13*(1+I9) -> 2115.8683 | J13: =I13*(1+J9) -> 2094.7096 | K13: =J13*(1+K9) -> 2073.7625
A14: Direct costs / COGS | C14: ='Historical Financials'!B18 -> 1643 | D14: ='Historical Financials'!C18 -> 1605.12 | E14: ='Historical Financials'!D18 -> 1568.45 | F14: ='Historical Financials'!E18 -> 1536 | G14: =G13*(1-G10) -> 1482.576 | H14: =H13*(1-H10) -> 1450.2735 | I14: =I13*(1-I10) -> 1430.327 | J14: =J13*(1-J10) -> 1403.4554 | K14: =K13*(1-K10) -> 1376.9783
A15: Gross profit (NOI for real estate) | C15: =C13-C14 -> 1007 | D15: =D13-D14 -> 954.88 | E15: =E13-E14 -> 901.55 | F15: =F13-F14 -> 864 | G15: =G13-G14 -> 730.224 | H15: =H13-H14 -> 676.22725 | I15: =I13-I14 -> 685.54133 | J15: =J13-J14 -> 691.25417 | K15: =K13-K14 -> 696.78421
A16: Operating expenses (implied: gross profit − EBITDA) | C16: ='Historical Financials'!B20 -> 781.75 | D16: ='Historical Financials'!C20 -> 755.2 | E16: ='Historical Financials'!D20 -> 728.65 | F16: ='Historical Financials'!E20 -> 708 | G16: =G15-G17 -> 652.776 | H16: =H15-H17 -> 627.31774 | I16: =I15-I17 -> 624.18115 | J16: =J15-J17 -> 617.93934 | K16: =K15-K17 -> 611.75994
A17: EBITDA | C17: =C15-C16 -> 225.25 | D17: =D15-D16 -> 199.68 | E17: =E15-E16 -> 172.9 | F17: =F15-F16 -> 156 | G17: =G13*G11 -> 77.448 | H17: =H13*H11 -> 48.909518 | I17: =I13*I11 -> 61.360181 | J17: =J13*J11 -> 73.314836 | K17: =K13*K11 -> 85.024263
A18: D&A | C18: ='Historical Financials'!B22 -> 58.3 | D18: ='Historical Financials'!C22 -> 56.32 | E18: ='Historical Financials'!D22 -> 54.34 | F18: ='Historical Financials'!E22 -> 52.8 | G18: =G13*'Historical Financials'!E22/'Historical Financials'!E17 -> 48.6816 | H18: =H13*'Historical Financials'!E22/'Historical Financials'!E17 -> 46.783018 | I18: =I13*'Historical Financials'!E22/'Historical Financials'!E17 -> 46.549103 | J18: =J13*'Historical Financials'!E22/'Historical Financials'!E17 -> 46.083611 | K18: =K13*'Historical Financials'!E22/'Historical Financials'!E17 -> 45.622775
A19: Share-based compensation (non-cash) | C19: ='Historical Financials'!B23 -> 0 | D19: ='Historical Financials'!C23 -> 0 | E19: ='Historical Financials'!D23 -> 0 | F19: ='Historical Financials'!E23 -> 0 | G19: =G13*'Historical Financials'!E23/'Historical Financials'!E17 -> 0 | H19: =H13*'Historical Financials'!E23/'Historical Financials'!E17 -> 0 | I19: =I13*'Historical Financials'!E23/'Historical Financials'!E17 -> 0 | J19: =J13*'Historical Financials'!E23/'Historical Financials'!E17 -> 0 | K19: =K13*'Historical Financials'!E23/'Historical Financials'!E17 -> 0
A20: EBIT | C20: =C17-C18-C19 -> 166.95 | D20: =D17-D18-D19 -> 143.36 | E20: =E17-E18-E19 -> 118.56 | F20: =F17-F18-F19 -> 103.2 | G20: =G17-G18-G19 -> 28.7664 | H20: =H17-H18-H19 -> 2.1265008 | I20: =I17-I18-I19 -> 14.811078 | J20: =J17-J18-J19 -> 27.231225 | K20: =K17-K18-K19 -> 39.401488
A21: Cash interest expense (Debt Schedule) | G21: ='Debt Schedule'!G21+'Debt Schedule'!G34+'Debt Schedule'!G47+'Debt Schedule'!G60 -> 129.54 | H21: ='Debt Schedule'!H21+'Debt Schedule'!H34+'Debt Schedule'!H47+'Debt Schedule'!H60 -> 130.76463 | I21: ='Debt Schedule'!I21+'Debt Schedule'!I34+'Debt Schedule'!I47+'Debt Schedule'!I60 -> 128.34929 | J21: ='Debt Schedule'!J21+'Debt Schedule'!J34+'Debt Schedule'!J47+'Debt Schedule'!J60 -> 127.76169 | K21: ='Debt Schedule'!K21+'Debt Schedule'!K34+'Debt Schedule'!K47+'Debt Schedule'!K60 -> 127.17409
A22: PIK interest (non-cash) | G22: ='Debt Schedule'!G22+'Debt Schedule'!G35+'Debt Schedule'!G48+'Debt Schedule'!G61 -> 0 | H22: ='Debt Schedule'!H22+'Debt Schedule'!H35+'Debt Schedule'!H48+'Debt Schedule'!H61 -> 0 | I22: ='Debt Schedule'!I22+'Debt Schedule'!I35+'Debt Schedule'!I48+'Debt Schedule'!I61 -> 0 | J22: ='Debt Schedule'!J22+'Debt Schedule'!J35+'Debt Schedule'!J48+'Debt Schedule'!J61 -> 0 | K22: ='Debt Schedule'!K22+'Debt Schedule'!K35+'Debt Schedule'!K48+'Debt Schedule'!K61 -> 0
A23: Interest expense | C23: ='Historical Financials'!B25 -> 101.184 | D23: ='Historical Financials'!C25 -> 107.136 | E23: ='Historical Financials'!D25 -> 113.088 | F23: ='Historical Financials'!E25 -> 119.04 | G23: =G21+G22 -> 129.54 | H23: =H21+H22 -> 130.76463 | I23: =I21+I22 -> 128.34929 | J23: =J21+J22 -> 127.76169 | K23: =K21+K22 -> 127.17409
A24: EBT | C24: =C20-C23 -> 65.766 | D24: =D20-D23 -> 36.224 | E24: =E20-E23 -> 5.472 | F24: =F20-F23 -> -15.84 | G24: =G20-G23 -> -100.7736 | H24: =H20-H23 -> -128.63813 | I24: =I20-I23 -> -113.53821 | J24: =J20-J23 -> -100.53047 | K24: =K20-K23 -> -87.772605
A25: Taxes | C25: ='Historical Financials'!B27 -> 16.4415 | D25: ='Historical Financials'!C27 -> 9.056 | E25: ='Historical Financials'!D27 -> 1.368 | F25: ='Historical Financials'!E27 -> 0 | G25: =MAX(0,G24)*Assumptions!$C$9 -> 0 | H25: =MAX(0,H24)*Assumptions!$C$9 -> 0 | I25: =MAX(0,I24)*Assumptions!$C$9 -> 0 | J25: =MAX(0,J24)*Assumptions!$C$9 -> 0 | K25: =MAX(0,K24)*Assumptions!$C$9 -> 0
A26: Net income (model basis) | C26: =C24-C25 -> 49.3245 | D26: =D24-D25 -> 27.168 | E26: =E24-E25 -> 4.104 | F26: =F24-F25 -> -15.84 | G26: =G24-G25 -> -100.7736 | H26: =H24-H25 -> -128.63813 | I26: =I24-I25 -> -113.53821 | J26: =J24-J25 -> -100.53047 | K26: =K24-K25 -> -87.772605
A27: Free cash flow build ($M)
A28: Capex | C28: ='Historical Financials'!B29 -> 53 | D28: ='Historical Financials'!C29 -> 51.2 | E28: ='Historical Financials'!D29 -> 49.4 | F28: ='Historical Financials'!E29 -> 48 | G28: =G13*CHOOSE(Assumptions!$C$10,Assumptions!$C$69,Assumptions!$C$88,Assumptions!$C$107) -> 42.0432 | H28: =H13*CHOOSE(Assumptions!$C$10,Assumptions!$C$69,Assumptions!$C$88,Assumptions!$C$107) -> 40.403515 | I28: =I13*CHOOSE(Assumptions!$C$10,Assumptions!$C$69,Assumptions!$C$88,Assumptions!$C$107) -> 40.201498 | J28: =J13*CHOOSE(Assumptions!$C$10,Assumptions!$C$69,Assumptions!$C$88,Assumptions!$C$107) -> 39.799483 | K28: =K13*CHOOSE(Assumptions!$C$10,Assumptions!$C$69,Assumptions!$C$88,Assumptions!$C$107) -> 39.401488
A29: Working capital & other cash items (+ = outflow) | C29: ='Historical Financials'!B30 -> -3.2121212 | D29: ='Historical Financials'!C30 -> -10.8 | E29: ='Historical Financials'!D30 -> -10.8 | F29: ='Historical Financials'!E30 -> -8.4 | G29: =CHOOSE(Assumptions!$C$10,Assumptions!$C$70,Assumptions!$C$89,Assumptions!$C$108)*(G13-F13)+CHOOSE(Assumptions!$C$10,Assumptions!$C$71,Assumptions!$C$90,Assumptions!$C$109)*G13 -> -18.0384 | H29: =CHOOSE(Assumptions!$C$10,Assumptions!$C$70,Assumptions!$C$89,Assumptions!$C$108)*(H13-G13)+CHOOSE(Assumptions!$C$10,Assumptions!$C$71,Assumptions!$C$90,Assumptions!$C$109)*H13 -> -6.1029024 | I29: =CHOOSE(Assumptions!$C$10,Assumptions!$C$70,Assumptions!$C$89,Assumptions!$C$108)*(I13-H13)+CHOOSE(Assumptions!$C$10,Assumptions!$C$71,Assumptions!$C$90,Assumptions!$C$109)*I13 -> 2.9558361 | J29: =CHOOSE(Assumptions!$C$10,Assumptions!$C$70,Assumptions!$C$89,Assumptions!$C$108)*(J13-I13)+CHOOSE(Assumptions!$C$10,Assumptions!$C$71,Assumptions!$C$90,Assumptions!$C$109)*J13 -> 1.6503773 | K29: =CHOOSE(Assumptions!$C$10,Assumptions!$C$70,Assumptions!$C$89,Assumptions!$C$108)*(K13-J13)+CHOOSE(Assumptions!$C$10,Assumptions!$C$71,Assumptions!$C$90,Assumptions!$C$109)*K13 -> 1.6338735
A30: Free cash flow (NI + D&A + SBC + PIK − capex − ΔNWC/other) | C30: ='Historical Financials'!B31 -> 57.836621 | D30: ='Historical Financials'!C31 -> 43.088 | E30: ='Historical Financials'!D31 -> 19.844 | F30: ='Historical Financials'!E31 -> -2.64 | G30: =G26+G18+G19+G22-G28-G29 -> -76.0968 | H30: =H26+H18+H19+H22-H28-H29 -> -116.15573 | I30: =I26+I18+I19+I22-I28-I29 -> -110.14645 | J30: =J26+J18+J19+J22-J28-J29 -> -95.896716 | K30: =K26+K18+K19+K22-K28-K29 -> -83.185191

Sheet Debt Schedule
A1: Debt Schedule — tranche roll-forward, rates, PIK, refinancing test, cash sweep
A2: ="Brightwater Retail Holdings · DEMO DATA · DEMO INVESTMENT TERMS · Active scenario: "&Assumptions!$D$10 -> Brightwater Retail Holdings · DEMO DATA · DEMO INVESTMENT TERMS · Active scenario: Downside
A4: $M | C4: FY2022A | D4: FY2023A | E4: FY2024A | F4: FY2025A | G4: FY2026E | H4: FY2027E | I4: FY2028E | J4: FY2029E | K4: FY2030E
A6: Rates & market-access (refinancing) test
A7: Base rate (SOFR) | G7: =Assumptions!$G$49 -> 0.0425 | H7: =Assumptions!$H$49 -> 0.04 | I7: =Assumptions!$I$49 -> 0.0375 | J7: =Assumptions!$J$49 -> 0.0375 | K7: =Assumptions!$K$49 -> 0.0375
A8: Floating-rate shock (selected scenario) | C8: =CHOOSE(Assumptions!$C$10,Assumptions!$C$72,Assumptions!$C$91,Assumptions!$C$110) -> 0.015
A9: Refinancing rate (selected scenario) | C9: =CHOOSE(Assumptions!$C$10,Assumptions!$C$73,Assumptions!$C$92,Assumptions!$C$111) -> 0.135
A10: Max net leverage to refinance | C10: =CHOOSE(Assumptions!$C$10,Assumptions!$C$74,Assumptions!$C$93,Assumptions!$C$112) -> 5.5
A11: Min pro-forma coverage to refinance | C11: =CHOOSE(Assumptions!$C$10,Assumptions!$C$75,Assumptions!$C$94,Assumptions!$C$113) -> 1.8
A12: Beginning total debt | G12: =G17+G30+G43+G56 -> 1250 | H12: =H17+H30+H43+H56 -> 1281.0968 | I12: =I17+I30+I43+I56 -> 1275.8968 | J12: =J17+J30+J43+J56 -> 1270.6968 | K12: =K17+K30+K43+K56 -> 1265.4968
A13: Beginning cash | G13: ='Cash Flow'!F19 -> 45 | H13: ='Cash Flow'!G19 -> 0 | I13: ='Cash Flow'!H19 -> -121.35573 | J13: ='Cash Flow'!I19 -> -236.70218 | K13: ='Cash Flow'!J19 -> -337.79889
A14: Pro-forma interest for refinancing test | G14: =G17*IF(G18=1,$C$9,IF(Assumptions!$I$53=1,MAX(G7,Assumptions!$G$53)+Assumptions!$F$53+$C$8,Assumptions!$E$53))+G30*IF(G31=1,$C$9,IF(Assumptions!$I$54=1,MAX(G7,Assumptions!$G$54)+Assumptions!$F$54+$C$8,Assumptions!$E$54))+G43*IF(G44=1,$C$9,IF(Assumptions!$I$55=1,MAX(G7,Assumptions!$G$55)+Assumptions!$F$55+$C$8,Assumptions!$E$55))+G56*IF(G57=1,$C$9,IF(Assumptions!$I$56=1,MAX(G7,Assumptions!$G$56)+Assumptions!$F$56+$C$8,Assumptions!$E$56)) -> 129.54 | H14: =H17*IF(OR(H18=1,Recovery!G39=1),$C$9,IF(Assumptions!$I$53=1,MAX(H7,Assumptions!$G$53)+Assumptions!$F$53+$C$8,Assumptions!$E$53))+H30*IF(OR(H31=1,Recovery!G40=1),$C$9,IF(Assumptions!$I$54=1,MAX(H7,Assumptions!$G$54)+Assumptions!$F$54+$C$8,Assumptions!$E$54))+H43*IF(OR(H44=1,Recovery!G41=1),$C$9,IF(Assumptions!$I$55=1,MAX(H7,Assumptions!$G$55)+Assumptions!$F$55+$C$8,Assumptions!$E$55))+H56*IF(OR(H57=1,Recovery!G42=1),$C$9,IF(Assumptions!$I$56=1,MAX(H7,Assumptions!$G$56)+Assumptions!$F$56+$C$8,Assumptions!$E$56)) -> 156.65947 | I14: =I17*IF(OR(I18=1,Recovery!H39=1),$C$9,IF(Assumptions!$I$53=1,MAX(I7,Assumptions!$G$53)+Assumptions!$F$53+$C$8,Assumptions!$E$53))+I30*IF(OR(I31=1,Recovery!H40=1),$C$9,IF(Assumptions!$I$54=1,MAX(I7,Assumptions!$G$54)+Assumptions!$F$54+$C$8,Assumptions!$E$54))+I43*IF(OR(I44=1,Recovery!H41=1),$C$9,IF(Assumptions!$I$55=1,MAX(I7,Assumptions!$G$55)+Assumptions!$F$55+$C$8,Assumptions!$E$55))+I56*IF(OR(I57=1,Recovery!H42=1),$C$9,IF(Assumptions!$I$56=1,MAX(I7,Assumptions!$G$56)+Assumptions!$F$56+$C$8,Assumptions!$E$56)) -> 139.56049 | J14: =J17*IF(OR(J18=1,Recovery!I39=1),$C$9,IF(Assumptions!$I$53=1,MAX(J7,Assumptions!$G$53)+Assumptions!$F$53+$C$8,Assumptions!$E$53))+J30*IF(OR(J31=1,Recovery!I40=1),$C$9,IF(Assumptions!$I$54=1,MAX(J7,Assumptions!$G$54)+Assumptions!$F$54+$C$8,Assumptions!$E$54))+J43*IF(OR(J44=1,Recovery!I41=1),$C$9,IF(Assumptions!$I$55=1,MAX(J7,Assumptions!$G$55)+Assumptions!$F$55+$C$8,Assumptions!$E$55))+J56*IF(OR(J57=1,Recovery!I42=1),$C$9,IF(Assumptions!$I$56=1,MAX(J7,Assumptions!$G$56)+Assumptions!$F$56+$C$8,Assumptions!$E$56)) -> 134.01169 | K14: =K17*IF(OR(K18=1,Recovery!J39=1),$C$9,IF(Assumptions!$I$53=1,MAX(K7,Assumptions!$G$53)+Assumptions!$F$53+$C$8,Assumptions!$E$53))+K30*IF(OR(K31=1,Recovery!J40=1),$C$9,IF(Assumptions!$I$54=1,MAX(K7,Assumptions!$G$54)+Assumptions!$F$54+$C$8,Assumptions!$E$54))+K43*IF(OR(K44=1,Recovery!J41=1),$C$9,IF(Assumptions!$I$55=1,MAX(K7,Assumptions!$G$55)+Assumptions!$F$55+$C$8,Assumptions!$E$55))+K56*IF(OR(K57=1,Recovery!J42=1),$C$9,IF(Assumptions!$I$56=1,MAX(K7,Assumptions!$G$56)+Assumptions!$F$56+$C$8,Assumptions!$E$56)) -> 127.17409
A15: Market access to refinance? (1 = yes) | G15: =IF('Operating Model'!G17<=0,0,IF(AND((G12-G13)/'Operating Model'!G17<=$C$10,'Operating Model'!G17/G14>=$C$11),1,0)) -> 0 | H15: =IF('Operating Model'!H17<=0,0,IF(AND((H12-H13)/'Operating Model'!H17<=$C$10,'Operating Model'!H17/H14>=$C$11),1,0)) -> 0 | I15: =IF('Operating Model'!I17<=0,0,IF(AND((I12-I13)/'Operating Model'!I17<=$C$10,'Operating Model'!I17/I14>=$C$11),1,0)) -> 0 | J15: =IF('Operating Model'!J17<=0,0,IF(AND((J12-J13)/'Operating Model'!J17<=$C$10,'Operating Model'!J17/J14>=$C$11),1,0)) -> 0 | K15: =IF('Operating Model'!K17<=0,0,IF(AND((K12-K13)/'Operating Model'!K17<=$C$10,'Operating Model'!K17/K14>=$C$11),1,0)) -> 0
A16: Tranche 1: ABL Revolver
A17: Beginning balance | G17: =F28 -> 180 | H17: =G28 -> 216.2968 | I17: =H28 -> 216.2968 | J17: =I28 -> 216.2968 | K17: =J28 -> 216.2968
A18: Maturing this period? (1 = yes) | G18: =IF('Operating Model'!G7=Assumptions!$K$53,1,0) -> 0 | H18: =IF('Operating Model'!H7=Assumptions!$K$53,1,0) -> 1 | I18: =IF('Operating Model'!I7=Assumptions!$K$53,1,0) -> 0 | J18: =IF('Operating Model'!J7=Assumptions!$K$53,1,0) -> 0 | K18: =IF('Operating Model'!K7=Assumptions!$K$53,1,0) -> 0
A20: All-in interest rate applied | G20: =IF(Assumptions!$I$53=1,MAX(G7,Assumptions!$G$53)+Assumptions!$F$53+$C$8,Assumptions!$E$53) -> 0.101 | H20: =IF(Recovery!G39=1,$C$9,IF(Assumptions!$I$53=1,MAX(H7,Assumptions!$G$53)+Assumptions!$F$53+$C$8,Assumptions!$E$53)) -> 0.0985 | I20: =IF(Recovery!H39=1,$C$9,IF(Assumptions!$I$53=1,MAX(I7,Assumptions!$G$53)+Assumptions!$F$53+$C$8,Assumptions!$E$53)) -> 0.096 | J20: =IF(Recovery!I39=1,$C$9,IF(Assumptions!$I$53=1,MAX(J7,Assumptions!$G$53)+Assumptions!$F$53+$C$8,Assumptions!$E$53)) -> 0.096 | K20: =IF(Recovery!J39=1,$C$9,IF(Assumptions!$I$53=1,MAX(K7,Assumptions!$G$53)+Assumptions!$F$53+$C$8,Assumptions!$E$53)) -> 0.096
A21: Cash interest expense | G21: =G17*G20 -> 18.18 | H21: =H17*H20 -> 21.305235 | I21: =I17*I20 -> 20.764493 | J21: =J17*J20 -> 20.764493 | K21: =K17*K20 -> 20.764493
A22: PIK interest | G22: =G17*Assumptions!$H$53 -> 0 | H22: =H17*Assumptions!$H$53 -> 0 | I22: =I17*Assumptions!$H$53 -> 0 | J22: =J17*Assumptions!$H$53 -> 0 | K22: =K17*Assumptions!$H$53 -> 0
A23: Mandatory amortization | G23: =MIN(G17,Assumptions!$L$53*Assumptions!$C$53) -> 0 | H23: =MIN(H17,Assumptions!$L$53*Assumptions!$C$53) -> 0 | I23: =MIN(I17,Assumptions!$L$53*Assumptions!$C$53) -> 0 | J23: =MIN(J17,Assumptions!$L$53*Assumptions!$C$53) -> 0 | K23: =MIN(K17,Assumptions!$L$53*Assumptions!$C$53) -> 0
A24: New borrowing (revolver draw) | G24: =IF(AND(Assumptions!$P$53=1,'Operating Model'!G7<Assumptions!$K$53),MIN(MAX(0,-'Cash Flow'!G11),MAX(0,Assumptions!$D$53-G17)),0) -> 36.2968 | H24: =IF(AND(Assumptions!$P$53=1,OR('Operating Model'!H7<Assumptions!$K$53,Recovery!G39=1)),MIN(MAX(0,-'Cash Flow'!H11),MAX(0,Assumptions!$D$53-H17)),0) -> 0 | I24: =IF(AND(Assumptions!$P$53=1,OR('Operating Model'!I7<Assumptions!$K$53,Recovery!H39=1)),MIN(MAX(0,-'Cash Flow'!I11),MAX(0,Assumptions!$D$53-I17)),0) -> 0 | J24: =IF(AND(Assumptions!$P$53=1,OR('Operating Model'!J7<Assumptions!$K$53,Recovery!I39=1)),MIN(MAX(0,-'Cash Flow'!J11),MAX(0,Assumptions!$D$53-J17)),0) -> 0 | K24: =IF(AND(Assumptions!$P$53=1,OR('Operating Model'!K7<Assumptions!$K$53,Recovery!J39=1)),MIN(MAX(0,-'Cash Flow'!K11),MAX(0,Assumptions!$D$53-K17)),0) -> 0
A25: Repayment at maturity (from available cash) | G25: =G18*MIN(G17-G23+G22,MAX(0,'Cash Flow'!G13-Assumptions!$C$12*G15)) -> 0 | H25: =H18*MIN(H17-H23+H22,MAX(0,'Cash Flow'!H13-Assumptions!$C$12*H15)) -> 0 | I25: =I18*MIN(I17-I23+I22,MAX(0,'Cash Flow'!I13-Assumptions!$C$12*I15)) -> 0 | J25: =J18*MIN(J17-J23+J22,MAX(0,'Cash Flow'!J13-Assumptions!$C$12*J15)) -> 0 | K25: =K18*MIN(K17-K23+K22,MAX(0,'Cash Flow'!K13-Assumptions!$C$12*K15)) -> 0
A26: Optional repayment (cash sweep) | G26: =Assumptions!$N$53*MIN(G17+G24+G22-G23-G25,MAX(0,'Cash Flow'!G17)) -> 0 | H26: =Assumptions!$N$53*MIN(H17+H24+H22-H23-H25,MAX(0,'Cash Flow'!H17)) -> 0 | I26: =Assumptions!$N$53*MIN(I17+I24+I22-I23-I25,MAX(0,'Cash Flow'!I17)) -> 0 | J26: =Assumptions!$N$53*MIN(J17+J24+J22-J23-J25,MAX(0,'Cash Flow'!J17)) -> 0 | K26: =Assumptions!$N$53*MIN(K17+K24+K22-K23-K25,MAX(0,'Cash Flow'!K17)) -> 0
A27: Unpaid at maturity (no refinancing, insufficient cash) | G27: =G18*(1-G15)*(G17-G23+G22-G25) -> 0 | H27: =H18*(1-H15)*(H17-H23+H22-H25) -> 216.2968 | I27: =I18*(1-I15)*(I17-I23+I22-I25) -> 0 | J27: =J18*(1-J15)*(J17-J23+J22-J25) -> 0 | K27: =K18*(1-K15)*(K17-K23+K22-K25) -> 0
A28: Ending balance | F28: =Assumptions!$C$53 -> 180 | G28: =G17+G24+G22-G23-G25-G26 -> 216.2968 | H28: =H17+H24+H22-H23-H25-H26 -> 216.2968 | I28: =I17+I24+I22-I23-I25-I26 -> 216.2968 | J28: =J17+J24+J22-J23-J25-J26 -> 216.2968 | K28: =K17+K24+K22-K23-K25-K26 -> 216.2968
A29: Tranche 2: First-Lien Term Loan
A30: Beginning balance | G30: =F41 -> 520 | H30: =G41 -> 514.8 | I30: =H41 -> 509.6 | J30: =I41 -> 504.4 | K30: =J41 -> 499.2
A31: Maturing this period? (1 = yes) | G31: =IF('Operating Model'!G7=Assumptions!$K$54,1,0) -> 0 | H31: =IF('Operating Model'!H7=Assumptions!$K$54,1,0) -> 0 | I31: =IF('Operating Model'!I7=Assumptions!$K$54,1,0) -> 1 | J31: =IF('Operating Model'!J7=Assumptions!$K$54,1,0) -> 0 | K31: =IF('Operating Model'!K7=Assumptions!$K$54,1,0) -> 0
A33: All-in interest rate applied | G33: =IF(Assumptions!$I$54=1,MAX(G7,Assumptions!$G$54)+Assumptions!$F$54+$C$8,Assumptions!$E$54) -> 0.118 | H33: =IF(Recovery!G40=1,$C$9,IF(Assumptions!$I$54=1,MAX(H7,Assumptions!$G$54)+Assumptions!$F$54+$C$8,Assumptions!$E$54)) -> 0.1155 | I33: =IF(Recovery!H40=1,$C$9,IF(Assumptions!$I$54=1,MAX(I7,Assumptions!$G$54)+Assumptions!$F$54+$C$8,Assumptions!$E$54)) -> 0.113 | J33: =IF(Recovery!I40=1,$C$9,IF(Assumptions!$I$54=1,MAX(J7,Assumptions!$G$54)+Assumptions!$F$54+$C$8,Assumptions!$E$54)) -> 0.113 | K33: =IF(Recovery!J40=1,$C$9,IF(Assumptions!$I$54=1,MAX(K7,Assumptions!$G$54)+Assumptions!$F$54+$C$8,Assumptions!$E$54)) -> 0.113
A34: Cash interest expense | G34: =G30*G33 -> 61.36 | H34: =H30*H33 -> 59.4594 | I34: =I30*I33 -> 57.5848 | J34: =J30*J33 -> 56.9972 | K34: =K30*K33 -> 56.4096
A35: PIK interest | G35: =G30*Assumptions!$H$54 -> 0 | H35: =H30*Assumptions!$H$54 -> 0 | I35: =I30*Assumptions!$H$54 -> 0 | J35: =J30*Assumptions!$H$54 -> 0 | K35: =K30*Assumptions!$H$54 -> 0
A36: Mandatory amortization | G36: =MIN(G30,Assumptions!$L$54*Assumptions!$C$54) -> 5.2 | H36: =MIN(H30,Assumptions!$L$54*Assumptions!$C$54) -> 5.2 | I36: =MIN(I30,Assumptions!$L$54*Assumptions!$C$54) -> 5.2 | J36: =MIN(J30,Assumptions!$L$54*Assumptions!$C$54) -> 5.2 | K36: =MIN(K30,Assumptions!$L$54*Assumptions!$C$54) -> 5.2
A37: New borrowing (revolver draw) | G37: =IF(AND(Assumptions!$P$54=1,'Operating Model'!G7<Assumptions!$K$54),MIN(MAX(0,-'Cash Flow'!G11),MAX(0,Assumptions!$D$54-G30)),0) -> 0 | H37: =IF(AND(Assumptions!$P$54=1,OR('Operating Model'!H7<Assumptions!$K$54,Recovery!G40=1)),MIN(MAX(0,-'Cash Flow'!H11),MAX(0,Assumptions!$D$54-H30)),0) -> 0 | I37: =IF(AND(Assumptions!$P$54=1,OR('Operating Model'!I7<Assumptions!$K$54,Recovery!H40=1)),MIN(MAX(0,-'Cash Flow'!I11),MAX(0,Assumptions!$D$54-I30)),0) -> 0 | J37: =IF(AND(Assumptions!$P$54=1,OR('Operating Model'!J7<Assumptions!$K$54,Recovery!I40=1)),MIN(MAX(0,-'Cash Flow'!J11),MAX(0,Assumptions!$D$54-J30)),0) -> 0 | K37: =IF(AND(Assumptions!$P$54=1,OR('Operating Model'!K7<Assumptions!$K$54,Recovery!J40=1)),MIN(MAX(0,-'Cash Flow'!K11),MAX(0,Assumptions!$D$54-K30)),0) -> 0
A38: Repayment at maturity (from available cash) | G38: =G31*MIN(G30-G36+G35,MAX(0,'Cash Flow'!G13-Assumptions!$C$12*G15-G25)) -> 0 | H38: =H31*MIN(H30-H36+H35,MAX(0,'Cash Flow'!H13-Assumptions!$C$12*H15-H25)) -> 0 | I38: =I31*MIN(I30-I36+I35,MAX(0,'Cash Flow'!I13-Assumptions!$C$12*I15-I25)) -> 0 | J38: =J31*MIN(J30-J36+J35,MAX(0,'Cash Flow'!J13-Assumptions!$C$12*J15-J25)) -> 0 | K38: =K31*MIN(K30-K36+K35,MAX(0,'Cash Flow'!K13-Assumptions!$C$12*K15-K25)) -> 0
A39: Optional repayment (cash sweep) | G39: =Assumptions!$N$54*MIN(G30+G37+G35-G36-G38,MAX(0,'Cash Flow'!G17-G26)) -> 0 | H39: =Assumptions!$N$54*MIN(H30+H37+H35-H36-H38,MAX(0,'Cash Flow'!H17-H26)) -> 0 | I39: =Assumptions!$N$54*MIN(I30+I37+I35-I36-I38,MAX(0,'Cash Flow'!I17-I26)) -> 0 | J39: =Assumptions!$N$54*MIN(J30+J37+J35-J36-J38,MAX(0,'Cash Flow'!J17-J26)) -> 0 | K39: =Assumptions!$N$54*MIN(K30+K37+K35-K36-K38,MAX(0,'Cash Flow'!K17-K26)) -> 0
A40: Unpaid at maturity (no refinancing, insufficient cash) | G40: =G31*(1-G15)*(G30-G36+G35-G38) -> 0 | H40: =H31*(1-H15)*(H30-H36+H35-H38) -> 0 | I40: =I31*(1-I15)*(I30-I36+I35-I38) -> 504.4 | J40: =J31*(1-J15)*(J30-J36+J35-J38) -> 0 | K40: =K31*(1-K15)*(K30-K36+K35-K38) -> 0
A41: Ending balance | F41: =Assumptions!$C$54 -> 520 | G41: =G30+G37+G35-G36-G38-G39 -> 514.8 | H41: =H30+H37+H35-H36-H38-H39 -> 509.6 | I41: =I30+I37+I35-I36-I38-I39 -> 504.4 | J41: =J30+J37+J35-J36-J38-J39 -> 499.2 | K41: =K30+K37+K35-K36-K38-K39 -> 494
A42: Tranche 3: Second-Lien Notes 11.0%
A43: Beginning balance | G43: =F54 -> 250 | H43: =G54 -> 250 | I43: =H54 -> 250 | J43: =I54 -> 250 | K43: =J54 -> 250
A44: Maturing this period? (1 = yes) | G44: =IF('Operating Model'!G7=Assumptions!$K$55,1,0) -> 0 | H44: =IF('Operating Model'!H7=Assumptions!$K$55,1,0) -> 0 | I44: =IF('Operating Model'!I7=Assumptions!$K$55,1,0) -> 0 | J44: =IF('Operating Model'!J7=Assumptions!$K$55,1,0) -> 1 | K44: =IF('Operating Model'!K7=Assumptions!$K$55,1,0) -> 0
...

Sheet Cash Flow
A1: Cash Flow & Liquidity — cash waterfall and default test
A2: ="Brightwater Retail Holdings · DEMO DATA · DEMO INVESTMENT TERMS · Active scenario: "&Assumptions!$D$10 -> Brightwater Retail Holdings · DEMO DATA · DEMO INVESTMENT TERMS · Active scenario: Downside
A4: $M | C4: FY2022A | D4: FY2023A | E4: FY2024A | F4: FY2025A | G4: FY2026E | H4: FY2027E | I4: FY2028E | J4: FY2029E | K4: FY2030E
A6: Cash flow & liquidity waterfall ($M)
A7: Beginning cash | G7: =F19 -> 45 | H7: =G19 -> 0 | I7: =H19 -> -121.35573 | J7: =I19 -> -236.70218 | K7: =J19 -> -337.79889
A8: Free cash flow (from Operating Model) | G8: ='Operating Model'!G30 -> -76.0968 | H8: ='Operating Model'!H30 -> -116.15573 | I8: ='Operating Model'!I30 -> -110.14645 | J8: ='Operating Model'!J30 -> -95.896716 | K8: ='Operating Model'!K30 -> -83.185191
A9: Plus: net asset-sale proceeds | G9: =CHOOSE(Assumptions!$C$10,Assumptions!$G$68,Assumptions!$G$87,Assumptions!$G$106) -> 0 | H9: =CHOOSE(Assumptions!$C$10,Assumptions!$H$68,Assumptions!$H$87,Assumptions!$H$106) -> 0 | I9: =CHOOSE(Assumptions!$C$10,Assumptions!$I$68,Assumptions!$I$87,Assumptions!$I$106) -> 0 | J9: =CHOOSE(Assumptions!$C$10,Assumptions!$J$68,Assumptions!$J$87,Assumptions!$J$106) -> 0 | K9: =CHOOSE(Assumptions!$C$10,Assumptions!$K$68,Assumptions!$K$87,Assumptions!$K$106) -> 0
A10: Less: mandatory amortization | G10: ='Debt Schedule'!G23+'Debt Schedule'!G36+'Debt Schedule'!G49+'Debt Schedule'!G62 -> 5.2 | H10: ='Debt Schedule'!H23+'Debt Schedule'!H36+'Debt Schedule'!H49+'Debt Schedule'!H62 -> 5.2 | I10: ='Debt Schedule'!I23+'Debt Schedule'!I36+'Debt Schedule'!I49+'Debt Schedule'!I62 -> 5.2 | J10: ='Debt Schedule'!J23+'Debt Schedule'!J36+'Debt Schedule'!J49+'Debt Schedule'!J62 -> 5.2 | K10: ='Debt Schedule'!K23+'Debt Schedule'!K36+'Debt Schedule'!K49+'Debt Schedule'!K62 -> 5.2
A11: Cash after mandatory debt service | G11: =G7+G8+G9-G10 -> -36.2968 | H11: =H7+H8+H9-H10 -> -121.35573 | I11: =I7+I8+I9-I10 -> -236.70218 | J11: =J7+J8+J9-J10 -> -337.79889 | K11: =K7+K8+K9-K10 -> -426.18408
A12: Plus: revolver draw | G12: ='Debt Schedule'!G24+'Debt Schedule'!G37+'Debt Schedule'!G50+'Debt Schedule'!G63 -> 36.2968 | H12: ='Debt Schedule'!H24+'Debt Schedule'!H37+'Debt Schedule'!H50+'Debt Schedule'!H63 -> 0 | I12: ='Debt Schedule'!I24+'Debt Schedule'!I37+'Debt Schedule'!I50+'Debt Schedule'!I63 -> 0 | J12: ='Debt Schedule'!J24+'Debt Schedule'!J37+'Debt Schedule'!J50+'Debt Schedule'!J63 -> 0 | K12: ='Debt Schedule'!K24+'Debt Schedule'!K37+'Debt Schedule'!K50+'Debt Schedule'!K63 -> 0
A13: Cash available for maturities | G13: =G11+G12 -> 0 | H13: =H11+H12 -> -121.35573 | I13: =I11+I12 -> -236.70218 | J13: =J11+J12 -> -337.79889 | K13: =K11+K12 -> -426.18408
A14: Less: repayment of maturing debt | G14: ='Debt Schedule'!G25+'Debt Schedule'!G38+'Debt Schedule'!G51+'Debt Schedule'!G64 -> 0 | H14: ='Debt Schedule'!H25+'Debt Schedule'!H38+'Debt Schedule'!H51+'Debt Schedule'!H64 -> 0 | I14: ='Debt Schedule'!I25+'Debt Schedule'!I38+'Debt Schedule'!I51+'Debt Schedule'!I64 -> 0 | J14: ='Debt Schedule'!J25+'Debt Schedule'!J38+'Debt Schedule'!J51+'Debt Schedule'!J64 -> 0 | K14: ='Debt Schedule'!K25+'Debt Schedule'!K38+'Debt Schedule'!K51+'Debt Schedule'!K64 -> 0
A15: Cash before sweep | G15: =G13-G14 -> 0 | H15: =H13-H14 -> -121.35573 | I15: =I13-I14 -> -236.70218 | J15: =J13-J14 -> -337.79889 | K15: =K13-K14 -> -426.18408
A16: Funding gap (shortfall after cash & revolver) | G16: =MAX(0,-G15) -> 0 | H16: =MAX(0,-H15) -> 121.35573 | I16: =MAX(0,-I15) -> 236.70218 | J16: =MAX(0,-J15) -> 337.79889 | K16: =MAX(0,-K15) -> 426.18408
A17: Excess cash available for sweep | G17: =MAX(0,G15-Assumptions!$C$12)*Assumptions!$C$13 -> 0 | H17: =MAX(0,H15-Assumptions!$C$12)*Assumptions!$C$13 -> 0 | I17: =MAX(0,I15-Assumptions!$C$12)*Assumptions!$C$13 -> 0 | J17: =MAX(0,J15-Assumptions!$C$12)*Assumptions!$C$13 -> 0 | K17: =MAX(0,K15-Assumptions!$C$12)*Assumptions!$C$13 -> 0
A18: Less: optional repayment (cash sweep) | G18: ='Debt Schedule'!G26+'Debt Schedule'!G39+'Debt Schedule'!G52+'Debt Schedule'!G65 -> 0 | H18: ='Debt Schedule'!H26+'Debt Schedule'!H39+'Debt Schedule'!H52+'Debt Schedule'!H65 -> 0 | I18: ='Debt Schedule'!I26+'Debt Schedule'!I39+'Debt Schedule'!I52+'Debt Schedule'!I65 -> 0 | J18: ='Debt Schedule'!J26+'Debt Schedule'!J39+'Debt Schedule'!J52+'Debt Schedule'!J65 -> 0 | K18: ='Debt Schedule'!K26+'Debt Schedule'!K39+'Debt Schedule'!K52+'Debt Schedule'!K65 -> 0
A19: Ending cash | F19: =Assumptions!$C$11 -> 45 | G19: =G15-G18 -> 0 | H19: =H15-H18 -> -121.35573 | I19: =I15-I18 -> -236.70218 | J19: =J15-J18 -> -337.79889 | K19: =K15-K18 -> -426.18408
A20: Unpaid maturities (balance left outstanding) | G20: ='Debt Schedule'!G27+'Debt Schedule'!G40+'Debt Schedule'!G53+'Debt Schedule'!G66 -> 0 | H20: ='Debt Schedule'!H27+'Debt Schedule'!H40+'Debt Schedule'!H53+'Debt Schedule'!H66 -> 516.2968 | I20: ='Debt Schedule'!I27+'Debt Schedule'!I40+'Debt Schedule'!I53+'Debt Schedule'!I66 -> 504.4 | J20: ='Debt Schedule'!J27+'Debt Schedule'!J40+'Debt Schedule'!J53+'Debt Schedule'!J66 -> 250 | K20: ='Debt Schedule'!K27+'Debt Schedule'!K40+'Debt Schedule'!K53+'Debt Schedule'!K66 -> 0
A21: Payment default? (1 = yes) | G21: =IF(OR(G16>0.001,G20>0.001),1,0) -> 0 | H21: =IF(OR(H16>0.001,H20>0.001),1,0) -> 1 | I21: =IF(OR(I16>0.001,I20>0.001),1,0) -> 1 | J21: =IF(OR(J16>0.001,J20>0.001),1,0) -> 1 | K21: =IF(OR(K16>0.001,K20>0.001),1,0) -> 1
A22: First default period flag | G22: =IF(G21=1,1,0) -> 0 | H22: =IF(AND(H21=1,SUM($G$21:G21)=0),1,0) -> 1 | I22: =IF(AND(I21=1,SUM($G$21:H21)=0),1,0) -> 0 | J22: =IF(AND(J21=1,SUM($G$21:I21)=0),1,0) -> 0 | K22: =IF(AND(K21=1,SUM($G$21:J21)=0),1,0) -> 0
A23: Check: Δ debt = draws + PIK − repayments | G23: =('Debt Schedule'!G69-'Debt Schedule'!F69)-(G12+'Operating Model'!G22-G10-G14-G18) -> 0 | H23: =('Debt Schedule'!H69-'Debt Schedule'!G69)-(H12+'Operating Model'!H22-H10-H14-H18) -> -4.5297099e-14 | I23: =('Debt Schedule'!I69-'Debt Schedule'!H69)-(I12+'Operating Model'!I22-I10-I14-I18) -> 1.8207658e-13 | J23: =('Debt Schedule'!J69-'Debt Schedule'!I69)-(J12+'Operating Model'!J22-J10-J14-J18) -> -2.7267077e-13 | K23: =('Debt Schedule'!K69-'Debt Schedule'!J69)-(K12+'Operating Model'!K22-K10-K14-K18) -> 1.8207658e-13

Sheet Credit Metrics
A1: Credit Metrics, Covenants & Credit Score
A2: ="Brightwater Retail Holdings · DEMO DATA · DEMO INVESTMENT TERMS · Active scenario: "&Assumptions!$D$10 -> Brightwater Retail Holdings · DEMO DATA · DEMO INVESTMENT TERMS · Active scenario: Downside
A4: $M | C4: FY2022A | D4: FY2023A | E4: FY2024A | F4: FY2025A | G4: FY2026E | H4: FY2027E | I4: FY2028E | J4: FY2029E | K4: FY2030E
A6: Credit metrics (selected scenario)
A7: Total debt (face value) | F7: ='Debt Schedule'!F69 -> 1250 | G7: ='Debt Schedule'!G69 -> 1281.0968 | H7: ='Debt Schedule'!H69 -> 1275.8968 | I7: ='Debt Schedule'!I69 -> 1270.6968 | J7: ='Debt Schedule'!J69 -> 1265.4968 | K7: ='Debt Schedule'!K69 -> 1260.2968
A8: Secured debt | F8: =Assumptions!$O$53*'Debt Schedule'!F28+Assumptions!$O$54*'Debt Schedule'!F41+Assumptions!$O$55*'Debt Schedule'!F54+Assumptions!$O$56*'Debt Schedule'!F67 -> 950 | G8: =Assumptions!$O$53*'Debt Schedule'!G28+Assumptions!$O$54*'Debt Schedule'!G41+Assumptions!$O$55*'Debt Schedule'!G54+Assumptions!$O$56*'Debt Schedule'!G67 -> 981.0968 | H8: =Assumptions!$O$53*'Debt Schedule'!H28+Assumptions!$O$54*'Debt Schedule'!H41+Assumptions!$O$55*'Debt Schedule'!H54+Assumptions!$O$56*'Debt Schedule'!H67 -> 975.8968 | I8: =Assumptions!$O$53*'Debt Schedule'!I28+Assumptions!$O$54*'Debt Schedule'!I41+Assumptions!$O$55*'Debt Schedule'!I54+Assumptions!$O$56*'Debt Schedule'!I67 -> 970.6968 | J8: =Assumptions!$O$53*'Debt Schedule'!J28+Assumptions!$O$54*'Debt Schedule'!J41+Assumptions!$O$55*'Debt Schedule'!J54+Assumptions!$O$56*'Debt Schedule'!J67 -> 965.4968 | K8: =Assumptions!$O$53*'Debt Schedule'!K28+Assumptions!$O$54*'Debt Schedule'!K41+Assumptions!$O$55*'Debt Schedule'!K54+Assumptions!$O$56*'Debt Schedule'!K67 -> 960.2968
A9: Net debt | F9: =F7-'Cash Flow'!F19 -> 1205 | G9: =G7-'Cash Flow'!G19 -> 1281.0968 | H9: =H7-'Cash Flow'!H19 -> 1397.2525 | I9: =I7-'Cash Flow'!I19 -> 1507.399 | J9: =J7-'Cash Flow'!J19 -> 1603.2957 | K9: =K7-'Cash Flow'!K19 -> 1686.4809
A10: Gross debt / EBITDA | F10: =IF('Operating Model'!F17>0,F7/'Operating Model'!F17,0) -> 8.0128205 | G10: =IF('Operating Model'!G17>0,G7/'Operating Model'!G17,0) -> 16.54138 | H10: =IF('Operating Model'!H17>0,H7/'Operating Model'!H17,0) -> 26.086881 | I10: =IF('Operating Model'!I17>0,I7/'Operating Model'!I17,0) -> 20.708818 | J10: =IF('Operating Model'!J17>0,J7/'Operating Model'!J17,0) -> 17.261128 | K10: =IF('Operating Model'!K17>0,K7/'Operating Model'!K17,0) -> 14.82279
A11: Net debt / EBITDA | F11: =IF('Operating Model'!F17>0,F9/'Operating Model'!F17,0) -> 7.724359 | G11: =IF('Operating Model'!G17>0,G9/'Operating Model'!G17,0) -> 16.54138 | H11: =IF('Operating Model'!H17>0,H9/'Operating Model'!H17,0) -> 28.568111 | I11: =IF('Operating Model'!I17>0,I9/'Operating Model'!I17,0) -> 24.566404 | J11: =IF('Operating Model'!J17>0,J9/'Operating Model'!J17,0) -> 21.868639 | K11: =IF('Operating Model'!K17>0,K9/'Operating Model'!K17,0) -> 19.83529
A12: Interest coverage (EBITDA / cash interest) | F12: =IF('Operating Model'!F23>0,'Operating Model'!F17/'Operating Model'!F23,0) -> 1.3104839 | G12: =IF('Operating Model'!G21>0,'Operating Model'!G17/'Operating Model'!G21,0) -> 0.59786938 | H12: =IF('Operating Model'!H21>0,'Operating Model'!H17/'Operating Model'!H21,0) -> 0.37402711 | I12: =IF('Operating Model'!I21>0,'Operating Model'!I17/'Operating Model'!I21,0) -> 0.47807182 | J12: =IF('Operating Model'!J21>0,'Operating Model'!J17/'Operating Model'!J21,0) -> 0.57384052 | K12: =IF('Operating Model'!K21>0,'Operating Model'!K17/'Operating Model'!K21,0) -> 0.66856591
A13: EBIT / interest | F13: =IF('Operating Model'!F23>0,'Operating Model'!F20/'Operating Model'!F23,0) -> 0.86693548 | G13: =IF('Operating Model'!G21>0,'Operating Model'!G20/'Operating Model'!G21,0) -> 0.22206577 | H13: =IF('Operating Model'!H21>0,'Operating Model'!H20/'Operating Model'!H21,0) -> 0.016262048 | I13: =IF('Operating Model'!I21>0,'Operating Model'!I20/'Operating Model'!I21,0) -> 0.11539665 | J13: =IF('Operating Model'!J21>0,'Operating Model'!J20/'Operating Model'!J21,0) -> 0.21314077 | K13: =IF('Operating Model'!K21>0,'Operating Model'!K20/'Operating Model'!K21,0) -> 0.30982323
A14: FCF / debt | F14: =IF(F7>0,'Operating Model'!F30/F7,0) -> -0.002112 | G14: =IF(G7>0,'Operating Model'!G30/G7,0) -> -0.059399727 | H14: =IF(H7>0,'Operating Model'!H30/H7,0) -> -0.091038499 | I14: =IF(I7>0,'Operating Model'!I30/I7,0) -> -0.086681926 | J14: =IF(J7>0,'Operating Model'!J30/J7,0) -> -0.075777921 | K14: =IF(K7>0,'Operating Model'!K30/K7,0) -> -0.066004445
A15: Debt service coverage ((EBITDA − capex − tax) / (cash interest + amortization)) | G15: =IF('Operating Model'!G21+'Cash Flow'!G10>0,('Operating Model'!G17-'Operating Model'!G28-'Operating Model'!G25)/('Operating Model'!G21+'Cash Flow'!G10),0) -> 0.26276384 | H15: =IF('Operating Model'!H21+'Cash Flow'!H10>0,('Operating Model'!H17-'Operating Model'!H28-'Operating Model'!H25)/('Operating Model'!H21+'Cash Flow'!H10),0) -> 0.062560409 | I15: =IF('Operating Model'!I21+'Cash Flow'!I10>0,('Operating Model'!I17-'Operating Model'!I28-'Operating Model'!I25)/('Operating Model'!I21+'Cash Flow'!I10),0) -> 0.15843351 | J15: =IF('Operating Model'!J21+'Cash Flow'!J10>0,('Operating Model'!J17-'Operating Model'!J28-'Operating Model'!J25)/('Operating Model'!J21+'Cash Flow'!J10),0) -> 0.25206774 | K15: =IF('Operating Model'!K21+'Cash Flow'!K10>0,('Operating Model'!K17-'Operating Model'!K28-'Operating Model'!K25)/('Operating Model'!K21+'Cash Flow'!K10),0) -> 0.34465033
A16: Liquidity (cash + undrawn revolver) | F16: =MAX(0,'Cash Flow'!F19)+Assumptions!$P$53*MAX(0,Assumptions!$D$53-'Debt Schedule'!F28)+Assumptions!$P$54*MAX(0,Assumptions!$D$54-'Debt Schedule'!F41)+Assumptions!$P$55*MAX(0,Assumptions!$D$55-'Debt Schedule'!F54)+Assumptions!$P$56*MAX(0,Assumptions!$D$56-'Debt Schedule'!F67) -> 165 | G16: =MAX(0,'Cash Flow'!G19)+Assumptions!$P$53*MAX(0,Assumptions!$D$53-'Debt Schedule'!G28)+Assumptions!$P$54*MAX(0,Assumptions!$D$54-'Debt Schedule'!G41)+Assumptions!$P$55*MAX(0,Assumptions!$D$55-'Debt Schedule'!G54)+Assumptions!$P$56*MAX(0,Assumptions!$D$56-'Debt Schedule'!G67) -> 83.7032 | H16: =MAX(0,'Cash Flow'!H19)+Assumptions!$P$53*MAX(0,Assumptions!$D$53-'Debt Schedule'!H28)+Assumptions!$P$54*MAX(0,Assumptions!$D$54-'Debt Schedule'!H41)+Assumptions!$P$55*MAX(0,Assumptions!$D$55-'Debt Schedule'!H54)+Assumptions!$P$56*MAX(0,Assumptions!$D$56-'Debt Schedule'!H67) -> 83.7032 | I16: =MAX(0,'Cash Flow'!I19)+Assumptions!$P$53*MAX(0,Assumptions!$D$53-'Debt Schedule'!I28)+Assumptions!$P$54*MAX(0,Assumptions!$D$54-'Debt Schedule'!I41)+Assumptions!$P$55*MAX(0,Assumptions!$D$55-'Debt Schedule'!I54)+Assumptions!$P$56*MAX(0,Assumptions!$D$56-'Debt Schedule'!I67) -> 83.7032 | J16: =MAX(0,'Cash Flow'!J19)+Assumptions!$P$53*MAX(0,Assumptions!$D$53-'Debt Schedule'!J28)+Assumptions!$P$54*MAX(0,Assumptions!$D$54-'Debt Schedule'!J41)+Assumptions!$P$55*MAX(0,Assumptions!$D$55-'Debt Schedule'!J54)+Assumptions!$P$56*MAX(0,Assumptions!$D$56-'Debt Schedule'!J67) -> 83.7032 | K16: =MAX(0,'Cash Flow'!K19)+Assumptions!$P$53*MAX(0,Assumptions!$D$53-'Debt Schedule'!K28)+Assumptions!$P$54*MAX(0,Assumptions!$D$54-'Debt Schedule'!K41)+Assumptions!$P$55*MAX(0,Assumptions!$D$55-'Debt Schedule'!K54)+Assumptions!$P$56*MAX(0,Assumptions!$D$56-'Debt Schedule'!K67) -> 83.7032
A17: Debt / capital (debt + implied equity) | G17: =IF(G7>0,G7/(G7+MAX(0,'Operating Model'!G17*CHOOSE(Assumptions!$C$10,Assumptions!$C$76,Assumptions!$C$95,Assumptions!$C$114)-G9)),0) -> 1 | H17: =IF(H7>0,H7/(H7+MAX(0,'Operating Model'!H17*CHOOSE(Assumptions!$C$10,Assumptions!$C$76,Assumptions!$C$95,Assumptions!$C$114)-H9)),0) -> 1 | I17: =IF(I7>0,I7/(I7+MAX(0,'Operating Model'!I17*CHOOSE(Assumptions!$C$10,Assumptions!$C$76,Assumptions!$C$95,Assumptions!$C$114)-I9)),0) -> 1 | J17: =IF(J7>0,J7/(J7+MAX(0,'Operating Model'!J17*CHOOSE(Assumptions!$C$10,Assumptions!$C$76,Assumptions!$C$95,Assumptions!$C$114)-J9)),0) -> 1 | K17: =IF(K7>0,K7/(K7+MAX(0,'Operating Model'!K17*CHOOSE(Assumptions!$C$10,Assumptions!$C$76,Assumptions!$C$95,Assumptions!$C$114)-K9)),0) -> 1
A18: Cash / debt | F18: =IF(F7>0,MAX(0,'Cash Flow'!F19)/F7,0) -> 0.036 | G18: =IF(G7>0,MAX(0,'Cash Flow'!G19)/G7,0) -> 0 | H18: =IF(H7>0,MAX(0,'Cash Flow'!H19)/H7,0) -> 0 | I18: =IF(I7>0,MAX(0,'Cash Flow'!I19)/I7,0) -> 0 | J18: =IF(J7>0,MAX(0,'Cash Flow'!J19)/J7,0) -> 0 | K18: =IF(K7>0,MAX(0,'Cash Flow'!K19)/K7,0) -> 0
A19: Asset value after scenario decline | G19: =Assumptions!$C$27*(1-CHOOSE(Assumptions!$C$10,Assumptions!$C$79,Assumptions!$C$98,Assumptions!$C$117)) -> 884 | H19: =Assumptions!$C$27*(1-CHOOSE(Assumptions!$C$10,Assumptions!$C$79,Assumptions!$C$98,Assumptions!$C$117)) -> 884 | I19: =Assumptions!$C$27*(1-CHOOSE(Assumptions!$C$10,Assumptions!$C$79,Assumptions!$C$98,Assumptions!$C$117)) -> 884 | J19: =Assumptions!$C$27*(1-CHOOSE(Assumptions!$C$10,Assumptions!$C$79,Assumptions!$C$98,Assumptions!$C$117)) -> 884 | K19: =Assumptions!$C$27*(1-CHOOSE(Assumptions!$C$10,Assumptions!$C$79,Assumptions!$C$98,Assumptions!$C$117)) -> 884
A20: Covenant compliance (active covenants; tests use model-basis metrics)
A21: Maximum net leverage [HYPOTHETICAL]
A22: Metric | G22: =IF('Operating Model'!G17>0,G9/'Operating Model'!G17,99) -> 16.54138 | H22: =IF('Operating Model'!H17>0,H9/'Operating Model'!H17,99) -> 28.568111 | I22: =IF('Operating Model'!I17>0,I9/'Operating Model'!I17,99) -> 24.566404 | J22: =IF('Operating Model'!J17>0,J9/'Operating Model'!J17,99) -> 21.868639 | K22: =IF('Operating Model'!K17>0,K9/'Operating Model'!K17,99) -> 19.83529
A23: Covenant threshold | G23: =Assumptions!$G$61 -> 8.5 | H23: =Assumptions!$H$61 -> 8.5 | I23: =Assumptions!$I$61 -> 8.5 | J23: =Assumptions!$J$61 -> 8.5 | K23: =Assumptions!$K$61 -> 8.5
A24: Headroom | G24: =G23-G22 -> -8.04138 | H24: =H23-H22 -> -20.068111 | I24: =I23-I22 -> -16.066404 | J24: =J23-J22 -> -13.368639 | K24: =K23-K22 -> -11.33529
A25: Headroom % of threshold | G25: =IF(G23=0,0,G24/ABS(G23)) -> -0.94604471 | H25: =IF(H23=0,0,H24/ABS(H23)) -> -2.3609542 | I25: =IF(I23=0,0,I24/ABS(I23)) -> -1.8901652 | J25: =IF(J23=0,0,J24/ABS(J23)) -> -1.5727811 | K25: =IF(K23=0,0,K24/ABS(K23)) -> -1.3335635
A26: BREACH? (1 = yes) | G26: =IF(G24<0,1,0) -> 1 | H26: =IF(H24<0,1,0) -> 1 | I26: =IF(I24<0,1,0) -> 1 | J26: =IF(J24<0,1,0) -> 1 | K26: =IF(K24<0,1,0) -> 1
A27: First breach period (0 = none) | C27: =IFERROR(INDEX('Operating Model'!$G$7:$K$7,MATCH(1,$G$26:$K$26,0)),0) -> 2026
A28: Minimum headroom % | C28: =MIN($G$25:$K$25) -> -2.3609542
A29: Covenant breaches (count, all active covenants) | G29: =G26 -> 1 | H29: =H26 -> 1 | I29: =I26 -> 1 | J29: =J26 -> 1 | K29: =K26 -> 1
A30: Total breaches across projection | C30: =SUM($G$29:$K$29) -> 5
A31: Minimum covenant headroom % (all active covenants) | C31: =MIN(C28) -> -2.3609542
A34: Credit score — transparent, formula-driven (base period; weights & thresholds on Assumptions §8)
A35: Factor | C35: Value | D35: Best | E35: Worst | F35: Weight | G35: Points | H35: Score % | I35: Projected value (period 1, selected scenario) | J35: Projected points
A36: Net leverage (net debt / EBITDA) | C36: ='Credit Metrics'!F11 -> 7.724359 | D36: =Assumptions!$D$125 -> 2 | E36: =Assumptions!$E$125 -> 7 | F36: =Assumptions!$C$125 -> 15 | G36: =F36*H36 -> 0 | H36: =MAX(0,MIN(1,(C36-E36)/(D36-E36))) -> 0 | I36: ='Credit Metrics'!G11 -> 16.54138 | J36: =F36*MAX(0,MIN(1,(I36-E36)/(D36-E36))) -> 0
A37: Interest coverage (EBITDA / interest) | C37: ='Credit Metrics'!F12 -> 1.3104839 | D37: =Assumptions!$D$126 -> 5 | E37: =Assumptions!$E$126 -> 1 | F37: =Assumptions!$C$126 -> 15 | G37: =F37*H37 -> 1.1643145 | H37: =MAX(0,MIN(1,(C37-E37)/(D37-E37))) -> 0.077620968 | I37: ='Credit Metrics'!G12 -> 0.59786938 | J37: =F37*MAX(0,MIN(1,(I37-E37)/(D37-E37))) -> 0
A38: Liquidity ratio (liquidity / next-period obligations) | C38: ='Credit Metrics'!F16/(SUMPRODUCT((Assumptions!$K$53:$K$56<=Assumptions!$C$6+1)*Assumptions!$C$53:$C$56)+SUMPRODUCT(Assumptions!$L$53:$L$56*Assumptions!$C$53:$C$56)+'Operating Model'!F23) -> 1.3280747 | D38: =Assumptions!$D$127 -> 2 | E38: =Assumptions!$E$127 -> 0.5 | F38: =Assumptions!$C$127 -> 10 | G38: =F38*H38 -> 5.520498 | H38: =MAX(0,MIN(1,(C38-E38)/(D38-E38))) -> 0.5520498 | I38: ='Credit Metrics'!G16/(SUMPRODUCT((Assumptions!$K$53:$K$56<=Assumptions!$C$6+1)*Assumptions!$C$53:$C$56)+SUMPRODUCT(Assumptions!$L$53:$L$56*Assumptions!$C$53:$C$56)+'Operating Model'!F23) -> 0.67372183 | J38: =F38*MAX(0,MIN(1,(I38-E38)/(D38-E38))) -> 1.1581455
A39: FCF / total debt | C39: ='Credit Metrics'!F14 -> -0.002112 | D39: =Assumptions!$D$128 -> 0.12 | E39: =Assumptions!$E$128 -> -0.02 | F39: =Assumptions!$C$128 -> 10 | G39: =F39*H39 -> 1.2777143 | H39: =MAX(0,MIN(1,(C39-E39)/(D39-E39))) -> 0.12777143 | I39: ='Credit Metrics'!G14 -> -0.059399727 | J39: =F39*MAX(0,MIN(1,(I39-E39)/(D39-E39))) -> 0
A40: Share of debt maturing within window | C40: =SUMPRODUCT((Assumptions!$K$53:$K$56<=Assumptions!$C$6+Assumptions!$C$22)*Assumptions!$C$53:$C$56)/SUM(Assumptions!$C$53:$C$56) -> 0.8 | D40: =Assumptions!$D$129 -> 0 | E40: =Assumptions!$E$129 -> 0.5 | F40: =Assumptions!$C$129 -> 10 | G40: =F40*H40 -> 0 | H40: =MAX(0,MIN(1,(C40-E40)/(D40-E40))) -> 0 | I40: =C40 -> 0.8 | J40: =F40*MAX(0,MIN(1,(I40-E40)/(D40-E40))) -> 0
A41: Margin stability (σ of annual EBITDA margin) | C41: =STDEVP('Historical Financials'!B35:E35) -> 0.0076321688 | D41: =Assumptions!$D$130 -> 0.01 | E41: =Assumptions!$E$130 -> 0.05 | F41: =Assumptions!$C$130 -> 10 | G41: =F41*H41 -> 10 | H41: =MAX(0,MIN(1,(C41-E41)/(D41-E41))) -> 1 | I41: =C41 -> 0.0076321688 | J41: =F41*MAX(0,MIN(1,(I41-E41)/(D41-E41))) -> 10
A42: Revenue stability (σ of annual growth) | C42: =STDEVP('Historical Financials'!C36:E36) -> 0.0029719935 | D42: =Assumptions!$D$131 -> 0.03 | E42: =Assumptions!$E$131 -> 0.15 | F42: =Assumptions!$C$131 -> 8 | G42: =F42*H42 -> 8 | H42: =MAX(0,MIN(1,(C42-E42)/(D42-E42))) -> 1 | I42: =C42 -> 0.0029719935 | J42: =F42*MAX(0,MIN(1,(I42-E42)/(D42-E42))) -> 8
A43: Asset coverage (asset base / debt) | C43: =Assumptions!$C$27/'Credit Metrics'!F7 -> 0.832 | D43: =Assumptions!$D$132 -> 2 | E43: =Assumptions!$E$132 -> 0.6 | F43: =Assumptions!$C$132 -> 12 | G43: =F43*H43 -> 1.9885714 | H43: =MAX(0,MIN(1,(C43-E43)/(D43-E43))) -> 0.16571429 | I43: =C43 -> 0.832 | J43: =F43*MAX(0,MIN(1,(I43-E43)/(D43-E43))) -> 1.9885714
A44: Industry risk factor (analyst input, 0-1) | C44: =Assumptions!$C$134 -> 0.25 | D44: =Assumptions!$D$133 -> 1 | E44: =Assumptions!$E$133 -> 0 | F44: =Assumptions!$C$133 -> 10 | G44: =F44*H44 -> 2.5 | H44: =MAX(0,MIN(1,(C44-E44)/(D44-E44))) -> 0.25 | I44: =C44 -> 0.25 | J44: =F44*MAX(0,MIN(1,(I44-E44)/(D44-E44))) -> 2.5
...

Sheet Scenarios
A1: Scenarios — side-by-side (all three run simultaneously on Calc Engine)
A2: ="Active scenario for the detailed tabs: "&Assumptions!$D$10 -> Active scenario for the detailed tabs: Downside
A4: Assumptions (links to Assumptions tab) | C4: Base Case | D4: Downside | E4: Severe Downside | F4: Selected
A5: Average revenue growth (5 periods) | C5: =AVERAGE(Assumptions!$G$65:$K$65) -> -0.01 | D5: =AVERAGE(Assumptions!$G$84:$K$84) -> -0.0284 | E5: =AVERAGE(Assumptions!$G$103:$K$103) -> -0.082 | F5: =CHOOSE(Assumptions!$C$10,C5,D5,E5) -> -0.0284
A6: Average EBITDA margin (5 periods) | C6: =AVERAGE(Assumptions!$G$67:$K$67) -> 0.069 | D6: =AVERAGE(Assumptions!$G$86:$K$86) -> 0.0326 | E6: =AVERAGE(Assumptions!$G$105:$K$105) -> 0.01 | F6: =CHOOSE(Assumptions!$C$10,C6,D6,E6) -> 0.0326
A7: Floating-rate shock | C7: =Assumptions!$C$72 -> 0 | D7: =Assumptions!$C$91 -> 0.015 | E7: =Assumptions!$C$110 -> 0.03 | F7: =CHOOSE(Assumptions!$C$10,C7,D7,E7) -> 0.015
A8: Refinancing rate | C8: =Assumptions!$C$73 -> 0.11 | D8: =Assumptions!$C$92 -> 0.135 | E8: =Assumptions!$C$111 -> 0.16 | F8: =CHOOSE(Assumptions!$C$10,C8,D8,E8) -> 0.135
A9: Market access: max net leverage / min coverage | C9: =TEXT(Assumptions!$C$74,"0.0")&"x / "&TEXT(Assumptions!$C$75,"0.00")&"x" -> 8.5x / 1.20x | D9: =TEXT(Assumptions!$C$93,"0.0")&"x / "&TEXT(Assumptions!$C$94,"0.00")&"x" -> 5.5x / 1.80x | E9: =TEXT(Assumptions!$C$112,"0.0")&"x / "&TEXT(Assumptions!$C$113,"0.00")&"x" -> 5.0x / 2.00x | F9: =CHOOSE(Assumptions!$C$10,C9,D9,E9) -> 5.5x / 1.80x
A10: Exit multiple / distressed multiple | C10: =TEXT(Assumptions!$C$76,"0.0")&"x / "&TEXT(Assumptions!$C$78,"0.0")&"x" -> 6.5x / 4.0x | D10: =TEXT(Assumptions!$C$95,"0.0")&"x / "&TEXT(Assumptions!$C$97,"0.0")&"x" -> 5.0x / 4.0x | E10: =TEXT(Assumptions!$C$114,"0.0")&"x / "&TEXT(Assumptions!$C$116,"0.0")&"x" -> 3.5x / 4.0x | F10: =CHOOSE(Assumptions!$C$10,C10,D10,E10) -> 5.0x / 4.0x
A11: Asset value decline | C11: =Assumptions!$C$79 -> 0 | D11: =Assumptions!$C$98 -> 0.15 | E11: =Assumptions!$C$117 -> 0.35 | F11: =CHOOSE(Assumptions!$C$10,C11,D11,E11) -> 0.15
A12: Scenario probability | C12: =Assumptions!$C$81 -> 0.55 | D12: =Assumptions!$C$100 -> 0.3 | E12: =Assumptions!$C$119 -> 0.15 | F12: =CHOOSE(Assumptions!$C$10,C12,D12,E12) -> 0.3
A14: Outputs (from Calc Engine) | C14: Base Case | D14: Downside | E14: Severe Downside | F14: Selected
A15: FY2030E revenue ($M) | C15: ='Calc Engine'!K19 -> 2282.3761 | D15: ='Calc Engine'!K372 -> 2073.7625 | E15: ='Calc Engine'!K725 -> 1526.8227 | F15: =CHOOSE(Assumptions!$C$10,C15,D15,E15) -> 2073.7625
A16: Trough EBITDA ($M) | C16: =MIN('Calc Engine'!$G$23:$K$23) -> 154.44 | D16: =MIN('Calc Engine'!$G$376:$K$376) -> 48.909518 | E16: =MIN('Calc Engine'!$G$729:$K$729) -> 15.268227 | F16: =CHOOSE(Assumptions!$C$10,C16,D16,E16) -> 48.909518
A17: Cumulative FCF, 5 periods ($M) | C17: ='Calc Engine'!C354 -> -46.975945 | D17: ='Calc Engine'!C707 -> -481.48088 | E17: ='Calc Engine'!C1060 -> -697.7929 | F17: =CHOOSE(Assumptions!$C$10,C17,D17,E17) -> -481.48088
A18: Peak net debt / EBITDA | C18: ='Calc Engine'!C352 -> 7.8622119 | D18: ='Calc Engine'!C705 -> 28.568111 | E18: ='Calc Engine'!C1058 -> 124.62435 | F18: =CHOOSE(Assumptions!$C$10,C18,D18,E18) -> 28.568111
A19: Minimum EBITDA / cash interest | C19: ='Calc Engine'!C353 -> 1.2147366 | D19: ='Calc Engine'!C706 -> 0.37402711 | E19: ='Calc Engine'!C1059 -> 0.10908021 | F19: =CHOOSE(Assumptions!$C$10,C19,D19,E19) -> 0.37402711
A20: Covenant breaches (count of tests failed) | C20: ='Calc Engine'!C165 -> 0 | D20: ='Calc Engine'!C518 -> 5 | E20: ='Calc Engine'!C871 -> 5 | F20: =CHOOSE(Assumptions!$C$10,C20,D20,E20) -> 5
A21: Refinancing failures (maturing tranches) | C21: ='Calc Engine'!C120 -> 0 | D21: ='Calc Engine'!C473 -> 4 | E21: ='Calc Engine'!C826 -> 4 | F21: =CHOOSE(Assumptions!$C$10,C21,D21,E21) -> 4
A22: Payment default modelled? (1 = yes) | C22: ='Calc Engine'!C170 -> 1 | D22: ='Calc Engine'!C523 -> 1 | E22: ='Calc Engine'!C876 -> 1 | F22: =CHOOSE(Assumptions!$C$10,C22,D22,E22) -> 1
A23: Valuation period (default or trough) | C23: ='Calc Engine'!C171 -> 2027 | D23: ='Calc Engine'!C524 -> 2027 | E23: ='Calc Engine'!C877 -> 2027 | F23: =CHOOSE(Assumptions!$C$10,C23,D23,E23) -> 2027
A24: Recovery value used ($M) | C24: ='Calc Engine'!C177 -> 630.40032 | D24: ='Calc Engine'!C530 -> 530.4 | E24: ='Calc Engine'!C883 -> 405.6 | F24: =CHOOSE(Assumptions!$C$10,C24,D24,E24) -> 530.4
A25: Target-tranche recovery % (valuation waterfall) | C25: ='Calc Engine'!C262 -> 0.86642715 | D25: ='Calc Engine'!C615 -> 0.54845094 | E25: ='Calc Engine'!C968 -> 0.28087124 | F25: =CHOOSE(Assumptions!$C$10,C25,D25,E25) -> 0.54845094
A26: Exit price used (% of face) | C26: ='Calc Engine'!C337 -> 100 | D26: ='Calc Engine'!C690 -> 5.543719 | E26: ='Calc Engine'!C1043 -> 0 | F26: =CHOOSE(Assumptions!$C$10,C26,D26,E26) -> 5.543719
A27: IRR | C27: ='Calc Engine'!C351 -> 0.13082152 | D27: ='Calc Engine'!C704 -> 0.0068898968 | E27: ='Calc Engine'!C1057 -> -0.13853405 | F27: =CHOOSE(Assumptions!$C$10,C27,D27,E27) -> 0.0068898968
A28: MOIC | C28: ='Calc Engine'!C350 -> 1.3926472 | D28: ='Calc Engine'!C703 -> 1.0177159 | E28: ='Calc Engine'!C1056 -> 0.70612917 | F28: =CHOOSE(Assumptions!$C$10,C28,D28,E28) -> 1.0177159
A29: Absolute profit ($M) | C29: ='Calc Engine'!C349 -> 30.779613 | D29: ='Calc Engine'!C702 -> 1.3887463 | E29: ='Calc Engine'!C1055 -> -23.036534 | F29: =CHOOSE(Assumptions!$C$10,C29,D29,E29) -> 1.3887463
A31: Probability-weighted IRR (IRR of expected cash flows) | C31: =IF(SUM(D38:I38)<=0,-1,IFERROR(IRR(C38:I38,MAX(-0.9,(SUM(D38:I38)/-C38)^(1/(COLUMNS(C38:I38)-1))-1)),IRR(C38:I38,0.1))) -> 0.064153443
A32: Memo: probability-weighted AVERAGE of scenario IRRs (IRR is non-linear, so this is not an IRR) | C32: =SUMPRODUCT(C12:E12,C27:E27) -> 0.0532387
A33: Probability-weighted MOIC | C33: =SUMPRODUCT(C12:E12,C28:E28) -> 1.1771901
A34: Probability of payment default | C34: =SUMPRODUCT(C12:E12,C22:E22) -> 1
A36: Expected (probability-weighted) position cash flows by period — basis of the probability-weighted IRR
C37: t=0 | D37: t=1 | E37: t=2 | F37: t=3 | G37: t=4 | H37: t=5 | I37: t=6
